Workbook

Sheet 1
C2: Oriente | I2: Poniente | O2: Nor Oriente | U2: Nor central | AA2: Nor Poniente | AG2: Central | AK2: J | AL2: H | AM2: Total
B3: Alimento ( sacos) | C3: 1 | D3: 2 | E3: 3 | F3: 4 | G3: 5 | H3: 6 | I3: 1 | J3: 2 | K3: 3 | L3: 4 | M3: 5 | N3: 6 | O3: 1 | P3: 2 | Q3: 3 | R3: 4 | S3: 5 | T3: 6 | U3: 1 | V3: 2 | W3: 3 | X3: 4 | Y3: 5 | Z3: 6 | AA3: 1 | AB3: 2 | AC3: 3 | AD3: 4 | AE3: 5 | AF3: 6 | AG3: 1 | AH3: 2 | AI3: 3 | AJ3: 4 | AM3: Sacos | AN3: Kg
A4: Lunes | B4: 3 mm progress ex | AM4: =SUM(C4:AL4) -> 0 | AN4: =AM4*25 -> 0
B5: 4,5 mm metabólica | AM5: =SUM(C5:AL5) -> 0 | AN5: =AM5*25 -> 0
B6: 6 mm metabólica | AM6: =SUM(C6:AL6) -> 0 | AN6: =AM6*25 -> 0
B7: 8 mm metabólica | AM7: =SUM(C7:AL7) -> 0 | AN7: =AM7*25 -> 0
B8: 6 mm Sturgeon Rep. | AM8: =SUM(C8:AL8) -> 0 | AN8: =AM8*25 -> 0
B9: 8 mm Sturgeon Rep. | AM9: =SUM(C9:AL9) -> 0 | AN9: =AM9*25 -> 0
AM10: =SUM(C10:AL10) -> 0 | AN10: =AM10*25 -> 0
AM11: =SUM(C11:AL11) -> 0 | AN11: =AM11*25 -> 0
A12: Martes | B12: 3 mm progress ex | AM12: =SUM(C12:AL12) -> 0 | AN12: =AM12*25 -> 0
B13: 4,5 mm metabólica | AM13: =SUM(C13:AL13) -> 0 | AN13: =AM13*25 -> 0
B14: 6 mm metabólica | AM14: =SUM(C14:AL14) -> 0 | AN14: =AM14*25 -> 0
B15: 8 mm metabólica | AM15: =SUM(C15:AL15) -> 0 | AN15: =AM15*25 -> 0
B16: 6 mm Sturgeon Rep. | AM16: =SUM(C16:AL16) -> 0 | AN16: =AM16*25 -> 0
B17: 8 mm Sturgeon Rep. | AM17: =SUM(C17:AL17) -> 0 | AN17: =AM17*25 -> 0
AM18: =SUM(C18:AL18) -> 0 | AN18: =AM18*25 -> 0
AM19: =SUM(C19:AL19) -> 0 | AN19: =AM19*25 -> 0
A20: Miércoles | B20: 3 mm progress ex | AM20: =SUM(C20:AL20) -> 0 | AN20: =AM20*25 -> 0
B21: 4,5 mm metabólica | P21: 1 | AM21: =SUM(C21:AL21) -> 1 | AN21: =AM21*25 -> 25
B22: 6 mm metabólica | D22: 1 | E22: 1 | J22: 1 | L22: 2 | M22: 1 | O22: 2 | T22: 2 | AM22: =SUM(C22:AL22) -> 10 | AN22: =AM22*25 -> 250
B23: 8 mm metabólica | C23: 2 | D23: 2 | E23: 1 | F23: 2 | J23: 2 | L23: 1 | M23: 2 | N23: 2 | AI23: 2 | AJ23: 1 | AM23: =SUM(C23:AL23) -> 17 | AN23: =AM23*25 -> 425
B24: 6 mm Sturgeon Rep. | AM24: =SUM(C24:AL24) -> 0 | AN24: =AM24*25 -> 0
B25: 8 mm Sturgeon Rep. | C25: 4 | F25: 2 | G25: 4 | H25: 4 | AM25: =SUM(C25:AL25) -> 14 | AN25: =AM25*25 -> 350
AM26: =SUM(C26:AL26) -> 0 | AN26: =AM26*25 -> 0
AM27: =SUM(C27:AL27) -> 0 | AN27: =AM27*25 -> 0
A28: Jueves | B28: 3 mm progress ex | AM28: =SUM(C28:AL28) -> 0 | AN28: =AM28*25 -> 0
B29: 4,5 mm metabólica | AM29: =SUM(C29:AL29) -> 0 | AN29: =AM29*25 -> 0
B30: 6 mm metabólica | AM30: =SUM(C30:AL30) -> 0 | AN30: =AM30*25 -> 0
B31: 8 mm metabólica | AM31: =SUM(C31:AL31) -> 0 | AN31: =AM31*25 -> 0
B32: 6 mm Sturgeon Rep. | AM32: =SUM(C32:AL32) -> 0 | AN32: =AM32*25 -> 0
B33: 8 mm Sturgeon Rep. | AM33: =SUM(C33:AL33) -> 0 | AN33: =AM33*25 -> 0
AM34: =SUM(C34:AL34) -> 0 | AN34: =AM34*25 -> 0
A35: Viernes | B35: 3 mm progress ex | AM35: =SUM(C35:AL35) -> 0 | AN35: =AM35*25 -> 0
B36: 4,5 mm metabólica | P36: 1 | AM36: =SUM(C36:AL36) -> 1 | AN36: =AM36*25 -> 25
B37: 6 mm metabólica | D37: 1 | E37: 1 | J37: 1 | L37: 2 | M37: 1 | O37: 2 | T37: 2 | AM37: =SUM(C37:AL37) -> 10 | AN37: =AM37*25 -> 250
B38: 8 mm metabólica | C38: 2 | D38: 2 | E38: 1 | F38: 2 | J38: 2 | L38: 1 | M38: 2 | N38: 2 | AI38: 2 | AJ38: 1 | AM38: =SUM(C38:AL38) -> 17 | AN38: =AM38*25 -> 425
B39: 6 mm Sturgeon Rep. | AM39: =SUM(C39:AL39) -> 0 | AN39: =AM39*25 -> 0
B40: 8 mm Sturgeon Rep. | C40: 4 | F40: 2 | G40: 4 | H40: 4 | AM40: =SUM(C40:AL40) -> 14 | AN40: =AM40*25 -> 350
AM41: =SUM(C41:AL41) -> 0 | AN41: =AM41*25 -> 0
...

Sheet 2
C2: Oriente | I2: Poniente | O2: Nor Oriente | U2: Nor central | AA2: Nor Poniente | AG2: Central | AK2: J | AL2: H | AM2: Total
B3: Alimento ( sacos) | C3: 1 | D3: 2 | E3: 3 | F3: 4 | G3: 5 | H3: 6 | I3: 1 | J3: 2 | K3: 3 | L3: 4 | M3: 5 | N3: 6 | O3: 1 | P3: 2 | Q3: 3 | R3: 4 | S3: 5 | T3: 6 | U3: 1 | V3: 2 | W3: 3 | X3: 4 | Y3: 5 | Z3: 6 | AA3: 1 | AB3: 2 | AC3: 3 | AD3: 4 | AE3: 5 | AF3: 6 | AG3: 1 | AH3: 2 | AI3: 3 | AJ3: 4 | AM3: Sacos | AN3: Kg
A4: Lunes | B4: 3 mm progress ex | AL4: 4 | AM4: =SUM(C4:AL4) -> 4 | AN4: =AM4*25 -> 100
B5: 4,5 mm metabólica | P5: 1 | AH5: 2 | AM5: =SUM(C5:AL5) -> 3 | AN5: =AM5*25 -> 75
B6: 6 mm metabólica | D6: 1 | E6: 1 | J6: 1 | L6: 2 | M6: 1 | O6: 2 | T6: 2 | AH6: 2 | AM6: =SUM(C6:AL6) -> 12 | AN6: =AM6*25 -> 300
B7: 8 mm metabólica | C7: 4 | D7: 2 | E7: 1 | F7: 4 | G7: 4 | H7: 4 | J7: 2 | L7: 1 | M7: 2 | N7: 2 | AG7: 2 | AI7: 2 | AJ7: 1 | AM7: =SUM(C7:AL7) -> 31 | AN7: =AM7*25 -> 775
B8: 6 mm Sturgeon Rep. | AM8: =SUM(C8:AL8) -> 0 | AN8: =AM8*25 -> 0
B9: 8 mm Sturgeon Rep. | C9: 2 | AM9: =SUM(C9:AL9) -> 2 | AN9: =AM9*25 -> 50
B10: Talasa | AM10: =SUM(C10:AL10) -> 0 | AN10: =AM10*25 -> 0
AM11: =SUM(C11:AL11) -> 0 | AN11: =AM11*25 -> 0
A12: Martes | B12: 3 mm progress ex | AM12: =SUM(C12:AL12) -> 0 | AN12: =AM12*25 -> 0
B13: 4,5 mm metabólica | AM13: =SUM(C13:AL13) -> 0 | AN13: =AM13*25 -> 0
B14: 6 mm metabólica | AM14: =SUM(C14:AL14) -> 0 | AN14: =AM14*25 -> 0
B15: 8 mm metabólica | AM15: =SUM(C15:AL15) -> 0 | AN15: =AM15*25 -> 0
B16: 6 mm Sturgeon Rep. | AM16: =SUM(C16:AL16) -> 0 | AN16: =AM16*25 -> 0
B17: 8 mm Sturgeon Rep. | AM17: =SUM(C17:AL17) -> 0 | AN17: =AM17*25 -> 0
AM18: =SUM(C18:AL18) -> 0 | AN18: =AM18*25 -> 0
AM19: =SUM(C19:AL19) -> 0 | AN19: =AM19*25 -> 0
A20: Miércoles | B20: 3 mm progress ex | AM20: =SUM(C20:AL20) -> 0 | AN20: =AM20*25 -> 0
B21: 4,5 mm metabólica | P21: 1 | AM21: =SUM(C21:AL21) -> 1 | AN21: =AM21*25 -> 25
B22: 6 mm metabólica | D22: 1 | E22: 1 | J22: 1 | L22: 2 | M22: 1 | O22: 2 | T22: 2 | AM22: =SUM(C22:AL22) -> 10 | AN22: =AM22*25 -> 250
B23: 8 mm metabólica | C23: 6 | D23: 2 | E23: 1 | F23: 4 | G23: 4 | H23: 4 | J23: 2 | L23: 1 | M23: 2 | N23: 2 | AM23: =SUM(C23:AL23) -> 28 | AN23: =AM23*25 -> 700
B24: 6 mm Sturgeon Rep. | AM24: =SUM(C24:AL24) -> 0 | AN24: =AM24*25 -> 0
B25: 8 mm Sturgeon Rep. | AM25: =SUM(C25:AL25) -> 0 | AN25: =AM25*25 -> 0
AM26: =SUM(C26:AL26) -> 0 | AN26: =AM26*25 -> 0
AM27: =SUM(C27:AL27) -> 0 | AN27: =AM27*25 -> 0
A28: Jueves | B28: 3 mm progress ex | AM28: =SUM(C28:AL28) -> 0 | AN28: =AM28*25 -> 0
B29: 4,5 mm metabólica | AM29: =SUM(C29:AL29) -> 0 | AN29: =AM29*25 -> 0
B30: 6 mm metabólica | AM30: =SUM(C30:AL30) -> 0 | AN30: =AM30*25 -> 0
B31: 8 mm metabólica | AM31: =SUM(C31:AL31) -> 0 | AN31: =AM31*25 -> 0
B32: 6 mm Sturgeon Rep. | AM32: =SUM(C32:AL32) -> 0 | AN32: =AM32*25 -> 0
B33: 8 mm Sturgeon Rep. | AM33: =SUM(C33:AL33) -> 0 | AN33: =AM33*25 -> 0
AM34: =SUM(C34:AL34) -> 0 | AN34: =AM34*25 -> 0
A35: Viernes | B35: 3 mm progress ex | AL35: 5 | AM35: =SUM(C35:AL35) -> 5 | AN35: =AM35*25 -> 125
B36: 4,5 mm metabólica | P36: 1 | AH36: 2 | AM36: =SUM(C36:AL36) -> 3 | AN36: =AM36*25 -> 75
B37: 6 mm metabólica | D37: 1 | E37: 1 | J37: 1 | L37: 2 | M37: 1 | O37: 2 | T37: 2 | AH37: 2 | AM37: =SUM(C37:AL37) -> 12 | AN37: =AM37*25 -> 300
B38: 8 mm metabólica | C38: 6 | D38: 2 | E38: 1 | F38: 4 | G38: 4 | H38: 4 | J38: 2 | L38: 1 | M38: 2 | N38: 2 | AJ38: 1 | AM38: =SUM(C38:AL38) -> 29 | AN38: =AM38*25 -> 725
B39: 6 mm Sturgeon Rep. | AM39: =SUM(C39:AL39) -> 0 | AN39: =AM39*25 -> 0
B40: 8 mm Sturgeon Rep. | AM40: =SUM(C40:AL40) -> 0 | AN40: =AM40*25 -> 0
AM41: =SUM(C41:AL41) -> 0 | AN41: =AM41*25 -> 0
...

Sheet 3
C2: Oriente | I2: Poniente | O2: Nor Oriente | U2: Nor central | AA2: Nor Poniente | AG2: Central | AK2: J | AL2: H | AM2: Total
B3: Alimento ( sacos) | C3: 1 | D3: 2 | E3: 3 | F3: 4 | G3: 5 | H3: 6 | I3: 1 | J3: 2 | K3: 3 | L3: 4 | M3: 5 | N3: 6 | O3: 1 | P3: 2 | Q3: 3 | R3: 4 | S3: 5 | T3: 6 | U3: 1 | V3: 2 | W3: 3 | X3: 4 | Y3: 5 | Z3: 6 | AA3: 1 | AB3: 2 | AC3: 3 | AD3: 4 | AE3: 5 | AF3: 6 | AG3: 1 | AH3: 2 | AI3: 3 | AJ3: 4 | AM3: Sacos | AN3: Kg
A4: Lunes | B4: 3 mm progress ex | AH4: 2 | AM4: =SUM(C4:AL4) -> 2 | AN4: =AM4*25 -> 50
B5: 4,5 mm metabólica | AM5: =SUM(C5:AL5) -> 0 | AN5: =AM5*25 -> 0
B6: 6 mm metabólica | D6: 1 | E6: 1 | J6: 1 | L6: 2 | M6: 1 | O6: 2 | T6: 2 | AM6: =SUM(C6:AL6) -> 10 | AN6: =AM6*25 -> 250
B7: 8 mm metabólica | C7: 6 | D7: 2 | E7: 1 | F7: 4 | G7: 4 | H7: 4 | J7: 2 | L7: 1 | M7: 2 | N7: 2 | AG7: 2 | AI7: 2 | AJ7: 1 | AM7: =SUM(C7:AL7) -> 33 | AN7: =AM7*25 -> 825
B8: 6 mm Sturgeon Rep. | AM8: =SUM(C8:AL8) -> 0 | AN8: =AM8*25 -> 0
B9: 8 mm Sturgeon Rep. | AM9: =SUM(C9:AL9) -> 0 | AN9: =AM9*25 -> 0
AM10: =SUM(C10:AL10) -> 0 | AN10: =AM10*25 -> 0
AM11: =SUM(C11:AL11) -> 0 | AN11: =AM11*25 -> 0
A12: Martes | B12: 3 mm progress ex | AM12: =SUM(C12:AL12) -> 0 | AN12: =AM12*25 -> 0
B13: 4,5 mm metabólica | AM13: =SUM(C13:AL13) -> 0 | AN13: =AM13*25 -> 0
B14: 6 mm metabólica | AM14: =SUM(C14:AL14) -> 0 | AN14: =AM14*25 -> 0
B15: 8 mm metabólica | AM15: =SUM(C15:AL15) -> 0 | AN15: =AM15*25 -> 0
B16: 6 mm Sturgeon Rep. | AM16: =SUM(C16:AL16) -> 0 | AN16: =AM16*25 -> 0
B17: 8 mm Sturgeon Rep. | AM17: =SUM(C17:AL17) -> 0 | AN17: =AM17*25 -> 0
AM18: =SUM(C18:AL18) -> 0 | AN18: =AM18*25 -> 0
AM19: =SUM(C19:AL19) -> 0 | AN19: =AM19*25 -> 0
A20: Miércoles | B20: 3 mm progress ex | AM20: =SUM(C20:AL20) -> 0 | AN20: =AM20*25 -> 0
B21: 4,5 mm metabólica | P21: 1 | AM21: =SUM(C21:AL21) -> 1 | AN21: =AM21*25 -> 25
B22: 6 mm metabólica | D22: 3 | E22: 2 | F22: 1 | G22: 1 | H22: 1 | J22: 3 | L22: 3 | M22: 3 | N22: 2 | O22: 2 | T22: 2 | AM22: =SUM(C22:AL22) -> 23 | AN22: =AM22*25 -> 575
B23: 8 mm metabólica | C23: 6 | F23: 3 | G23: 3 | H23: 4 | AM23: =SUM(C23:AL23) -> 16 | AN23: =AM23*25 -> 400
B24: 6 mm Sturgeon Rep. | AM24: =SUM(C24:AL24) -> 0 | AN24: =AM24*25 -> 0
B25: 8 mm Sturgeon Rep. | AM25: =SUM(C25:AL25) -> 0 | AN25: =AM25*25 -> 0
AM26: =SUM(C26:AL26) -> 0 | AN26: =AM26*25 -> 0
AM27: =SUM(C27:AL27) -> 0 | AN27: =AM27*25 -> 0
A28: Jueves | B28: 3 mm progress ex | AM28: =SUM(C28:AL28) -> 0 | AN28: =AM28*25 -> 0
B29: 4,5 mm metabólica | AM29: =SUM(C29:AL29) -> 0 | AN29: =AM29*25 -> 0
B30: 6 mm metabólica | AM30: =SUM(C30:AL30) -> 0 | AN30: =AM30*25 -> 0
B31: 8 mm metabólica | AM31: =SUM(C31:AL31) -> 0 | AN31: =AM31*25 -> 0
B32: 6 mm Sturgeon Rep. | AM32: =SUM(C32:AL32) -> 0 | AN32: =AM32*25 -> 0
B33: 8 mm Sturgeon Rep. | AM33: =SUM(C33:AL33) -> 0 | AN33: =AM33*25 -> 0
AM34: =SUM(C34:AL34) -> 0 | AN34: =AM34*25 -> 0
A35: Viernes | B35: 3 mm progress ex | AM35: =SUM(C35:AL35) -> 0 | AN35: =AM35*25 -> 0
B36: 4,5 mm metabólica | AM36: =SUM(C36:AL36) -> 0 | AN36: =AM36*25 -> 0
B37: 6 mm metabólica | AM37: =SUM(C37:AL37) -> 0 | AN37: =AM37*25 -> 0
B38: 8 mm metabólica | AM38: =SUM(C38:AL38) -> 0 | AN38: =AM38*25 -> 0
B39: 6 mm Sturgeon Rep. | AM39: =SUM(C39:AL39) -> 0 | AN39: =AM39*25 -> 0
B40: 8 mm Sturgeon Rep. | AM40: =SUM(C40:AL40) -> 0 | AN40: =AM40*25 -> 0
B41: Thallasa | AM41: =SUM(C41:AL41) -> 0 | AN41: =AM41*25 -> 0
...

Sheet 4
C2: Oriente | I2: Poniente | O2: Nor Oriente | U2: Nor central | AA2: Nor Poniente | AG2: Central | AK2: J | AL2: H | AM2: Total
B3: Alimento ( sacos) | C3: 1 | D3: 2 | E3: 3 | F3: 4 | G3: 5 | H3: 6 | I3: 1 | J3: 2 | K3: 3 | L3: 4 | M3: 5 | N3: 6 | O3: 1 | P3: 2 | Q3: 3 | R3: 4 | S3: 5 | T3: 6 | U3: 1 | V3: 2 | W3: 3 | X3: 4 | Y3: 5 | Z3: 6 | AA3: 1 | AB3: 2 | AC3: 3 | AD3: 4 | AE3: 5 | AF3: 6 | AG3: 1 | AH3: 2 | AI3: 3 | AJ3: 4 | AM3: Sacos | AN3: Kg
A4: Lunes | B4: 3 mm progress ex | AH4: 2 | AM4: =SUM(C4:AL4) -> 2 | AN4: =AM4*25 -> 50
B5: 4,5 mm metabólica | O5: 2 | P5: 2 | S5: 2 | T5: 2 | AM5: =SUM(C5:AL5) -> 8 | AN5: =AM5*25 -> 200
B6: 6 mm metabólica | C6: 4 | D6: 2 | E6: 2 | F6: 2 | G6: 4 | H6: 4 | I6: 1 | J6: 2 | L6: 1 | M6: 1 | N6: 2 | AG6: 1 | AI6: 2 | AJ6: 2 | AM6: =SUM(C6:AL6) -> 30 | AN6: =AM6*25 -> 750
B7: 8 mm metabólica | AM7: =SUM(C7:AL7) -> 0 | AN7: =AM7*25 -> 0
B8: 6 mm Sturgeon Rep. | AM8: =SUM(C8:AL8) -> 0 | AN8: =AM8*25 -> 0
B9: 8 mm Sturgeon Rep. | AM9: =SUM(C9:AL9) -> 0 | AN9: =AM9*25 -> 0
AM10: =SUM(C10:AL10) -> 0 | AN10: =AM10*25 -> 0
AM11: =SUM(C11:AL11) -> 0 | AN11: =AM11*25 -> 0
A12: Martes | B12: 3 mm progress ex | AM12: =SUM(C12:AL12) -> 0 | AN12: =AM12*25 -> 0
B13: 4,5 mm metabólica | AM13: =SUM(C13:AL13) -> 0 | AN13: =AM13*25 -> 0
B14: 6 mm metabólica | AM14: =SUM(C14:AL14) -> 0 | AN14: =AM14*25 -> 0
B15: 8 mm metabólica | AM15: =SUM(C15:AL15) -> 0 | AN15: =AM15*25 -> 0
B16: 6 mm Sturgeon Rep. | AM16: =SUM(C16:AL16) -> 0 | AN16: =AM16*25 -> 0
B17: 8 mm Sturgeon Rep. | AM17: =SUM(C17:AL17) -> 0 | AN17: =AM17*25 -> 0
AM18: =SUM(C18:AL18) -> 0 | AN18: =AM18*25 -> 0
AM19: =SUM(C19:AL19) -> 0 | AN19: =AM19*25 -> 0
A20: Miércoles | B20: 3 mm progress ex | AM20: =SUM(C20:AL20) -> 0 | AN20: =AM20*25 -> 0
B21: 4,5 mm metabólica | AM21: =SUM(C21:AL21) -> 0 | AN21: =AM21*25 -> 0
B22: 6 mm metabólica | AM22: =SUM(C22:AL22) -> 0 | AN22: =AM22*25 -> 0
B23: 8 mm metabólica | AM23: =SUM(C23:AL23) -> 0 | AN23: =AM23*25 -> 0
B24: 6 mm Sturgeon Rep. | AM24: =SUM(C24:AL24) -> 0 | AN24: =AM24*25 -> 0
B25: 8 mm Sturgeon Rep. | AM25: =SUM(C25:AL25) -> 0 | AN25: =AM25*25 -> 0
AM26: =SUM(C26:AL26) -> 0 | AN26: =AM26*25 -> 0
AM27: =SUM(C27:AL27) -> 0 | AN27: =AM27*25 -> 0
A28: Jueves | B28: 3 mm progress ex | AM28: =SUM(C28:AL28) -> 0 | AN28: =AM28*25 -> 0
B29: 4,5 mm metabólica | AM29: =SUM(C29:AL29) -> 0 | AN29: =AM29*25 -> 0
B30: 6 mm metabólica | AM30: =SUM(C30:AL30) -> 0 | AN30: =AM30*25 -> 0
B31: 8 mm metabólica | AM31: =SUM(C31:AL31) -> 0 | AN31: =AM31*25 -> 0
B32: 6 mm Sturgeon Rep. | AM32: =SUM(C32:AL32) -> 0 | AN32: =AM32*25 -> 0
B33: 8 mm Sturgeon Rep. | AM33: =SUM(C33:AL33) -> 0 | AN33: =AM33*25 -> 0
AM34: =SUM(C34:AL34) -> 0 | AN34: =AM34*25 -> 0
A35: Viernes | B35: 3 mm progress ex | AM35: =SUM(C35:AL35) -> 0 | AN35: =AM35*25 -> 0
B36: 4,5 mm metabólica | AM36: =SUM(C36:AL36) -> 0 | AN36: =AM36*25 -> 0
B37: 6 mm metabólica | AM37: =SUM(C37:AL37) -> 0 | AN37: =AM37*25 -> 0
B38: 8 mm metabólica | AM38: =SUM(C38:AL38) -> 0 | AN38: =AM38*25 -> 0
B39: 6 mm Sturgeon Rep. | AM39: =SUM(C39:AL39) -> 0 | AN39: =AM39*25 -> 0
B40: 8 mm Sturgeon Rep. | AM40: =SUM(C40:AL40) -> 0 | AN40: =AM40*25 -> 0
AM41: =SUM(C41:AL41) -> 0 | AN41: =AM41*25 -> 0
...

Sheet 5
C2: Oriente | I2: Poniente | O2: Nor Oriente | U2: Nor central | AA2: Nor Poniente | AG2: Central | AK2: J | AL2: H | AM2: Total
B3: Alimento ( sacos) | C3: 1 | D3: 2 | E3: 3 | F3: 4 | G3: 5 | H3: 6 | I3: 1 | J3: 2 | K3: 3 | L3: 4 | M3: 5 | N3: 6 | O3: 1 | P3: 2 | Q3: 3 | R3: 4 | S3: 5 | T3: 6 | U3: 1 | V3: 2 | W3: 3 | X3: 4 | Y3: 5 | Z3: 6 | AA3: 1 | AB3: 2 | AC3: 3 | AD3: 4 | AE3: 5 | AF3: 6 | AG3: 1 | AH3: 2 | AI3: 3 | AJ3: 4 | AM3: Sacos | AN3: Kg
A4: Lunes | B4: 3 mm progress ex | AH4: 2 | AL4: 3 | AM4: =SUM(C4:AL4) -> 5 | AN4: =AM4*25 -> 125
B5: 4,5 mm metabólica | O5: 2 | P5: 2 | S5: 2 | T5: 2 | AM5: =SUM(C5:AL5) -> 8 | AN5: =AM5*25 -> 200
B6: 6 mm metabólica | C6: 4 | D6: 2 | E6: 2 | F6: 2 | G6: 4 | H6: 4 | I6: 1 | J6: 2 | L6: 1 | M6: 1 | N6: 2 | AG6: 1 | AI6: 2 | AJ6: 2 | AM6: =SUM(C6:AL6) -> 30 | AN6: =AM6*25 -> 750
B7: 8 mm metabólica | AM7: =SUM(C7:AL7) -> 0 | AN7: =AM7*25 -> 0
B8: 6 mm Sturgeon Rep. | AM8: =SUM(C8:AL8) -> 0 | AN8: =AM8*25 -> 0
B9: 8 mm Sturgeon Rep. | AM9: =SUM(C9:AL9) -> 0 | AN9: =AM9*25 -> 0
AM10: =SUM(C10:AL10) -> 0 | AN10: =AM10*25 -> 0
AM11: =SUM(C11:AL11) -> 0 | AN11: =AM11*25 -> 0
A12: Martes | B12: 3 mm progress ex | AM12: =SUM(C12:AL12) -> 0 | AN12: =AM12*25 -> 0
B13: 4,5 mm metabólica | AM13: =SUM(C13:AL13) -> 0 | AN13: =AM13*25 -> 0
B14: 6 mm metabólica | AM14: =SUM(C14:AL14) -> 0 | AN14: =AM14*25 -> 0
B15: 8 mm metabólica | AM15: =SUM(C15:AL15) -> 0 | AN15: =AM15*25 -> 0
B16: 6 mm Sturgeon Rep. | AM16: =SUM(C16:AL16) -> 0 | AN16: =AM16*25 -> 0
B17: 8 mm Sturgeon Rep. | AM17: =SUM(C17:AL17) -> 0 | AN17: =AM17*25 -> 0
AM18: =SUM(C18:AL18) -> 0 | AN18: =AM18*25 -> 0
AM19: =SUM(C19:AL19) -> 0 | AN19: =AM19*25 -> 0
A20: Miércoles | B20: 3 mm progress ex | AM20: =SUM(C20:AL20) -> 0 | AN20: =AM20*25 -> 0
B21: 4,5 mm metabólica | AM21: =SUM(C21:AL21) -> 0 | AN21: =AM21*25 -> 0
B22: 6 mm metabólica | AM22: =SUM(C22:AL22) -> 0 | AN22: =AM22*25 -> 0
B23: 8 mm metabólica | AM23: =SUM(C23:AL23) -> 0 | AN23: =AM23*25 -> 0
B24: 6 mm Sturgeon Rep. | AM24: =SUM(C24:AL24) -> 0 | AN24: =AM24*25 -> 0
B25: 8 mm Sturgeon Rep. | AM25: =SUM(C25:AL25) -> 0 | AN25: =AM25*25 -> 0
AM26: =SUM(C26:AL26) -> 0 | AN26: =AM26*25 -> 0
AM27: =SUM(C27:AL27) -> 0 | AN27: =AM27*25 -> 0
A28: Jueves | B28: 3 mm progress ex | AM28: =SUM(C28:AL28) -> 0 | AN28: =AM28*25 -> 0
B29: 4,5 mm metabólica | AM29: =SUM(C29:AL29) -> 0 | AN29: =AM29*25 -> 0
B30: 6 mm metabólica | AM30: =SUM(C30:AL30) -> 0 | AN30: =AM30*25 -> 0
B31: 8 mm metabólica | AM31: =SUM(C31:AL31) -> 0 | AN31: =AM31*25 -> 0
B32: 6 mm Sturgeon Rep. | AM32: =SUM(C32:AL32) -> 0 | AN32: =AM32*25 -> 0
B33: 8 mm Sturgeon Rep. | AM33: =SUM(C33:AL33) -> 0 | AN33: =AM33*25 -> 0
AM34: =SUM(C34:AL34) -> 0 | AN34: =AM34*25 -> 0
A35: Viernes | B35: 3 mm progress ex | AM35: =SUM(C35:AL35) -> 0 | AN35: =AM35*25 -> 0
B36: 4,5 mm metabólica | AM36: =SUM(C36:AL36) -> 0 | AN36: =AM36*25 -> 0
B37: 6 mm metabólica | AM37: =SUM(C37:AL37) -> 0 | AN37: =AM37*25 -> 0
B38: 8 mm metabólica | AM38: =SUM(C38:AL38) -> 0 | AN38: =AM38*25 -> 0
B39: 6 mm Sturgeon Rep. | AM39: =SUM(C39:AL39) -> 0 | AN39: =AM39*25 -> 0
B40: 8 mm Sturgeon Rep. | AM40: =SUM(C40:AL40) -> 0 | AN40: =AM40*25 -> 0
AM41: =SUM(C41:AL41) -> 0 | AN41: =AM41*25 -> 0
...

Sheet 6
C2: Oriente | I2: Poniente | O2: Nor Oriente | U2: Nor central | AA2: Nor Poniente | AG2: Central | AK2: J | AL2: H | AM2: Total
B3: Alimento ( sacos) | C3: 1 | D3: 2 | E3: 3 | F3: 4 | G3: 5 | H3: 6 | I3: 1 | J3: 2 | K3: 3 | L3: 4 | M3: 5 | N3: 6 | O3: 1 | P3: 2 | Q3: 3 | R3: 4 | S3: 5 | T3: 6 | U3: 1 | V3: 2 | W3: 3 | X3: 4 | Y3: 5 | Z3: 6 | AA3: 1 | AB3: 2 | AC3: 3 | AD3: 4 | AE3: 5 | AF3: 6 | AG3: 1 | AH3: 2 | AI3: 3 | AJ3: 4 | AM3: Sacos | AN3: Kg
A4: Lunes | B4: 3 mm progress ex | AM4: =SUM(C4:AL4) -> 0 | AN4: =AM4*25 -> 0
B5: 4,5 mm metabólica | AM5: =SUM(C5:AL5) -> 0 | AN5: =AM5*25 -> 0
B6: 6 mm metabólica | AM6: =SUM(C6:AL6) -> 0 | AN6: =AM6*25 -> 0
B7: 8 mm metabólica | AM7: =SUM(C7:AL7) -> 0 | AN7: =AM7*25 -> 0
B8: 6 mm Sturgeon Rep. | AM8: =SUM(C8:AL8) -> 0 | AN8: =AM8*25 -> 0
B9: 8 mm Sturgeon Rep. | AM9: =SUM(C9:AL9) -> 0 | AN9: =AM9*25 -> 0
AM10: =SUM(C10:AL10) -> 0 | AN10: =AM10*25 -> 0
AM11: =SUM(C11:AL11) -> 0 | AN11: =AM11*25 -> 0
A12: Martes | B12: 3 mm progress ex | AM12: =SUM(C12:AL12) -> 0 | AN12: =AM12*25 -> 0
B13: 4,5 mm metabólica | AM13: =SUM(C13:AL13) -> 0 | AN13: =AM13*25 -> 0
B14: 6 mm metabólica | AM14: =SUM(C14:AL14) -> 0 | AN14: =AM14*25 -> 0
B15: 8 mm metabólica | AM15: =SUM(C15:AL15) -> 0 | AN15: =AM15*25 -> 0
B16: 6 mm Sturgeon Rep. | AM16: =SUM(C16:AL16) -> 0 | AN16: =AM16*25 -> 0
B17: 8 mm Sturgeon Rep. | AM17: =SUM(C17:AL17) -> 0 | AN17: =AM17*25 -> 0
AM18: =SUM(C18:AL18) -> 0 | AN18: =AM18*25 -> 0
AM19: =SUM(C19:AL19) -> 0 | AN19: =AM19*25 -> 0
A20: Miércoles | B20: 3 mm progress ex | AM20: =SUM(C20:AL20) -> 0 | AN20: =AM20*25 -> 0
B21: 4,5 mm metabólica | AM21: =SUM(C21:AL21) -> 0 | AN21: =AM21*25 -> 0
B22: 6 mm metabólica | AM22: =SUM(C22:AL22) -> 0 | AN22: =AM22*25 -> 0
B23: 8 mm metabólica | AM23: =SUM(C23:AL23) -> 0 | AN23: =AM23*25 -> 0
B24: 6 mm Sturgeon Rep. | AM24: =SUM(C24:AL24) -> 0 | AN24: =AM24*25 -> 0
B25: 8 mm Sturgeon Rep. | AM25: =SUM(C25:AL25) -> 0 | AN25: =AM25*25 -> 0
AM26: =SUM(C26:AL26) -> 0 | AN26: =AM26*25 -> 0
AM27: =SUM(C27:AL27) -> 0 | AN27: =AM27*25 -> 0
A28: Jueves | B28: 3 mm progress ex | AM28: =SUM(C28:AL28) -> 0 | AN28: =AM28*25 -> 0
B29: 4,5 mm metabólica | AM29: =SUM(C29:AL29) -> 0 | AN29: =AM29*25 -> 0
B30: 6 mm metabólica | AM30: =SUM(C30:AL30) -> 0 | AN30: =AM30*25 -> 0
B31: 8 mm metabólica | AM31: =SUM(C31:AL31) -> 0 | AN31: =AM31*25 -> 0
B32: 6 mm Sturgeon Rep. | AM32: =SUM(C32:AL32) -> 0 | AN32: =AM32*25 -> 0
B33: 8 mm Sturgeon Rep. | AM33: =SUM(C33:AL33) -> 0 | AN33: =AM33*25 -> 0
AM34: =SUM(C34:AL34) -> 0 | AN34: =AM34*25 -> 0
A35: Viernes | B35: 3 mm progress ex | AM35: =SUM(C35:AL35) -> 0 | AN35: =AM35*25 -> 0
B36: 4,5 mm metabólica | AM36: =SUM(C36:AL36) -> 0 | AN36: =AM36*25 -> 0
B37: 6 mm metabólica | AM37: =SUM(C37:AL37) -> 0 | AN37: =AM37*25 -> 0
B38: 8 mm metabólica | AM38: =SUM(C38:AL38) -> 0 | AN38: =AM38*25 -> 0
B39: 6 mm Sturgeon Rep. | AM39: =SUM(C39:AL39) -> 0 | AN39: =AM39*25 -> 0
B40: 8 mm Sturgeon Rep. | AM40: =SUM(C40:AL40) -> 0 | AN40: =AM40*25 -> 0
AM41: =SUM(C41:AL41) -> 0 | AN41: =AM41*25 -> 0
...

Sheet 7
C2: Oriente | I2: Poniente | O2: Nor Oriente | U2: Nor central | AA2: Nor Poniente | AG2: Central | AK2: J | AL2: H | AM2: Total
B3: Alimento ( sacos) | C3: 1 | D3: 2 | E3: 3 | F3: 4 | G3: 5 | H3: 6 | I3: 1 | J3: 2 | K3: 3 | L3: 4 | M3: 5 | N3: 6 | O3: 1 | P3: 2 | Q3: 3 | R3: 4 | S3: 5 | T3: 6 | U3: 1 | V3: 2 | W3: 3 | X3: 4 | Y3: 5 | Z3: 6 | AA3: 1 | AB3: 2 | AC3: 3 | AD3: 4 | AE3: 5 | AF3: 6 | AG3: 1 | AH3: 2 | AI3: 3 | AJ3: 4 | AM3: Sacos | AN3: Kg
A4: Lunes | B4: 3 mm progress ex | AM4: =SUM(C4:AL4) -> 0 | AN4: =AM4*25 -> 0
B5: 4,5 mm metabólica | AM5: =SUM(C5:AL5) -> 0 | AN5: =AM5*25 -> 0
B6: 6 mm metabólica | AM6: =SUM(C6:AL6) -> 0 | AN6: =AM6*25 -> 0
B7: 8 mm metabólica | AM7: =SUM(C7:AL7) -> 0 | AN7: =AM7*25 -> 0
B8: 6 mm Sturgeon Rep. | AM8: =SUM(C8:AL8) -> 0 | AN8: =AM8*25 -> 0
B9: 8 mm Sturgeon Rep. | AM9: =SUM(C9:AL9) -> 0 | AN9: =AM9*25 -> 0
AM10: =SUM(C10:AL10) -> 0 | AN10: =AM10*25 -> 0
AM11: =SUM(C11:AL11) -> 0 | AN11: =AM11*25 -> 0
A12: Martes | B12: 3 mm progress ex | AM12: =SUM(C12:AL12) -> 0 | AN12: =AM12*25 -> 0
B13: 4,5 mm metabólica | AM13: =SUM(C13:AL13) -> 0 | AN13: =AM13*25 -> 0
B14: 6 mm metabólica | AM14: =SUM(C14:AL14) -> 0 | AN14: =AM14*25 -> 0
B15: 8 mm metabólica | AM15: =SUM(C15:AL15) -> 0 | AN15: =AM15*25 -> 0
B16: 6 mm Sturgeon Rep. | AM16: =SUM(C16:AL16) -> 0 | AN16: =AM16*25 -> 0
B17: 8 mm Sturgeon Rep. | AM17: =SUM(C17:AL17) -> 0 | AN17: =AM17*25 -> 0
AM18: =SUM(C18:AL18) -> 0 | AN18: =AM18*25 -> 0
AM19: =SUM(C19:AL19) -> 0 | AN19: =AM19*25 -> 0
A20: Miércoles | B20: 3 mm progress ex | AM20: =SUM(C20:AL20) -> 0 | AN20: =AM20*25 -> 0
B21: 4,5 mm metabólica | AM21: =SUM(C21:AL21) -> 0 | AN21: =AM21*25 -> 0
B22: 6 mm metabólica | AM22: =SUM(C22:AL22) -> 0 | AN22: =AM22*25 -> 0
B23: 8 mm metabólica | AM23: =SUM(C23:AL23) -> 0 | AN23: =AM23*25 -> 0
B24: 6 mm Sturgeon Rep. | AM24: =SUM(C24:AL24) -> 0 | AN24: =AM24*25 -> 0
B25: 8 mm Sturgeon Rep. | AM25: =SUM(C25:AL25) -> 0 | AN25: =AM25*25 -> 0
AM26: =SUM(C26:AL26) -> 0 | AN26: =AM26*25 -> 0
AM27: =SUM(C27:AL27) -> 0 | AN27: =AM27*25 -> 0
A28: Jueves | B28: 3 mm progress ex | AM28: =SUM(C28:AL28) -> 0 | AN28: =AM28*25 -> 0
B29: 4,5 mm metabólica | AM29: =SUM(C29:AL29) -> 0 | AN29: =AM29*25 -> 0
B30: 6 mm metabólica | AM30: =SUM(C30:AL30) -> 0 | AN30: =AM30*25 -> 0
B31: 8 mm metabólica | AM31: =SUM(C31:AL31) -> 0 | AN31: =AM31*25 -> 0
B32: 6 mm Sturgeon Rep. | AM32: =SUM(C32:AL32) -> 0 | AN32: =AM32*25 -> 0
B33: 8 mm Sturgeon Rep. | AM33: =SUM(C33:AL33) -> 0 | AN33: =AM33*25 -> 0
AM34: =SUM(C34:AL34) -> 0 | AN34: =AM34*25 -> 0
A35: Viernes | B35: 3 mm progress ex | AM35: =SUM(C35:AL35) -> 0 | AN35: =AM35*25 -> 0
B36: 4,5 mm metabólica | AM36: =SUM(C36:AL36) -> 0 | AN36: =AM36*25 -> 0
B37: 6 mm metabólica | AM37: =SUM(C37:AL37) -> 0 | AN37: =AM37*25 -> 0
B38: 8 mm metabólica | AM38: =SUM(C38:AL38) -> 0 | AN38: =AM38*25 -> 0
B39: 6 mm Sturgeon Rep. | AM39: =SUM(C39:AL39) -> 0 | AN39: =AM39*25 -> 0
B40: 8 mm Sturgeon Rep. | AM40: =SUM(C40:AL40) -> 0 | AN40: =AM40*25 -> 0
AM41: =SUM(C41:AL41) -> 0 | AN41: =AM41*25 -> 0
...

Sheet 8
C2: Oriente | I2: Poniente | O2: Nor Oriente | U2: Nor central | AA2: Nor Poniente | AG2: Central | AK2: J | AL2: H | AM2: Total
B3: Alimento ( sacos) | C3: 1 | D3: 2 | E3: 3 | F3: 4 | G3: 5 | H3: 6 | I3: 1 | J3: 2 | K3: 3 | L3: 4 | M3: 5 | N3: 6 | O3: 1 | P3: 2 | Q3: 3 | R3: 4 | S3: 5 | T3: 6 | U3: 1 | V3: 2 | W3: 3 | X3: 4 | Y3: 5 | Z3: 6 | AA3: 1 | AB3: 2 | AC3: 3 | AD3: 4 | AE3: 5 | AF3: 6 | AG3: 1 | AH3: 2 | AI3: 3 | AJ3: 4 | AM3: Sacos | AN3: Kg
A4: Lunes | B4: 3 mm progress ex | AM4: =SUM(C4:AL4) -> 0 | AN4: =AM4*25 -> 0
B5: 4,5 mm metabólica | AM5: =SUM(C5:AL5) -> 0 | AN5: =AM5*25 -> 0
B6: 6 mm metabólica | AM6: =SUM(C6:AL6) -> 0 | AN6: =AM6*25 -> 0
B7: 8 mm metabólica | AM7: =SUM(C7:AL7) -> 0 | AN7: =AM7*25 -> 0
B8: 6 mm Sturgeon Rep. | AM8: =SUM(C8:AL8) -> 0 | AN8: =AM8*25 -> 0
B9: 8 mm Sturgeon Rep. | AM9: =SUM(C9:AL9) -> 0 | AN9: =AM9*25 -> 0
AM10: =SUM(C10:AL10) -> 0 | AN10: =AM10*25 -> 0
AM11: =SUM(C11:AL11) -> 0 | AN11: =AM11*25 -> 0
A12: Martes | B12: 3 mm progress ex | AM12: =SUM(C12:AL12) -> 0 | AN12: =AM12*25 -> 0
B13: 4,5 mm metabólica | AM13: =SUM(C13:AL13) -> 0 | AN13: =AM13*25 -> 0
B14: 6 mm metabólica | AM14: =SUM(C14:AL14) -> 0 | AN14: =AM14*25 -> 0
B15: 8 mm metabólica | AM15: =SUM(C15:AL15) -> 0 | AN15: =AM15*25 -> 0
B16: 6 mm Sturgeon Rep. | AM16: =SUM(C16:AL16) -> 0 | AN16: =AM16*25 -> 0
B17: 8 mm Sturgeon Rep. | AM17: =SUM(C17:AL17) -> 0 | AN17: =AM17*25 -> 0
AM18: =SUM(C18:AL18) -> 0 | AN18: =AM18*25 -> 0
AM19: =SUM(C19:AL19) -> 0 | AN19: =AM19*25 -> 0
A20: Miércoles | B20: 3 mm progress ex | AM20: =SUM(C20:AL20) -> 0 | AN20: =AM20*25 -> 0
B21: 4,5 mm metabólica | AM21: =SUM(C21:AL21) -> 0 | AN21: =AM21*25 -> 0
B22: 6 mm metabólica | AM22: =SUM(C22:AL22) -> 0 | AN22: =AM22*25 -> 0
B23: 8 mm metabólica | AM23: =SUM(C23:AL23) -> 0 | AN23: =AM23*25 -> 0
B24: 6 mm Sturgeon Rep. | AM24: =SUM(C24:AL24) -> 0 | AN24: =AM24*25 -> 0
B25: 8 mm Sturgeon Rep. | AM25: =SUM(C25:AL25) -> 0 | AN25: =AM25*25 -> 0
AM26: =SUM(C26:AL26) -> 0 | AN26: =AM26*25 -> 0
AM27: =SUM(C27:AL27) -> 0 | AN27: =AM27*25 -> 0
A28: Jueves | B28: 3 mm progress ex | AM28: =SUM(C28:AL28) -> 0 | AN28: =AM28*25 -> 0
B29: 4,5 mm metabólica | AM29: =SUM(C29:AL29) -> 0 | AN29: =AM29*25 -> 0
B30: 6 mm metabólica | AM30: =SUM(C30:AL30) -> 0 | AN30: =AM30*25 -> 0
B31: 8 mm metabólica | AM31: =SUM(C31:AL31) -> 0 | AN31: =AM31*25 -> 0
B32: 6 mm Sturgeon Rep. | AM32: =SUM(C32:AL32) -> 0 | AN32: =AM32*25 -> 0
B33: 8 mm Sturgeon Rep. | AM33: =SUM(C33:AL33) -> 0 | AN33: =AM33*25 -> 0
AM34: =SUM(C34:AL34) -> 0 | AN34: =AM34*25 -> 0
A35: Viernes | B35: 3 mm progress ex | AM35: =SUM(C35:AL35) -> 0 | AN35: =AM35*25 -> 0
B36: 4,5 mm metabólica | AM36: =SUM(C36:AL36) -> 0 | AN36: =AM36*25 -> 0
B37: 6 mm metabólica | AM37: =SUM(C37:AL37) -> 0 | AN37: =AM37*25 -> 0
B38: 8 mm metabólica | AM38: =SUM(C38:AL38) -> 0 | AN38: =AM38*25 -> 0
B39: 6 mm Sturgeon Rep. | AM39: =SUM(C39:AL39) -> 0 | AN39: =AM39*25 -> 0
B40: 8 mm Sturgeon Rep. | AM40: =SUM(C40:AL40) -> 0 | AN40: =AM40*25 -> 0
AM41: =SUM(C41:AL41) -> 0 | AN41: =AM41*25 -> 0
...

Sheet 9
C2: Oriente | I2: Poniente | O2: Nor Oriente | U2: Nor central | AA2: Nor Poniente | AG2: Central | AK2: J | AL2: H | AM2: Total
B3: Alimento ( sacos) | C3: 1 | D3: 2 | E3: 3 | F3: 4 | G3: 5 | H3: 6 | I3: 1 | J3: 2 | K3: 3 | L3: 4 | M3: 5 | N3: 6 | O3: 1 | P3: 2 | Q3: 3 | R3: 4 | S3: 5 | T3: 6 | U3: 1 | V3: 2 | W3: 3 | X3: 4 | Y3: 5 | Z3: 6 | AA3: 1 | AB3: 2 | AC3: 3 | AD3: 4 | AE3: 5 | AF3: 6 | AG3: 1 | AH3: 2 | AI3: 3 | AJ3: 4 | AM3: Sacos | AN3: Kg
A4: Lunes | B4: 3 mm progress ex | AM4: =SUM(C4:AL4) -> 0 | AN4: =AM4*25 -> 0
B5: 4,5 mm metabólica | AM5: =SUM(C5:AL5) -> 0 | AN5: =AM5*25 -> 0
B6: 6 mm metabólica | AM6: =SUM(C6:AL6) -> 0 | AN6: =AM6*25 -> 0
B7: 8 mm metabólica | AM7: =SUM(C7:AL7) -> 0 | AN7: =AM7*25 -> 0
B8: 6 mm Sturgeon Rep. | AM8: =SUM(C8:AL8) -> 0 | AN8: =AM8*25 -> 0
B9: 8 mm Sturgeon Rep. | AM9: =SUM(C9:AL9) -> 0 | AN9: =AM9*25 -> 0
AM10: =SUM(C10:AL10) -> 0 | AN10: =AM10*25 -> 0
AM11: =SUM(C11:AL11) -> 0 | AN11: =AM11*25 -> 0
A12: Martes | B12: 3 mm progress ex | AM12: =SUM(C12:AL12) -> 0 | AN12: =AM12*25 -> 0
B13: 4,5 mm metabólica | AM13: =SUM(C13:AL13) -> 0 | AN13: =AM13*25 -> 0
B14: 6 mm metabólica | AM14: =SUM(C14:AL14) -> 0 | AN14: =AM14*25 -> 0
B15: 8 mm metabólica | AM15: =SUM(C15:AL15) -> 0 | AN15: =AM15*25 -> 0
B16: 6 mm Sturgeon Rep. | AM16: =SUM(C16:AL16) -> 0 | AN16: =AM16*25 -> 0
B17: 8 mm Sturgeon Rep. | AM17: =SUM(C17:AL17) -> 0 | AN17: =AM17*25 -> 0
AM18: =SUM(C18:AL18) -> 0 | AN18: =AM18*25 -> 0
AM19: =SUM(C19:AL19) -> 0 | AN19: =AM19*25 -> 0
A20: Miércoles | B20: 3 mm progress ex | AM20: =SUM(C20:AL20) -> 0 | AN20: =AM20*25 -> 0
B21: 4,5 mm metabólica | AM21: =SUM(C21:AL21) -> 0 | AN21: =AM21*25 -> 0
B22: 6 mm metabólica | AM22: =SUM(C22:AL22) -> 0 | AN22: =AM22*25 -> 0
B23: 8 mm metabólica | AM23: =SUM(C23:AL23) -> 0 | AN23: =AM23*25 -> 0
B24: 6 mm Sturgeon Rep. | AM24: =SUM(C24:AL24) -> 0 | AN24: =AM24*25 -> 0
B25: 8 mm Sturgeon Rep. | AM25: =SUM(C25:AL25) -> 0 | AN25: =AM25*25 -> 0
AM26: =SUM(C26:AL26) -> 0 | AN26: =AM26*25 -> 0
AM27: =SUM(C27:AL27) -> 0 | AN27: =AM27*25 -> 0
A28: Jueves | B28: 3 mm progress ex | AM28: =SUM(C28:AL28) -> 0 | AN28: =AM28*25 -> 0
B29: 4,5 mm metabólica | AM29: =SUM(C29:AL29) -> 0 | AN29: =AM29*25 -> 0
B30: 6 mm metabólica | AM30: =SUM(C30:AL30) -> 0 | AN30: =AM30*25 -> 0
B31: 8 mm metabólica | AM31: =SUM(C31:AL31) -> 0 | AN31: =AM31*25 -> 0
B32: 6 mm Sturgeon Rep. | AM32: =SUM(C32:AL32) -> 0 | AN32: =AM32*25 -> 0
B33: 8 mm Sturgeon Rep. | AM33: =SUM(C33:AL33) -> 0 | AN33: =AM33*25 -> 0
AM34: =SUM(C34:AL34) -> 0 | AN34: =AM34*25 -> 0
A35: Viernes | B35: 3 mm progress ex | AM35: =SUM(C35:AL35) -> 0 | AN35: =AM35*25 -> 0
B36: 4,5 mm metabólica | AM36: =SUM(C36:AL36) -> 0 | AN36: =AM36*25 -> 0
B37: 6 mm metabólica | AM37: =SUM(C37:AL37) -> 0 | AN37: =AM37*25 -> 0
B38: 8 mm metabólica | AM38: =SUM(C38:AL38) -> 0 | AN38: =AM38*25 -> 0
B39: 6 mm Sturgeon Rep. | AM39: =SUM(C39:AL39) -> 0 | AN39: =AM39*25 -> 0
B40: 8 mm Sturgeon Rep. | AM40: =SUM(C40:AL40) -> 0 | AN40: =AM40*25 -> 0
AM41: =SUM(C41:AL41) -> 0 | AN41: =AM41*25 -> 0
...

Sheet 10
C2: Oriente | I2: Poniente | O2: Nor Oriente | U2: Nor central | AA2: Nor Poniente | AG2: Central | AK2: J | AL2: H | AM2: Total
B3: Alimento ( sacos) | C3: 1 | D3: 2 | E3: 3 | F3: 4 | G3: 5 | H3: 6 | I3: 1 | J3: 2 | K3: 3 | L3: 4 | M3: 5 | N3: 6 | O3: 1 | P3: 2 | Q3: 3 | R3: 4 | S3: 5 | T3: 6 | U3: 1 | V3: 2 | W3: 3 | X3: 4 | Y3: 5 | Z3: 6 | AA3: 1 | AB3: 2 | AC3: 3 | AD3: 4 | AE3: 5 | AF3: 6 | AG3: 1 | AH3: 2 | AI3: 3 | AJ3: 4 | AM3: Sacos | AN3: Kg
A4: Lunes | B4: 3 mm progress ex | AM4: =SUM(C4:AL4) -> 0 | AN4: =AM4*25 -> 0
B5: 4,5 mm metabólica | AM5: =SUM(C5:AL5) -> 0 | AN5: =AM5*25 -> 0
B6: 6 mm metabólica | AM6: =SUM(C6:AL6) -> 0 | AN6: =AM6*25 -> 0
B7: 8 mm metabólica | AM7: =SUM(C7:AL7) -> 0 | AN7: =AM7*25 -> 0
B8: 6 mm Sturgeon Rep. | AM8: =SUM(C8:AL8) -> 0 | AN8: =AM8*25 -> 0
B9: 8 mm Sturgeon Rep. | AM9: =SUM(C9:AL9) -> 0 | AN9: =AM9*25 -> 0
AM10: =SUM(C10:AL10) -> 0 | AN10: =AM10*25 -> 0
AM11: =SUM(C11:AL11) -> 0 | AN11: =AM11*25 -> 0
A12: Martes | B12: 3 mm progress ex | AM12: =SUM(C12:AL12) -> 0 | AN12: =AM12*25 -> 0
B13: 4,5 mm metabólica | AM13: =SUM(C13:AL13) -> 0 | AN13: =AM13*25 -> 0
B14: 6 mm metabólica | AM14: =SUM(C14:AL14) -> 0 | AN14: =AM14*25 -> 0
B15: 8 mm metabólica | AM15: =SUM(C15:AL15) -> 0 | AN15: =AM15*25 -> 0
B16: 6 mm Sturgeon Rep. | AM16: =SUM(C16:AL16) -> 0 | AN16: =AM16*25 -> 0
B17: 8 mm Sturgeon Rep. | AM17: =SUM(C17:AL17) -> 0 | AN17: =AM17*25 -> 0
AM18: =SUM(C18:AL18) -> 0 | AN18: =AM18*25 -> 0
AM19: =SUM(C19:AL19) -> 0 | AN19: =AM19*25 -> 0
A20: Miércoles | B20: 3 mm progress ex | AM20: =SUM(C20:AL20) -> 0 | AN20: =AM20*25 -> 0
B21: 4,5 mm metabólica | AM21: =SUM(C21:AL21) -> 0 | AN21: =AM21*25 -> 0
B22: 6 mm metabólica | AM22: =SUM(C22:AL22) -> 0 | AN22: =AM22*25 -> 0
B23: 8 mm metabólica | AM23: =SUM(C23:AL23) -> 0 | AN23: =AM23*25 -> 0
B24: 6 mm Sturgeon Rep. | AM24: =SUM(C24:AL24) -> 0 | AN24: =AM24*25 -> 0
B25: 8 mm Sturgeon Rep. | AM25: =SUM(C25:AL25) -> 0 | AN25: =AM25*25 -> 0
AM26: =SUM(C26:AL26) -> 0 | AN26: =AM26*25 -> 0
AM27: =SUM(C27:AL27) -> 0 | AN27: =AM27*25 -> 0
A28: Jueves | B28: 3 mm progress ex | AM28: =SUM(C28:AL28) -> 0 | AN28: =AM28*25 -> 0
B29: 4,5 mm metabólica | AM29: =SUM(C29:AL29) -> 0 | AN29: =AM29*25 -> 0
B30: 6 mm metabólica | AM30: =SUM(C30:AL30) -> 0 | AN30: =AM30*25 -> 0
B31: 8 mm metabólica | AM31: =SUM(C31:AL31) -> 0 | AN31: =AM31*25 -> 0
B32: 6 mm Sturgeon Rep. | AM32: =SUM(C32:AL32) -> 0 | AN32: =AM32*25 -> 0
B33: 8 mm Sturgeon Rep. | AM33: =SUM(C33:AL33) -> 0 | AN33: =AM33*25 -> 0
AM34: =SUM(C34:AL34) -> 0 | AN34: =AM34*25 -> 0
A35: Viernes | B35: 3 mm progress ex | AM35: =SUM(C35:AL35) -> 0 | AN35: =AM35*25 -> 0
B36: 4,5 mm metabólica | AM36: =SUM(C36:AL36) -> 0 | AN36: =AM36*25 -> 0
B37: 6 mm metabólica | AM37: =SUM(C37:AL37) -> 0 | AN37: =AM37*25 -> 0
B38: 8 mm metabólica | AM38: =SUM(C38:AL38) -> 0 | AN38: =AM38*25 -> 0
B39: 6 mm Sturgeon Rep. | AM39: =SUM(C39:AL39) -> 0 | AN39: =AM39*25 -> 0
B40: 8 mm Sturgeon Rep. | AM40: =SUM(C40:AL40) -> 0 | AN40: =AM40*25 -> 0
AM41: =SUM(C41:AL41) -> 0 | AN41: =AM41*25 -> 0
...

Sheet Total
A1: Alimento | B1: SO1 | C1: SO2 | D1: SO3 | E1: SO4 | F1: SO5 | G1: SO6 | H1: SP1 | I1: SP2 | J1: SP3 | K1: SP4 | L1: SP5 | M1: SP6 | N1: NO1 | O1: NO2 | P1: NO3 | Q1: NO4 | R1: NO5 | S1: NO6 | T1: NC1 | U1: NC2 | V1: NC3 | W1: NC4 | X1: NC5 | Y1: NC6 | Z1: NP1 | AA1: NP2 | AB1: NP3 | AC1: NP4 | AD1: NP5 | AE1: NP6 | AF1: C1 | AG1: C2 | AH1: C3 | AI1: C4 | AJ1: J | AK1: H
A2: 3 mm progress ex | B2: ='1'!C66+'2'!C66+'3'!C66+'4'!C66+'5'!C66+'6'!C66+'7'!C66+'8'!C66+'9'!C66+'10'!C66 -> 0 | C2: ='1'!D66+'2'!D66+'3'!D66+'4'!D66+'5'!D66+'6'!D66+'7'!D66+'8'!D66+'9'!D66+'10'!D66 -> 0 | D2: ='1'!E66+'2'!E66+'3'!E66+'4'!E66+'5'!E66+'6'!E66+'7'!E66+'8'!E66+'9'!E66+'10'!E66 -> 0 | E2: ='1'!F66+'2'!F66+'3'!F66+'4'!F66+'5'!F66+'6'!F66+'7'!F66+'8'!F66+'9'!F66+'10'!F66 -> 0 | F2: ='1'!G66+'2'!G66+'3'!G66+'4'!G66+'5'!G66+'6'!G66+'7'!G66+'8'!G66+'9'!G66+'10'!G66 -> 0 | G2: ='1'!H66+'2'!H66+'3'!H66+'4'!H66+'5'!H66+'6'!H66+'7'!H66+'8'!H66+'9'!H66+'10'!H66 -> 0 | H2: ='1'!I66+'2'!I66+'3'!I66+'4'!I66+'5'!I66+'6'!I66+'7'!I66+'8'!I66+'9'!I66+'10'!I66 -> 0 | I2: ='1'!J66+'2'!J66+'3'!J66+'4'!J66+'5'!J66+'6'!J66+'7'!J66+'8'!J66+'9'!J66+'10'!J66 -> 0 | ... AK2: ='1'!AL66+'2'!AL66+'3'!AL66+'4'!AL66+'5'!AL66+'6'!AL66+'7'!AL66+'8'!AL66+'9'!AL66+'10'!AL66 -> 12 | AL2: =SUM(B2:AK2) -> 18 | AM2: =AL2*215 -> 3870
A3: 4,5 mm metabólica | B3: ='1'!C67+'2'!C67+'3'!C67+'4'!C67+'5'!C67+'6'!C67+'7'!C67+'8'!C67+'9'!C67+'10'!C67 -> 0 | C3: ='1'!D67+'2'!D67+'3'!D67+'4'!D67+'5'!D67+'6'!D67+'7'!D67+'8'!D67+'9'!D67+'10'!D67 -> 0 | D3: ='1'!E67+'2'!E67+'3'!E67+'4'!E67+'5'!E67+'6'!E67+'7'!E67+'8'!E67+'9'!E67+'10'!E67 -> 0 | E3: ='1'!F67+'2'!F67+'3'!F67+'4'!F67+'5'!F67+'6'!F67+'7'!F67+'8'!F67+'9'!F67+'10'!F67 -> 0 | F3: ='1'!G67+'2'!G67+'3'!G67+'4'!G67+'5'!G67+'6'!G67+'7'!G67+'8'!G67+'9'!G67+'10'!G67 -> 0 | G3: ='1'!H67+'2'!H67+'3'!H67+'4'!H67+'5'!H67+'6'!H67+'7'!H67+'8'!H67+'9'!H67+'10'!H67 -> 0 | H3: ='1'!I67+'2'!I67+'3'!I67+'4'!I67+'5'!I67+'6'!I67+'7'!I67+'8'!I67+'9'!I67+'10'!I67 -> 0 | I3: ='1'!J67+'2'!J67+'3'!J67+'4'!J67+'5'!J67+'6'!J67+'7'!J67+'8'!J67+'9'!J67+'10'!J67 -> 0 | ... AK3: ='1'!AL67+'2'!AL67+'3'!AL67+'4'!AL67+'5'!AL67+'6'!AL67+'7'!AL67+'8'!AL67+'9'!AL67+'10'!AL67 -> 0 | AL3: =SUM(B3:AK3) -> 26 | AM3: =AL3*215 -> 5590
A4: 6 mm metabólica | B4: ='1'!C68+'2'!C68+'3'!C68+'4'!C68+'5'!C68+'6'!C68+'7'!C68+'8'!C68+'9'!C68+'10'!C68 -> 8 | C4: ='1'!D68+'2'!D68+'3'!D68+'4'!D68+'5'!D68+'6'!D68+'7'!D68+'8'!D68+'9'!D68+'10'!D68 -> 13 | D4: ='1'!E68+'2'!E68+'3'!E68+'4'!E68+'5'!E68+'6'!E68+'7'!E68+'8'!E68+'9'!E68+'10'!E68 -> 12 | E4: ='1'!F68+'2'!F68+'3'!F68+'4'!F68+'5'!F68+'6'!F68+'7'!F68+'8'!F68+'9'!F68+'10'!F68 -> 5 | F4: ='1'!G68+'2'!G68+'3'!G68+'4'!G68+'5'!G68+'6'!G68+'7'!G68+'8'!G68+'9'!G68+'10'!G68 -> 9 | G4: ='1'!H68+'2'!H68+'3'!H68+'4'!H68+'5'!H68+'6'!H68+'7'!H68+'8'!H68+'9'!H68+'10'!H68 -> 9 | H4: ='1'!I68+'2'!I68+'3'!I68+'4'!I68+'5'!I68+'6'!I68+'7'!I68+'8'!I68+'9'!I68+'10'!I68 -> 2 | I4: ='1'!J68+'2'!J68+'3'!J68+'4'!J68+'5'!J68+'6'!J68+'7'!J68+'8'!J68+'9'!J68+'10'!J68 -> 13 | ... AK4: ='1'!AL68+'2'!AL68+'3'!AL68+'4'!AL68+'5'!AL68+'6'!AL68+'7'!AL68+'8'!AL68+'9'!AL68+'10'!AL68 -> 0 | AL4: =SUM(B4:AK4) -> 147 | AM4: =AL4*215 -> 31605
A5: 8 mm metabólica | B5: ='1'!C69+'2'!C69+'3'!C69+'4'!C69+'5'!C69+'6'!C69+'7'!C69+'8'!C69+'9'!C69+'10'!C69 -> 32 | C5: ='1'!D69+'2'!D69+'3'!D69+'4'!D69+'5'!D69+'6'!D69+'7'!D69+'8'!D69+'9'!D69+'10'!D69 -> 12 | D5: ='1'!E69+'2'!E69+'3'!E69+'4'!E69+'5'!E69+'6'!E69+'7'!E69+'8'!E69+'9'!E69+'10'!E69 -> 6 | E5: ='1'!F69+'2'!F69+'3'!F69+'4'!F69+'5'!F69+'6'!F69+'7'!F69+'8'!F69+'9'!F69+'10'!F69 -> 23 | F5: ='1'!G69+'2'!G69+'3'!G69+'4'!G69+'5'!G69+'6'!G69+'7'!G69+'8'!G69+'9'!G69+'10'!G69 -> 19 | G5: ='1'!H69+'2'!H69+'3'!H69+'4'!H69+'5'!H69+'6'!H69+'7'!H69+'8'!H69+'9'!H69+'10'!H69 -> 20 | H5: ='1'!I69+'2'!I69+'3'!I69+'4'!I69+'5'!I69+'6'!I69+'7'!I69+'8'!I69+'9'!I69+'10'!I69 -> 0 | I5: ='1'!J69+'2'!J69+'3'!J69+'4'!J69+'5'!J69+'6'!J69+'7'!J69+'8'!J69+'9'!J69+'10'!J69 -> 12 | ... AK5: ='1'!AL69+'2'!AL69+'3'!AL69+'4'!AL69+'5'!AL69+'6'!AL69+'7'!AL69+'8'!AL69+'9'!AL69+'10'!AL69 -> 0 | AL5: =SUM(B5:AK5) -> 171 | AM5: =AL5*215 -> 36765
A6: 6 mm Sturgeon Rep. | B6: ='1'!C70+'2'!C70+'3'!C70+'4'!C70+'5'!C70+'6'!C70+'7'!C70+'8'!C70+'9'!C70+'10'!C70 -> 0 | C6: ='1'!D70+'2'!D70+'3'!D70+'4'!D70+'5'!D70+'6'!D70+'7'!D70+'8'!D70+'9'!D70+'10'!D70 -> 0 | D6: ='1'!E70+'2'!E70+'3'!E70+'4'!E70+'5'!E70+'6'!E70+'7'!E70+'8'!E70+'9'!E70+'10'!E70 -> 0 | E6: ='1'!F70+'2'!F70+'3'!F70+'4'!F70+'5'!F70+'6'!F70+'7'!F70+'8'!F70+'9'!F70+'10'!F70 -> 0 | F6: ='1'!G70+'2'!G70+'3'!G70+'4'!G70+'5'!G70+'6'!G70+'7'!G70+'8'!G70+'9'!G70+'10'!G70 -> 0 | G6: ='1'!H70+'2'!H70+'3'!H70+'4'!H70+'5'!H70+'6'!H70+'7'!H70+'8'!H70+'9'!H70+'10'!H70 -> 0 | H6: ='1'!I70+'2'!I70+'3'!I70+'4'!I70+'5'!I70+'6'!I70+'7'!I70+'8'!I70+'9'!I70+'10'!I70 -> 0 | I6: ='1'!J70+'2'!J70+'3'!J70+'4'!J70+'5'!J70+'6'!J70+'7'!J70+'8'!J70+'9'!J70+'10'!J70 -> 0 | ... AK6: ='1'!AL70+'2'!AL70+'3'!AL70+'4'!AL70+'5'!AL70+'6'!AL70+'7'!AL70+'8'!AL70+'9'!AL70+'10'!AL70 -> 0 | AL6: =SUM(B6:AK6) -> 0 | AM6: =AL6*215 -> 0
A7: 8 mm Sturgeon Rep. | B7: ='1'!C71+'2'!C71+'3'!C71+'4'!C71+'5'!C71+'6'!C71+'7'!C71+'8'!C71+'9'!C71+'10'!C71 -> 10 | C7: ='1'!D71+'2'!D71+'3'!D71+'4'!D71+'5'!D71+'6'!D71+'7'!D71+'8'!D71+'9'!D71+'10'!D71 -> 0 | D7: ='1'!E71+'2'!E71+'3'!E71+'4'!E71+'5'!E71+'6'!E71+'7'!E71+'8'!E71+'9'!E71+'10'!E71 -> 0 | E7: ='1'!F71+'2'!F71+'3'!F71+'4'!F71+'5'!F71+'6'!F71+'7'!F71+'8'!F71+'9'!F71+'10'!F71 -> 4 | F7: ='1'!G71+'2'!G71+'3'!G71+'4'!G71+'5'!G71+'6'!G71+'7'!G71+'8'!G71+'9'!G71+'10'!G71 -> 8 | G7: ='1'!H71+'2'!H71+'3'!H71+'4'!H71+'5'!H71+'6'!H71+'7'!H71+'8'!H71+'9'!H71+'10'!H71 -> 8 | H7: ='1'!I71+'2'!I71+'3'!I71+'4'!I71+'5'!I71+'6'!I71+'7'!I71+'8'!I71+'9'!I71+'10'!I71 -> 0 | I7: ='1'!J71+'2'!J71+'3'!J71+'4'!J71+'5'!J71+'6'!J71+'7'!J71+'8'!J71+'9'!J71+'10'!J71 -> 0 | ... AK7: ='1'!AL71+'2'!AL71+'3'!AL71+'4'!AL71+'5'!AL71+'6'!AL71+'7'!AL71+'8'!AL71+'9'!AL71+'10'!AL71 -> 0 | AL7: =SUM(B7:AK7) -> 30 | AM7: =AL7*215 -> 6450
B8: ='1'!C72+'2'!C72+'3'!C72+'4'!C72+'5'!C72+'6'!C72+'7'!C72+'8'!C72+'9'!C72+'10'!C72 -> 0 | C8: ='1'!D72+'2'!D72+'3'!D72+'4'!D72+'5'!D72+'6'!D72+'7'!D72+'8'!D72+'9'!D72+'10'!D72 -> 0 | D8: ='1'!E72+'2'!E72+'3'!E72+'4'!E72+'5'!E72+'6'!E72+'7'!E72+'8'!E72+'9'!E72+'10'!E72 -> 0 | E8: ='1'!F72+'2'!F72+'3'!F72+'4'!F72+'5'!F72+'6'!F72+'7'!F72+'8'!F72+'9'!F72+'10'!F72 -> 0 | F8: ='1'!G72+'2'!G72+'3'!G72+'4'!G72+'5'!G72+'6'!G72+'7'!G72+'8'!G72+'9'!G72+'10'!G72 -> 0 | G8: ='1'!H72+'2'!H72+'3'!H72+'4'!H72+'5'!H72+'6'!H72+'7'!H72+'8'!H72+'9'!H72+'10'!H72 -> 0 | H8: ='1'!I72+'2'!I72+'3'!I72+'4'!I72+'5'!I72+'6'!I72+'7'!I72+'8'!I72+'9'!I72+'10'!I72 -> 0 | I8: ='1'!J72+'2'!J72+'3'!J72+'4'!J72+'5'!J72+'6'!J72+'7'!J72+'8'!J72+'9'!J72+'10'!J72 -> 0 | ... AK8: ='1'!AL72+'2'!AL72+'3'!AL72+'4'!AL72+'5'!AL72+'6'!AL72+'7'!AL72+'8'!AL72+'9'!AL72+'10'!AL72 -> 0 | AL8: =SUM(B8:AK8) -> 0 | AM8: =AL8*215 -> 0
A11: Alimentacion Consumida Mensual
A13: Ubicación | C13: Origen | D13: 0,2 mm infa | E13: 0,4 mm infa ex | F13: 0,5 mm thalassa ex | G13: 1,3 mm thalassa ex gr | H13: 3 mm progress ex | I13: 4,5 mm metabólica | J13: 6 mm metabólica | K13: 8 mm metabólica | L13: 6 mm Sturgeon Rep. | M13: 8 mm Sturgeon Rep.
A15: Lag. Sur Oriente | B15: SO1 | C15: Iberia | H15: =B2 -> 0 | I15: =B3 -> 0 | J15: =B4 -> 8 | K15: =B5 -> 32 | L15: =B6 -> 0 | M15: =B7 -> 10 | N15: =+B15 -> SO1
B16: SO2 | C16: Iberia | H16: =C2 -> 0 | I16: =C3 -> 0 | J16: =C4 -> 13 | K16: =C5 -> 12 | L16: =C6 -> 0 | M16: =C7 -> 0 | N16: =+B16 -> SO2
B17: SO3 | C17: Fátima | H17: =D2 -> 0 | I17: =D3 -> 0 | J17: =D4 -> 12 | K17: =D5 -> 6 | L17: =D6 -> 0 | M17: =D7 -> 0 | N17: =+B17 -> SO3
B18: SO4 | C18: Oscetra | H18: =E2 -> 0 | I18: =E3 -> 0 | J18: =E4 -> 5 | K18: =E5 -> 23 | L18: =E6 -> 0 | M18: =E7 -> 4 | N18: =+B18 -> SO4
B19: SO5 | C19: Oscetra | H19: =F2 -> 0 | I19: =F3 -> 0 | J19: =F4 -> 9 | K19: =F5 -> 19 | L19: =F6 -> 0 | M19: =F7 -> 8 | N19: =+B19 -> SO5
B20: SO6 | C20: Fátima | H20: =G2 -> 0 | I20: =G3 -> 0 | J20: =G4 -> 9 | K20: =G5 -> 20 | L20: =G6 -> 0 | M20: =G7 -> 8 | N20: =+B20 -> SO6
A21: Lag. Sur Poniente | B21: SP1 | C21: Rosario | H21: =H2 -> 0 | I21: =H3 -> 0 | J21: =H4 -> 2 | K21: =H5 -> 0 | L21: =H6 -> 0 | M21: =H7 -> 0
B22: SP2 | C22: Guadalupe | H22: =I2 -> 0 | I22: =I3 -> 0 | J22: =I4 -> 13 | K22: =I5 -> 12 | L22: =I6 -> 0 | M22: =I7 -> 0
B23: SP3 | C23: Fátima | H23: =J2 -> 0 | I23: =J3 -> 0 | J23: =J4 -> 0 | K23: =J5 -> 0 | L23: =J6 -> 0 | M23: =J7 -> 0
B24: SP4 | C24: Fátima | H24: =K2 -> 0 | I24: =K3 -> 0 | J24: =K4 -> 17 | K24: =K5 -> 6 | L24: =K6 -> 0 | M24: =K7 -> 0
B25: SP5 | C25: Fátima | H25: =L2 -> 0 | I25: =L3 -> 0 | J25: =L4 -> 11 | K25: =L5 -> 12 | L25: =L6 -> 0 | M25: =L7 -> 0
B26: SP6 | C26: Del Carmen | H26: =M2 -> 0 | I26: =M3 -> 0 | J26: =M4 -> 6 | K26: =M5 -> 12 | L26: =M6 -> 0 | M26: =M7 -> 0
A27: Lag Nor Oriente | B27: NO1 | C27: Rosario | H27: =N2 -> 0 | I27: =N3 -> 4 | J27: =N4 -> 14 | K27: =N5 -> 0 | L27: =N6 -> 0 | M27: =N7 -> 0
B28: NO2 | H28: =O2 -> 0 | I28: =O3 -> 10 | J28: =O4 -> 0 | K28: =O5 -> 0 | L28: =O6 -> 0 | M28: =O7 -> 0
B29: NO3 | H29: =P2 -> 0 | I29: =P3 -> 0 | J29: =P4 -> 0 | K29: =P5 -> 0 | L29: =P6 -> 0 | M29: =P7 -> 0
B30: NO4 | H30: =Q2 -> 0 | I30: =Q3 -> 0 | J30: =Q4 -> 0 | K30: =Q5 -> 0 | L30: =Q6 -> 0 | M30: =Q7 -> 0
B31: NO5 | H31: =R2 -> 0 | I31: =R3 -> 4 | J31: =R4 -> 0 | K31: =R5 -> 0 | L31: =R6 -> 0 | M31: =R7 -> 0
B32: NO6 | C32: Rosario | H32: =S2 -> 0 | I32: =S3 -> 4 | J32: =S4 -> 14 | K32: =S5 -> 0 | L32: =S6 -> 0 | M32: =S7 -> 0
A33: Laguna Nor Central | B33: NC1 | H33: =T2 -> 0 | I33: =T3 -> 0 | J33: =T4 -> 0 | K33: =T5 -> 0 | L33: =T6 -> 0 | M33: =T7 -> 0
B34: NC2 | H34: =U2 -> 0 | I34: =U3 -> 0 | J34: =U4 -> 0 | K34: =U5 -> 0 | L34: =U6 -> 0 | M34: =U7 -> 0
B35: NC3 | H35: =V2 -> 0 | I35: =V3 -> 0 | J35: =V4 -> 0 | K35: =V5 -> 0 | L35: =V6 -> 0 | M35: =V7 -> 0
B36: NC4 | H36: =W2 -> 0 | I36: =W3 -> 0 | J36: =W4 -> 0 | K36: =W5 -> 0 | L36: =W6 -> 0 | M36: =W7 -> 0
B37: NC5 | H37: =X2 -> 0 | I37: =X3 -> 0 | J37: =X4 -> 0 | K37: =X5 -> 0 | L37: =X6 -> 0 | M37: =X7 -> 0
B38: NC6 | H38: =Y2 -> 0 | I38: =Y3 -> 0 | J38: =Y4 -> 0 | K38: =Y5 -> 0 | L38: =Y6 -> 0 | M38: =Y7 -> 0
A39: Laguna Nor Poniente | B39: NP1 | H39: =Z2 -> 0 | I39: =Z3 -> 0 | J39: =Z4 -> 0 | K39: =Z5 -> 0 | L39: =Z6 -> 0 | M39: =Z7 -> 0
B40: NP2 | H40: =AA2 -> 0 | I40: =AA3 -> 0 | J40: =AA4 -> 0 | K40: =AA5 -> 0 | L40: =AA6 -> 0 | M40: =AA7 -> 0
B41: NP3 | H41: =AB2 -> 0 | I41: =AB3 -> 0 | J41: =AB4 -> 0 | K41: =AB5 -> 0 | L41: =AB6 -> 0 | M41: =AB7 -> 0
B42: NP4 | H42: =AC2 -> 0 | I42: =AC3 -> 0 | J42: =AC4 -> 0 | K42: =AC5 -> 0 | L42: =AC6 -> 0 | M42: =AC7 -> 0
B43: NP5 | H43: =AD2 -> 0 | I43: =AD3 -> 0 | J43: =AD4 -> 0 | K43: =AD5 -> 0 | L43: =AD6 -> 0 | M43: =AD7 -> 0
B44: NP6 | H44: =AE2 -> 0 | I44: =AE3 -> 0 | J44: =AE4 -> 0 | K44: =AE5 -> 0 | L44: =AE6 -> 0 | M44: =AE7 -> 0
...

Sheet Total Consumo Mensual
A1: Registro | B1: PC 01.1 | D1: Programa de Crianza
A2: Versión: | B2: 0.24
A3: Fecha: | B3: 44701 | D3: RESUMEN MENSUAL EXISTENCIAS
A4: Elaborado Por: | B4: A - Vial
A5: Modificado por: | B5: R - Gatica | J5: Mes: | K5: Agosto
A6: Aprobado Por | B6: A - Vial | D6: Acuícola Alas S.A., Ruta 5 sur, Km 338, VII región, Parral | J6: Folio:
A7: Hojas: | B7: 1 de 3
A9: Alimentacion Consumida Mensual
A11: Ubicación | C11: Origen | D11: 0,2 mm infa | E11: 0,4 mm infa ex | F11: 0,5 mm thalassa ex | G11: 1,3 mm thalassa ex gr | H11: 3 mm progress ex | I11: 4,5 mm metabólica | J11: 6 mm metabólica | K11: 8 mm metabólica | L11: 6 mm Sturgeon Rep. | M11: 8 mm Sturgeon Rep.
A12: Lag. Sur Oriente | B12: SO1 | C12: Iberia | H12: =Total!H15*25 -> 0 | I12: =Total!I15*25 -> 0 | J12: =Total!J15*25 -> 200 | K12: =Total!K15*25 -> 800 | L12: =Total!L15*25 -> 0 | M12: =Total!M15*25 -> 250 | N12: =+B12 -> SO1
B13: SO2 | C13: Iberia | H13: =Total!H16*25 -> 0 | I13: =Total!I16*25 -> 0 | J13: =Total!J16*25 -> 325 | K13: =Total!K16*25 -> 300 | L13: =Total!L16*25 -> 0 | M13: =Total!M16*25 -> 0 | N13: =+B13 -> SO2
B14: SO3 | C14: Fátima | H14: =Total!H17*25 -> 0 | I14: =Total!I17*25 -> 0 | J14: =Total!J17*25 -> 300 | K14: =Total!K17*25 -> 150 | L14: =Total!L17*25 -> 0 | M14: =Total!M17*25 -> 0 | N14: =+B14 -> SO3
B15: SO4 | C15: Oscetra | H15: =Total!H18*25 -> 0 | I15: =Total!I18*25 -> 0 | J15: =Total!J18*25 -> 125 | K15: =Total!K18*25 -> 575 | L15: =Total!L18*25 -> 0 | M15: =Total!M18*25 -> 100 | N15: =+B15 -> SO4
B16: SO5 | C16: Oscetra | H16: =Total!H19*25 -> 0 | I16: =Total!I19*25 -> 0 | J16: =Total!J19*25 -> 225 | K16: =Total!K19*25 -> 475 | L16: =Total!L19*25 -> 0 | M16: =Total!M19*25 -> 200 | N16: =+B16 -> SO5
B17: SO6 | C17: Fátima | H17: =Total!H20*25 -> 0 | I17: =Total!I20*25 -> 0 | J17: =Total!J20*25 -> 225 | K17: =Total!K20*25 -> 500 | L17: =Total!L20*25 -> 0 | M17: =Total!M20*25 -> 200 | N17: =+B17 -> SO6
A18: Lag. Sur Poniente | B18: SP1 | C18: Rosario | H18: =Total!H21*25 -> 0 | I18: =Total!I21*25 -> 0 | J18: =Total!J21*25 -> 50 | K18: =Total!K21*25 -> 0 | L18: =Total!L21*25 -> 0 | M18: =Total!M21*25 -> 0
B19: SP2 | C19: Guadalupe | H19: =Total!H22*25 -> 0 | I19: =Total!I22*25 -> 0 | J19: =Total!J22*25 -> 325 | K19: =Total!K22*25 -> 300 | L19: =Total!L22*25 -> 0 | M19: =Total!M22*25 -> 0
B20: SP3 | C20: Fátima | H20: =Total!H23*25 -> 0 | I20: =Total!I23*25 -> 0 | J20: =Total!J23*25 -> 0 | K20: =Total!K23*25 -> 0 | L20: =Total!L23*25 -> 0 | M20: =Total!M23*25 -> 0
B21: SP4 | C21: Fátima | H21: =Total!H24*25 -> 0 | I21: =Total!I24*25 -> 0 | J21: =Total!J24*25 -> 425 | K21: =Total!K24*25 -> 150 | L21: =Total!L24*25 -> 0 | M21: =Total!M24*25 -> 0
B22: SP5 | C22: Fátima | H22: =Total!H25*25 -> 0 | I22: =Total!I25*25 -> 0 | J22: =Total!J25*25 -> 275 | K22: =Total!K25*25 -> 300 | L22: =Total!L25*25 -> 0 | M22: =Total!M25*25 -> 0
B23: SP6 | C23: Del Carmen | H23: =Total!H26*25 -> 0 | I23: =Total!I26*25 -> 0 | J23: =Total!J26*25 -> 150 | K23: =Total!K26*25 -> 300 | L23: =Total!L26*25 -> 0 | M23: =Total!M26*25 -> 0
A24: Lag Nor Oriente | B24: NO1 | C24: Rosario | H24: =Total!H27*25 -> 0 | I24: =Total!I27*25 -> 100 | J24: =Total!J27*25 -> 350 | K24: =Total!K27*25 -> 0 | L24: =Total!L27*25 -> 0 | M24: =Total!M27*25 -> 0
B25: NO2 | C25: Pilar | H25: =Total!H28*25 -> 0 | I25: =Total!I28*25 -> 250 | J25: =Total!J28*25 -> 0 | K25: =Total!K28*25 -> 0 | L25: =Total!L28*25 -> 0 | M25: =Total!M28*25 -> 0
B26: NO3 | C26: Pilar | H26: =Total!H29*25 -> 0 | I26: =Total!I29*25 -> 0 | J26: =Total!J29*25 -> 0 | K26: =Total!K29*25 -> 0 | L26: =Total!L29*25 -> 0 | M26: =Total!M29*25 -> 0
B27: NO4 | H27: =Total!H30*25 -> 0 | I27: =Total!I30*25 -> 0 | J27: =Total!J30*25 -> 0 | K27: =Total!K30*25 -> 0 | L27: =Total!L30*25 -> 0 | M27: =Total!M30*25 -> 0
B28: NO5 | C28: Del Carmen | H28: =Total!H31*25 -> 0 | I28: =Total!I31*25 -> 100 | J28: =Total!J31*25 -> 0 | K28: =Total!K31*25 -> 0 | L28: =Total!L31*25 -> 0 | M28: =Total!M31*25 -> 0
B29: NO6 | C29: Rosario | H29: =Total!H32*25 -> 0 | I29: =Total!I32*25 -> 100 | J29: =Total!J32*25 -> 350 | K29: =Total!K32*25 -> 0 | L29: =Total!L32*25 -> 0 | M29: =Total!M32*25 -> 0
A30: Laguna Nor Central | B30: NC1 | H30: =Total!H33*25 -> 0 | I30: =Total!I33*25 -> 0 | J30: =Total!J33*25 -> 0 | K30: =Total!K33*25 -> 0 | L30: =Total!L33*25 -> 0 | M30: =Total!M33*25 -> 0
B31: NC2 | H31: =Total!H34*25 -> 0 | I31: =Total!I34*25 -> 0 | J31: =Total!J34*25 -> 0 | K31: =Total!K34*25 -> 0 | L31: =Total!L34*25 -> 0 | M31: =Total!M34*25 -> 0
B32: NC3 | H32: =Total!H35*25 -> 0 | I32: =Total!I35*25 -> 0 | J32: =Total!J35*25 -> 0 | K32: =Total!K35*25 -> 0 | L32: =Total!L35*25 -> 0 | M32: =Total!M35*25 -> 0
B33: NC4 | H33: =Total!H36*25 -> 0 | I33: =Total!I36*25 -> 0 | J33: =Total!J36*25 -> 0 | K33: =Total!K36*25 -> 0 | L33: =Total!L36*25 -> 0 | M33: =Total!M36*25 -> 0
B34: NC5 | H34: =Total!H37*25 -> 0 | I34: =Total!I37*25 -> 0 | J34: =Total!J37*25 -> 0 | K34: =Total!K37*25 -> 0 | L34: =Total!L37*25 -> 0 | M34: =Total!M37*25 -> 0
B35: NC6 | H35: =Total!H38*25 -> 0 | I35: =Total!I38*25 -> 0 | J35: =Total!J38*25 -> 0 | K35: =Total!K38*25 -> 0 | L35: =Total!L38*25 -> 0 | M35: =Total!M38*25 -> 0
A36: Laguna Nor Poniente | B36: NP1 | H36: =Total!H39*25 -> 0 | I36: =Total!I39*25 -> 0 | J36: =Total!J39*25 -> 0 | K36: =Total!K39*25 -> 0 | L36: =Total!L39*25 -> 0 | M36: =Total!M39*25 -> 0
B37: NP2 | H37: =Total!H40*25 -> 0 | I37: =Total!I40*25 -> 0 | J37: =Total!J40*25 -> 0 | K37: =Total!K40*25 -> 0 | L37: =Total!L40*25 -> 0 | M37: =Total!M40*25 -> 0
B38: NP3 | H38: =Total!H41*25 -> 0 | I38: =Total!I41*25 -> 0 | J38: =Total!J41*25 -> 0 | K38: =Total!K41*25 -> 0 | L38: =Total!L41*25 -> 0 | M38: =Total!M41*25 -> 0
B39: NP4 | H39: =Total!H42*25 -> 0 | I39: =Total!I42*25 -> 0 | J39: =Total!J42*25 -> 0 | K39: =Total!K42*25 -> 0 | L39: =Total!L42*25 -> 0 | M39: =Total!M42*25 -> 0
B40: NP5 | H40: =Total!H43*25 -> 0 | I40: =Total!I43*25 -> 0 | J40: =Total!J43*25 -> 0 | K40: =Total!K43*25 -> 0 | L40: =Total!L43*25 -> 0 | M40: =Total!M43*25 -> 0
B41: NP6 | H41: =Total!H44*25 -> 0 | I41: =Total!I44*25 -> 0 | J41: =Total!J44*25 -> 0 | K41: =Total!K44*25 -> 0 | L41: =Total!L44*25 -> 0 | M41: =Total!M44*25 -> 0
A42: Laguna Central | B42: C1 | C42: Dolores | H42: =Total!H45*25 -> 0 | I42: =Total!I45*25 -> 0 | J42: =Total!J45*25 -> 50 | K42: =Total!K45*25 -> 100 | L42: =Total!L45*25 -> 0 | M42: =Total!M45*25 -> 0 | N42: =+B42 -> C1
...
