Workbook

Sheet 1
A1: Registro: | C1: PC 02.1 | F1: Programa de Crianza
A2: Versión: | C2: 2.2
A3: Fecha: | C3: 44589 | F3: Retiro de Alimentación Piscinas exteriores
A4: Elaborado por: | C4: R - Gatica
A5: Revisado por: | C5: A -Vial | F5: Acuícola Alas S.A., Ruta 5 sur, Km 338, VII región, Parral | AC5: Folio:
A6: Aprobado por: | C6: A -Vial
A8: Nombre quien retira: | P8: Supervisor: | AB8: Enero | AH8: 1 | AM8: 5
A9: Firma: | P9: Firma:
C11: Oriente | I11: Poniente | O11: Nor Oriente | U11: Nor central | AA11: Nor Poniente | AG11: Central | AM11: J | AN11: H | AO11: Total
B12: Alimento ( sacos) | C12: 1 | D12: 2 | E12: 3 | F12: 4 | G12: 5 | H12: 6 | I12: 1 | J12: 2 | K12: 3 | L12: 4 | M12: 5 | N12: 6 | O12: 1 | P12: 2 | Q12: 3 | R12: 4 | S12: 5 | T12: 6 | U12: 1 | V12: 2 | W12: 3 | X12: 4 | Y12: 5 | Z12: 6 | AA12: 1 | AB12: 2 | AC12: 3 | AD12: 4 | AE12: 5 | AF12: 6 | AG12: 1 | AH12: 2 | AI12: 3 | AJ12: 4 | AK12: 5 | AL12: 6 | AO12: Sacos | AP12: Kg
A13: Lunes | B13: 3 mm progress ex | AL13: 1 | AO13: =SUM(C13:AN13) -> 1 | AP13: =AO13*25 -> 25
B14: 4,5 mm metabólica | AO14: =SUM(C14:AN14) -> 0 | AP14: =AO14*25 -> 0
B15: 4.5 mm Progress | P15: 1 | Q15: 1 | AL15: 1 | AO15: =SUM(C15:AN15) -> 3 | AP15: =AO15*25 -> 75
B16: 6 mm Metabolica | AO16: =SUM(C16:AN16) -> 0 | AP16: =AO16*25 -> 0
B17: 6 mm Progress | O17: 1 | R17: 1 | S17: 1 | U17: 1 | V17: 1 | W17: 1 | X17: 1 | Y17: 1 | Z17: 1 | AO17: =SUM(C17:AN17) -> 9 | AP17: =AO17*25 -> 225
B18: 8 mm Progress | AO18: =SUM(C18:AN18) -> 0 | AP18: =AO18*25 -> 0
B19: 8 mm Reproductor | S19: 1 | U19: 1 | V19: 1 | W19: 1 | X19: 1 | Y19: 1 | Z19: 1 | AA19: 1 | AB19: 0 | AC19: 1 | AD19: 1 | AO19: =SUM(C19:AN19) -> 10 | AP19: =AO19*25 -> 250
A21: Martes | B21: 3 mm progress ex | AO21: =SUM(C21:AN21) -> 0 | AP21: =AO21*25 -> 0
B22: 4,5 mm metabólica | AO22: =SUM(C22:AN22) -> 0 | AP22: =AO22*25 -> 0
B23: 4.5 mm Progress | AO23: =SUM(C23:AN23) -> 0 | AP23: =AO23*25 -> 0
B24: 6 mm Metabolica | AO24: =SUM(C24:AN24) -> 0 | AP24: =AO24*25 -> 0
B25: 6 mm Progress | AO25: =SUM(C25:AN25) -> 0 | AP25: =AO25*25 -> 0
B26: 8 mm Progress | AO26: =SUM(C26:AN26) -> 0 | AP26: =AO26*25 -> 0
B27: 8 mm Reproductor | AO27: =SUM(C27:AN27) -> 0 | AP27: =AO27*25 -> 0
A29: Miércoles | B29: 3 mm progress ex | AO29: =SUM(C29:AN29) -> 0 | AP29: =AO29*25 -> 0
B30: 4,5 mm metabólica | AO30: =SUM(C30:AN30) -> 0 | AP30: =AO30*25 -> 0
B31: 4.5 mm Progress | AO31: =SUM(C31:AN31) -> 0 | AP31: =AO31*25 -> 0
B32: 6 mm Metabolica | AO32: =SUM(C32:AN32) -> 0 | AP32: =AO32*25 -> 0
B33: 6 mm Progress | AO33: =SUM(C33:AN33) -> 0 | AP33: =AO33*25 -> 0
B34: 8 mm Progress | AO34: =SUM(C34:AN34) -> 0 | AP34: =AO34*25 -> 0
B35: 8 mm Reproductor | AO35: =SUM(C35:AN35) -> 0 | AP35: =AO35*25 -> 0
A37: Jueves | B37: 3 mm progress ex | AO37: =SUM(C37:AN37) -> 0 | AP37: =AO37*25 -> 0
B38: 4,5 mm metabólica | AO38: =SUM(C38:AN38) -> 0 | AP38: =AO38*25 -> 0
B39: 4.5 mm Progress | AO39: =SUM(C39:AN39) -> 0 | AP39: =AO39*25 -> 0
B40: 6 mm Metabolica | AO40: =SUM(C40:AN40) -> 0 | AP40: =AO40*25 -> 0
B41: 6 mm Progress | AO41: =SUM(C41:AN41) -> 0 | AP41: =AO41*25 -> 0
B42: 8 mm Progress | AO42: =SUM(C42:AN42) -> 0 | AP42: =AO42*25 -> 0
B43: 8 mm Reproductor | AO43: =SUM(C43:AN43) -> 0 | AP43: =AO43*25 -> 0
A44: Viernes | B44: 3 mm progress ex | AL44: 1 | AO44: =SUM(C44:AN44) -> 1 | AP44: =AO44*25 -> 25
B45: 4,5 mm metabólica | AO45: =SUM(C45:AN45) -> 0 | AP45: =AO45*25 -> 0
...

Sheet 2
A1: Registro: | C1: PC 02.1 | F1: Programa de Crianza
A2: Versión: | C2: 2.2
A3: Fecha: | C3: 44589 | F3: Retiro de Alimentación Piscinas exteriores
A4: Elaborado por: | C4: R - Gatica
A5: Revisado por: | C5: A -Vial | F5: Acuícola Alas S.A., Ruta 5 sur, Km 338, VII región, Parral | AC5: Folio:
A6: Aprobado por: | C6: A -Vial
A8: Nombre quien retira: | P8: Supervisor: | AB8: Enero | AH8: 6 | AM8: 12
A9: Firma: | P9: Firma:
C11: Oriente | I11: Poniente | O11: Nor Oriente | U11: Nor central | AA11: Nor Poniente | AG11: Central | AM11: J | AN11: H | AO11: Total
B12: Alimento ( sacos) | C12: 1 | D12: 2 | E12: 3 | F12: 4 | G12: 5 | H12: 6 | I12: 1 | J12: 2 | K12: 3 | L12: 4 | M12: 5 | N12: 6 | O12: 1 | P12: 2 | Q12: 3 | R12: 4 | S12: 5 | T12: 6 | U12: 1 | V12: 2 | W12: 3 | X12: 4 | Y12: 5 | Z12: 6 | AA12: 1 | AB12: 2 | AC12: 3 | AD12: 4 | AE12: 5 | AF12: 6 | AG12: 1 | AH12: 2 | AI12: 3 | AJ12: 4 | AK12: 5 | AL12: 6 | AO12: Sacos | AP12: Kg
A13: Lunes | B13: 3 mm progress ex | L13: 1 | AL13: 1 | AO13: =SUM(C13:AN13) -> 2 | AP13: =AO13*25 -> 50
B14: 4,5 mm metabólica | AO14: =SUM(C14:AN14) -> 0 | AP14: =AO14*25 -> 0
B15: 4.5 mm Progress | O15: 1 | P15: 3 | Q15: 3 | T15: 1 | AO15: =SUM(C15:AN15) -> 8 | AP15: =AO15*25 -> 200
B16: 6 mm Metabolica | AO16: =SUM(C16:AN16) -> 0 | AP16: =AO16*25 -> 0
B17: 6 mm Progress | O17: 2 | AO17: =SUM(C17:AN17) -> 2 | AP17: =AO17*25 -> 50
B18: 8 mm Progress | R18: 1 | S18: 1 | U18: 1 | V18: 1 | AO18: =SUM(C18:AN18) -> 4 | AP18: =AO18*25 -> 100
B19: 8 mm Reproductor | R19: 1 | S19: 1 | U19: 1 | V19: 1 | W19: 1 | X19: 2 | Y19: 1 | Z19: 1 | AA19: 1 | AB19: 1 | AC19: 1 | AD19: 1 | AE19: 1 | AG19: 1 | AI19: 1 | AJ19: 1 | AO19: =SUM(C19:AN19) -> 17 | AP19: =AO19*25 -> 425
A21: Martes | B21: 3 mm progress ex | AO21: =SUM(C21:AN21) -> 0 | AP21: =AO21*25 -> 0
B22: 4,5 mm metabólica | AO22: =SUM(C22:AN22) -> 0 | AP22: =AO22*25 -> 0
B23: 4.5 mm Progress | AO23: =SUM(C23:AN23) -> 0 | AP23: =AO23*25 -> 0
B24: 6 mm Metabolica | AO24: =SUM(C24:AN24) -> 0 | AP24: =AO24*25 -> 0
B25: 6 mm Progress | AO25: =SUM(C25:AN25) -> 0 | AP25: =AO25*25 -> 0
B26: 8 mm Progress | AO26: =SUM(C26:AN26) -> 0 | AP26: =AO26*25 -> 0
B27: 8 mm Reproductor | AO27: =SUM(C27:AN27) -> 0 | AP27: =AO27*25 -> 0
A29: Miércoles | B29: 3 mm progress ex | AO29: =SUM(C29:AN29) -> 0 | AP29: =AO29*25 -> 0
B30: 4,5 mm metabólica | AO30: =SUM(C30:AN30) -> 0 | AP30: =AO30*25 -> 0
B31: 4.5 mm Progress | AO31: =SUM(C31:AN31) -> 0 | AP31: =AO31*25 -> 0
B32: 6 mm Metabolica | AO32: =SUM(C32:AN32) -> 0 | AP32: =AO32*25 -> 0
B33: 6 mm Progress | AO33: =SUM(C33:AN33) -> 0 | AP33: =AO33*25 -> 0
B34: 8 mm Progress | AO34: =SUM(C34:AN34) -> 0 | AP34: =AO34*25 -> 0
B35: 8 mm Reproductor | AO35: =SUM(C35:AN35) -> 0 | AP35: =AO35*25 -> 0
A37: Jueves | B37: 3 mm progress ex | AO37: =SUM(C37:AN37) -> 0 | AP37: =AO37*25 -> 0
B38: 4,5 mm metabólica | AO38: =SUM(C38:AN38) -> 0 | AP38: =AO38*25 -> 0
B39: 4.5 mm Progress | AO39: =SUM(C39:AN39) -> 0 | AP39: =AO39*25 -> 0
B40: 6 mm Metabolica | AO40: =SUM(C40:AN40) -> 0 | AP40: =AO40*25 -> 0
B41: 6 mm Progress | AO41: =SUM(C41:AN41) -> 0 | AP41: =AO41*25 -> 0
B42: 8 mm Progress | AO42: =SUM(C42:AN42) -> 0 | AP42: =AO42*25 -> 0
B43: 8 mm Reproductor | AO43: =SUM(C43:AN43) -> 0 | AP43: =AO43*25 -> 0
A44: Viernes | B44: 3 mm progress ex | K44: 1 | L44: 1 | AL44: 1 | AO44: =SUM(C44:AN44) -> 3 | AP44: =AO44*25 -> 75
B45: 4,5 mm metabólica | AO45: =SUM(C45:AN45) -> 0 | AP45: =AO45*25 -> 0
...

Sheet 3
A1: Registro: | C1: PC 02.1 | F1: Programa de Crianza
A2: Versión: | C2: 2.2
A3: Fecha: | C3: 44589 | F3: Retiro de Alimentación Piscinas exteriores
A4: Elaborado por: | C4: R - Gatica
A5: Revisado por: | C5: A -Vial | F5: Acuícola Alas S.A., Ruta 5 sur, Km 338, VII región, Parral | AC5: Folio:
A6: Aprobado por: | C6: A -Vial
A8: Nombre quien retira: | P8: Supervisor: | AB8: Enero | AH8: 13 | AM8: 19
A9: Firma: | P9: Firma:
C11: Oriente | I11: Poniente | O11: Nor Oriente | U11: Nor central | AA11: Nor Poniente | AG11: Central | AM11: J | AN11: H | AO11: Total
B12: Alimento ( sacos) | C12: 1 | D12: 2 | E12: 3 | F12: 4 | G12: 5 | H12: 6 | I12: 1 | J12: 2 | K12: 3 | L12: 4 | M12: 5 | N12: 6 | O12: 1 | P12: 2 | Q12: 3 | R12: 4 | S12: 5 | T12: 6 | U12: 1 | V12: 2 | W12: 3 | X12: 4 | Y12: 5 | Z12: 6 | AA12: 1 | AB12: 2 | AC12: 3 | AD12: 4 | AE12: 5 | AF12: 6 | AG12: 1 | AH12: 2 | AI12: 3 | AJ12: 4 | AK12: 5 | AL12: 6 | AO12: Sacos | AP12: Kg
A13: Lunes | B13: 3 mm progress ex | K13: 2 | L13: 1 | AL13: 1 | AO13: =SUM(C13:AN13) -> 4 | AP13: =AO13*25 -> 100
B14: 4,5 mm metabólica | AO14: =SUM(C14:AN14) -> 0 | AP14: =AO14*25 -> 0
B15: 4.5 mm Progress | P15: 1 | Q15: 1 | AL15: 1 | AO15: =SUM(C15:AN15) -> 3 | AP15: =AO15*25 -> 75
B16: 6 mm Metabolica | AO16: =SUM(C16:AN16) -> 0 | AP16: =AO16*25 -> 0
B17: 6 mm Progress | O17: 2 | R17: 2 | S17: 1 | U17: 1 | V17: 1 | AO17: =SUM(C17:AN17) -> 7 | AP17: =AO17*25 -> 175
B18: 8 mm Progress | R18: 1 | S18: 2 | U18: 1 | V18: 2 | W18: 2 | X18: 2 | Y18: 1 | Z18: 1 | AA18: 2 | AB18: 2 | AC18: 1 | AD18: 1 | AE18: 1 | AG18: 1 | AI18: 1 | AJ18: 1 | AO18: =SUM(C18:AN18) -> 22 | AP18: =AO18*25 -> 550
B19: 8 mm Reproductor | R19: 1 | S19: 2 | U19: 1 | V19: 2 | W19: 2 | X19: 2 | Y19: 1 | Z19: 1 | AA19: 1 | AB19: 1 | AC19: 1 | AD19: 1 | AE19: 1 | AG19: 1 | AI19: 1 | AJ19: 1 | AO19: =SUM(C19:AN19) -> 20 | AP19: =AO19*25 -> 500
A21: Martes | B21: 3 mm progress ex | AO21: =SUM(C21:AN21) -> 0 | AP21: =AO21*25 -> 0
B22: 4,5 mm metabólica | AO22: =SUM(C22:AN22) -> 0 | AP22: =AO22*25 -> 0
B23: 4.5 mm Progress | AO23: =SUM(C23:AN23) -> 0 | AP23: =AO23*25 -> 0
B24: 6 mm Metabolica | AO24: =SUM(C24:AN24) -> 0 | AP24: =AO24*25 -> 0
B25: 6 mm Progress | AO25: =SUM(C25:AN25) -> 0 | AP25: =AO25*25 -> 0
B26: 8 mm Progress | AO26: =SUM(C26:AN26) -> 0 | AP26: =AO26*25 -> 0
B27: 8 mm Reproductor | AO27: =SUM(C27:AN27) -> 0 | AP27: =AO27*25 -> 0
A29: Miércoles | B29: 3 mm progress ex | AO29: =SUM(C29:AN29) -> 0 | AP29: =AO29*25 -> 0
B30: 4,5 mm metabólica | AO30: =SUM(C30:AN30) -> 0 | AP30: =AO30*25 -> 0
B31: 4.5 mm Progress | AO31: =SUM(C31:AN31) -> 0 | AP31: =AO31*25 -> 0
B32: 6 mm Metabolica | AO32: =SUM(C32:AN32) -> 0 | AP32: =AO32*25 -> 0
B33: 6 mm Progress | AO33: =SUM(C33:AN33) -> 0 | AP33: =AO33*25 -> 0
B34: 8 mm Progress | AO34: =SUM(C34:AN34) -> 0 | AP34: =AO34*25 -> 0
B35: 8 mm Reproductor | AO35: =SUM(C35:AN35) -> 0 | AP35: =AO35*25 -> 0
A37: Jueves | B37: 3 mm progress ex | AO37: =SUM(C37:AN37) -> 0 | AP37: =AO37*25 -> 0
B38: 4,5 mm metabólica | AO38: =SUM(C38:AN38) -> 0 | AP38: =AO38*25 -> 0
B39: 4.5 mm Progress | AO39: =SUM(C39:AN39) -> 0 | AP39: =AO39*25 -> 0
B40: 6 mm Metabolica | AO40: =SUM(C40:AN40) -> 0 | AP40: =AO40*25 -> 0
B41: 6 mm Progress | AO41: =SUM(C41:AN41) -> 0 | AP41: =AO41*25 -> 0
B42: 8 mm Progress | AO42: =SUM(C42:AN42) -> 0 | AP42: =AO42*25 -> 0
B43: 8 mm Reproductor | AO43: =SUM(C43:AN43) -> 0 | AP43: =AO43*25 -> 0
A44: Viernes | B44: 3 mm progress ex | K44: 2 | L44: 2 | AL44: 1 | AO44: =SUM(C44:AN44) -> 5 | AP44: =AO44*25 -> 125
B45: 4,5 mm metabólica | AO45: =SUM(C45:AN45) -> 0 | AP45: =AO45*25 -> 0
...

Sheet 4
A1: Registro: | C1: PC 02.1 | F1: Programa de Crianza
A2: Versión: | C2: 2.2
A3: Fecha: | C3: 44589 | F3: Retiro de Alimentación Piscinas exteriores
A4: Elaborado por: | C4: R - Gatica
A5: Revisado por: | C5: A -Vial | F5: Acuícola Alas S.A., Ruta 5 sur, Km 338, VII región, Parral | AC5: Folio:
A6: Aprobado por: | C6: A -Vial
A8: Nombre quien retira: | P8: Supervisor: | AB8: Enero | AH8: 20 | AM8: 26
A9: Firma: | P9: Firma:
C11: Oriente | I11: Poniente | O11: Nor Oriente | U11: Nor central | AA11: Nor Poniente | AG11: Central | AM11: J | AN11: H | AO11: Total
B12: Alimento ( sacos) | C12: 1 | D12: 2 | E12: 3 | F12: 4 | G12: 5 | H12: 6 | I12: 1 | J12: 2 | K12: 3 | L12: 4 | M12: 5 | N12: 6 | O12: 1 | P12: 2 | Q12: 3 | R12: 4 | S12: 5 | T12: 6 | U12: 1 | V12: 2 | W12: 3 | X12: 4 | Y12: 5 | Z12: 6 | AA12: 1 | AB12: 2 | AC12: 3 | AD12: 4 | AE12: 5 | AF12: 6 | AG12: 1 | AH12: 2 | AI12: 3 | AJ12: 4 | AK12: 5 | AL12: 6 | AO12: Sacos | AP12: Kg
A13: Lunes | B13: 3 mm progress ex | K13: 2 | L13: 1 | AL13: 1 | AO13: =SUM(C13:AN13) -> 4 | AP13: =AO13*25 -> 100
B14: 4,5 mm metabólica | AO14: =SUM(C14:AN14) -> 0 | AP14: =AO14*25 -> 0
B15: 4.5 mm Progress | L15: 1 | P15: 1 | Q15: 1 | AL15: 1 | AO15: =SUM(C15:AN15) -> 4 | AP15: =AO15*25 -> 100
B16: 6 mm Metabolica | AO16: =SUM(C16:AN16) -> 0 | AP16: =AO16*25 -> 0
B17: 6 mm Progress | O17: 3 | R17: 1 | S17: 2 | U17: 1 | V17: 2 | AO17: =SUM(C17:AN17) -> 9 | AP17: =AO17*25 -> 225
B18: 8 mm Progress | U18: 1 | V18: 2 | W18: 2 | X18: 2 | Y18: 1 | Z18: 1 | AA18: 2 | AB18: 2 | AC18: 1 | AD18: 1 | AO18: =SUM(C18:AN18) -> 15 | AP18: =AO18*25 -> 375
B19: 8 mm Reproductor | U19: 1 | V19: 2 | W19: 2 | X19: 2 | Y19: 1 | Z19: 2 | AA19: 1 | AB19: 2 | AC19: 2 | AD19: 1 | AO19: =SUM(C19:AN19) -> 16 | AP19: =AO19*25 -> 400
A21: Martes | B21: 3 mm progress ex | AO21: =SUM(C21:AN21) -> 0 | AP21: =AO21*25 -> 0
B22: 4,5 mm metabólica | AO22: =SUM(C22:AN22) -> 0 | AP22: =AO22*25 -> 0
B23: 4.5 mm Progress | AO23: =SUM(C23:AN23) -> 0 | AP23: =AO23*25 -> 0
B24: 6 mm Metabolica | AO24: =SUM(C24:AN24) -> 0 | AP24: =AO24*25 -> 0
B25: 6 mm Progress | AO25: =SUM(C25:AN25) -> 0 | AP25: =AO25*25 -> 0
B26: 8 mm Progress | AO26: =SUM(C26:AN26) -> 0 | AP26: =AO26*25 -> 0
B27: 8 mm Reproductor | AO27: =SUM(C27:AN27) -> 0 | AP27: =AO27*25 -> 0
A29: Miércoles | B29: 3 mm progress ex | AO29: =SUM(C29:AN29) -> 0 | AP29: =AO29*25 -> 0
B30: 4,5 mm metabólica | AO30: =SUM(C30:AN30) -> 0 | AP30: =AO30*25 -> 0
B31: 4.5 mm Progress | AO31: =SUM(C31:AN31) -> 0 | AP31: =AO31*25 -> 0
B32: 6 mm Metabolica | AO32: =SUM(C32:AN32) -> 0 | AP32: =AO32*25 -> 0
B33: 6 mm Progress | AO33: =SUM(C33:AN33) -> 0 | AP33: =AO33*25 -> 0
B34: 8 mm Progress | AO34: =SUM(C34:AN34) -> 0 | AP34: =AO34*25 -> 0
B35: 8 mm Reproductor | AO35: =SUM(C35:AN35) -> 0 | AP35: =AO35*25 -> 0
A37: Jueves | B37: 3 mm progress ex | AO37: =SUM(C37:AN37) -> 0 | AP37: =AO37*25 -> 0
B38: 4,5 mm metabólica | AO38: =SUM(C38:AN38) -> 0 | AP38: =AO38*25 -> 0
B39: 4.5 mm Progress | AO39: =SUM(C39:AN39) -> 0 | AP39: =AO39*25 -> 0
B40: 6 mm Metabolica | AO40: =SUM(C40:AN40) -> 0 | AP40: =AO40*25 -> 0
B41: 6 mm Progress | AO41: =SUM(C41:AN41) -> 0 | AP41: =AO41*25 -> 0
B42: 8 mm Progress | AO42: =SUM(C42:AN42) -> 0 | AP42: =AO42*25 -> 0
B43: 8 mm Reproductor | AO43: =SUM(C43:AN43) -> 0 | AP43: =AO43*25 -> 0
A44: Viernes | B44: 3 mm progress ex | K44: 2 | L44: 2 | AO44: =SUM(C44:AN44) -> 4 | AP44: =AO44*25 -> 100
B45: 4,5 mm metabólica | AO45: =SUM(C45:AN45) -> 0 | AP45: =AO45*25 -> 0
...

Sheet 5
A1: Registro: | C1: PC 02.1 | F1: Programa de Crianza
A2: Versión: | C2: 2.2
A3: Fecha: | C3: 44589 | F3: Retiro de Alimentación Piscinas exteriores
A4: Elaborado por: | C4: R - Gatica
A5: Revisado por: | C5: A -Vial | F5: Acuícola Alas S.A., Ruta 5 sur, Km 338, VII región, Parral | AC5: Folio:
A6: Aprobado por: | C6: A -Vial
A8: Nombre quien retira: | P8: Supervisor: | AB8: Enero | AH8: 27 | AM8: 31
A9: Firma: | P9: Firma:
C11: Oriente | I11: Poniente | O11: Nor Oriente | U11: Nor central | AA11: Nor Poniente | AG11: Central | AM11: J | AN11: H | AO11: Total
B12: Alimento ( sacos) | C12: 1 | D12: 2 | E12: 3 | F12: 4 | G12: 5 | H12: 6 | I12: 1 | J12: 2 | K12: 3 | L12: 4 | M12: 5 | N12: 6 | O12: 1 | P12: 2 | Q12: 3 | R12: 4 | S12: 5 | T12: 6 | U12: 1 | V12: 2 | W12: 3 | X12: 4 | Y12: 5 | Z12: 6 | AA12: 1 | AB12: 2 | AC12: 3 | AD12: 4 | AE12: 5 | AF12: 6 | AG12: 1 | AH12: 2 | AI12: 3 | AJ12: 4 | AK12: 5 | AL12: 6 | AO12: Sacos | AP12: Kg
A13: Lunes | B13: 3 mm progress ex | K13: 2 | L13: 2 | AL13: 1 | AO13: =SUM(C13:AN13) -> 5 | AP13: =AO13*25 -> 125
B14: 4,5 mm metabólica | AO14: =SUM(C14:AN14) -> 0 | AP14: =AO14*25 -> 0
B15: 4.5 mm Progress | K15: 1 | P15: 1 | Q15: 1 | AL15: 1 | AO15: =SUM(C15:AN15) -> 4 | AP15: =AO15*25 -> 100
B16: 6 mm Metabolica | AO16: =SUM(C16:AN16) -> 0 | AP16: =AO16*25 -> 0
B17: 6 mm Progress | O17: 3 | R17: 1 | S17: 2 | U17: 1 | V17: 2 | AO17: =SUM(C17:AN17) -> 9 | AP17: =AO17*25 -> 225
B18: 8 mm Progress | AO18: =SUM(C18:AN18) -> 0 | AP18: =AO18*25 -> 0
B19: 8 mm Reproductor | U19: 2 | V19: 2 | W19: 1 | X19: 1 | Y19: 1 | Z19: 2 | AA19: 1 | AB19: 1 | AC19: 1 | AD19: 1 | AE19: 1 | AF19: 1 | AO19: =SUM(C19:AN19) -> 15 | AP19: =AO19*25 -> 375
A21: Martes | B21: 3 mm progress ex | AO21: =SUM(C21:AN21) -> 0 | AP21: =AO21*25 -> 0
B22: 4,5 mm metabólica | AO22: =SUM(C22:AN22) -> 0 | AP22: =AO22*25 -> 0
B23: 4.5 mm Progress | AO23: =SUM(C23:AN23) -> 0 | AP23: =AO23*25 -> 0
B24: 6 mm Metabolica | AO24: =SUM(C24:AN24) -> 0 | AP24: =AO24*25 -> 0
B25: 6 mm Progress | AO25: =SUM(C25:AN25) -> 0 | AP25: =AO25*25 -> 0
B26: 8 mm Progress | AO26: =SUM(C26:AN26) -> 0 | AP26: =AO26*25 -> 0
B27: 8 mm Reproductor | AO27: =SUM(C27:AN27) -> 0 | AP27: =AO27*25 -> 0
A29: Miércoles | B29: 3 mm progress ex | AO29: =SUM(C29:AN29) -> 0 | AP29: =AO29*25 -> 0
B30: 4,5 mm metabólica | AO30: =SUM(C30:AN30) -> 0 | AP30: =AO30*25 -> 0
B31: 4.5 mm Progress | AO31: =SUM(C31:AN31) -> 0 | AP31: =AO31*25 -> 0
B32: 6 mm Metabolica | AO32: =SUM(C32:AN32) -> 0 | AP32: =AO32*25 -> 0
B33: 6 mm Progress | AO33: =SUM(C33:AN33) -> 0 | AP33: =AO33*25 -> 0
B34: 8 mm Progress | AO34: =SUM(C34:AN34) -> 0 | AP34: =AO34*25 -> 0
B35: 8 mm Reproductor | AO35: =SUM(C35:AN35) -> 0 | AP35: =AO35*25 -> 0
A37: Jueves | B37: 3 mm progress ex | AO37: =SUM(C37:AN37) -> 0 | AP37: =AO37*25 -> 0
B38: 4,5 mm metabólica | AO38: =SUM(C38:AN38) -> 0 | AP38: =AO38*25 -> 0
B39: 4.5 mm Progress | AO39: =SUM(C39:AN39) -> 0 | AP39: =AO39*25 -> 0
B40: 6 mm Metabolica | AO40: =SUM(C40:AN40) -> 0 | AP40: =AO40*25 -> 0
B41: 6 mm Progress | AO41: =SUM(C41:AN41) -> 0 | AP41: =AO41*25 -> 0
B42: 8 mm Progress | AO42: =SUM(C42:AN42) -> 0 | AP42: =AO42*25 -> 0
B43: 8 mm Reproductor | AO43: =SUM(C43:AN43) -> 0 | AP43: =AO43*25 -> 0
A44: Viernes | B44: 3 mm progress ex | AO44: =SUM(C44:AN44) -> 0 | AP44: =AO44*25 -> 0
B45: 4,5 mm metabólica | AO45: =SUM(C45:AN45) -> 0 | AP45: =AO45*25 -> 0
...

Sheet 6
A1: Registro: | C1: PC 02.1 | F1: Programa de Crianza
A2: Versión: | C2: 2.2
A3: Fecha: | C3: 44589 | F3: Retiro de Alimentación Piscinas exteriores
A4: Elaborado por: | C4: R - Gatica
A5: Revisado por: | C5: A -Vial | F5: Acuícola Alas S.A., Ruta 5 sur, Km 338, VII región, Parral | AC5: Folio:
A6: Aprobado por: | C6: A -Vial
A8: Nombre quien retira: | P8: Supervisor: | AB8: Agosto | AH8: 5 | AM8: 11
A9: Firma: | P9: Firma:
C11: Oriente | I11: Poniente | O11: Nor Oriente | U11: Nor central | AA11: Nor Poniente | AG11: Central | AM11: J | AN11: H | AO11: Total
B12: Alimento ( sacos) | C12: 1 | D12: 2 | E12: 3 | F12: 4 | G12: 5 | H12: 6 | I12: 1 | J12: 2 | K12: 3 | L12: 4 | M12: 5 | N12: 6 | O12: 1 | P12: 2 | Q12: 3 | R12: 4 | S12: 5 | T12: 6 | U12: 1 | V12: 2 | W12: 3 | X12: 4 | Y12: 5 | Z12: 6 | AA12: 1 | AB12: 2 | AC12: 3 | AD12: 4 | AE12: 5 | AF12: 6 | AG12: 1 | AH12: 2 | AI12: 3 | AJ12: 4 | AK12: 5 | AL12: 6 | AO12: Sacos | AP12: Kg
A13: Lunes | B13: 3 mm progress ex | AO13: =SUM(C13:AN13) -> 0 | AP13: =AO13*25 -> 0
B14: 4,5 mm metabólica | AO14: =SUM(C14:AN14) -> 0 | AP14: =AO14*25 -> 0
B15: 4.5 mm Progress | AO15: =SUM(C15:AN15) -> 0 | AP15: =AO15*25 -> 0
B16: 6 mm Metabolica | AO16: =SUM(C16:AN16) -> 0 | AP16: =AO16*25 -> 0
B17: 6 mm Progress | AO17: =SUM(C17:AN17) -> 0 | AP17: =AO17*25 -> 0
B18: 8 mm Progress | AO18: =SUM(C18:AN18) -> 0 | AP18: =AO18*25 -> 0
B19: 8 mm Reproductor | AO19: =SUM(C19:AN19) -> 0 | AP19: =AO19*25 -> 0
A21: Martes | B21: 3 mm progress ex | AO21: =SUM(C21:AN21) -> 0 | AP21: =AO21*25 -> 0
B22: 4,5 mm metabólica | AO22: =SUM(C22:AN22) -> 0 | AP22: =AO22*25 -> 0
B23: 4.5 mm Progress | AO23: =SUM(C23:AN23) -> 0 | AP23: =AO23*25 -> 0
B24: 6 mm Metabolica | AO24: =SUM(C24:AN24) -> 0 | AP24: =AO24*25 -> 0
B25: 6 mm Progress | AO25: =SUM(C25:AN25) -> 0 | AP25: =AO25*25 -> 0
B26: 8 mm Progress | AO26: =SUM(C26:AN26) -> 0 | AP26: =AO26*25 -> 0
B27: 8 mm Reproductor | AO27: =SUM(C27:AN27) -> 0 | AP27: =AO27*25 -> 0
A29: Miércoles | B29: 3 mm progress ex | AO29: =SUM(C29:AN29) -> 0 | AP29: =AO29*25 -> 0
B30: 4,5 mm metabólica | AO30: =SUM(C30:AN30) -> 0 | AP30: =AO30*25 -> 0
B31: 4.5 mm Progress | AO31: =SUM(C31:AN31) -> 0 | AP31: =AO31*25 -> 0
B32: 6 mm Metabolica | AO32: =SUM(C32:AN32) -> 0 | AP32: =AO32*25 -> 0
B33: 6 mm Progress | AO33: =SUM(C33:AN33) -> 0 | AP33: =AO33*25 -> 0
B34: 8 mm Progress | AO34: =SUM(C34:AN34) -> 0 | AP34: =AO34*25 -> 0
B35: 8 mm Reproductor | AO35: =SUM(C35:AN35) -> 0 | AP35: =AO35*25 -> 0
A37: Jueves | B37: 3 mm progress ex | AO37: =SUM(C37:AN37) -> 0 | AP37: =AO37*25 -> 0
B38: 4,5 mm metabólica | AO38: =SUM(C38:AN38) -> 0 | AP38: =AO38*25 -> 0
B39: 4.5 mm Progress | AO39: =SUM(C39:AN39) -> 0 | AP39: =AO39*25 -> 0
B40: 6 mm Metabolica | AO40: =SUM(C40:AN40) -> 0 | AP40: =AO40*25 -> 0
B41: 6 mm Progress | AO41: =SUM(C41:AN41) -> 0 | AP41: =AO41*25 -> 0
B42: 8 mm Progress | AO42: =SUM(C42:AN42) -> 0 | AP42: =AO42*25 -> 0
B43: 8 mm Reproductor | AO43: =SUM(C43:AN43) -> 0 | AP43: =AO43*25 -> 0
A44: Viernes | B44: 3 mm progress ex | AO44: =SUM(C44:AN44) -> 0 | AP44: =AO44*25 -> 0
B45: 4,5 mm metabólica | AO45: =SUM(C45:AN45) -> 0 | AP45: =AO45*25 -> 0
...

Sheet 7
A1: Registro: | C1: PC 02.1 | F1: Programa de Crianza
A2: Versión: | C2: 2.2
A3: Fecha: | C3: 44589 | F3: Retiro de Alimentación Piscinas exteriores
A4: Elaborado por: | C4: R - Gatica
A5: Revisado por: | C5: A -Vial | F5: Acuícola Alas S.A., Ruta 5 sur, Km 338, VII región, Parral | AC5: Folio:
A6: Aprobado por: | C6: A -Vial
A8: Nombre quien retira: | P8: Supervisor: | AB8: Agosto | AH8: 5 | AM8: 11
A9: Firma: | P9: Firma:
C11: Oriente | I11: Poniente | O11: Nor Oriente | U11: Nor central | AA11: Nor Poniente | AG11: Central | AM11: J | AN11: H | AO11: Total
B12: Alimento ( sacos) | C12: 1 | D12: 2 | E12: 3 | F12: 4 | G12: 5 | H12: 6 | I12: 1 | J12: 2 | K12: 3 | L12: 4 | M12: 5 | N12: 6 | O12: 1 | P12: 2 | Q12: 3 | R12: 4 | S12: 5 | T12: 6 | U12: 1 | V12: 2 | W12: 3 | X12: 4 | Y12: 5 | Z12: 6 | AA12: 1 | AB12: 2 | AC12: 3 | AD12: 4 | AE12: 5 | AF12: 6 | AG12: 1 | AH12: 2 | AI12: 3 | AJ12: 4 | AK12: 5 | AL12: 6 | AO12: Sacos | AP12: Kg
A13: Lunes | B13: 3 mm progress ex | AO13: =SUM(C13:AN13) -> 0 | AP13: =AO13*25 -> 0
B14: 4,5 mm metabólica | AO14: =SUM(C14:AN14) -> 0 | AP14: =AO14*25 -> 0
B15: 4.5 mm Progress | AO15: =SUM(C15:AN15) -> 0 | AP15: =AO15*25 -> 0
B16: 6 mm Metabolica | AO16: =SUM(C16:AN16) -> 0 | AP16: =AO16*25 -> 0
B17: 7 mm Metabolica | AO17: =SUM(C17:AN17) -> 0 | AP17: =AO17*25 -> 0
B18: 8 mm Progress | AO18: =SUM(C18:AN18) -> 0 | AP18: =AO18*25 -> 0
AO19: =SUM(C19:AN19) -> 0 | AP19: =AO19*25 -> 0
A21: Martes | B21: 3 mm progress ex | AO21: =SUM(C21:AN21) -> 0 | AP21: =AO21*25 -> 0
B22: 4,5 mm metabólica | AO22: =SUM(C22:AN22) -> 0 | AP22: =AO22*25 -> 0
B23: 4.5 mm Progress | AO23: =SUM(C23:AN23) -> 0 | AP23: =AO23*25 -> 0
B24: 6 mm Metabolica | AO24: =SUM(C24:AN24) -> 0 | AP24: =AO24*25 -> 0
B25: 7 mm Metabolica | AO25: =SUM(C25:AN25) -> 0 | AP25: =AO25*25 -> 0
B26: 8 mm Progress | AO26: =SUM(C26:AN26) -> 0 | AP26: =AO26*25 -> 0
AO27: =SUM(C27:AN27) -> 0 | AP27: =AO27*25 -> 0
A29: Miércoles | B29: 3 mm progress ex | AO29: =SUM(C29:AN29) -> 0 | AP29: =AO29*25 -> 0
B30: 4,5 mm metabólica | AO30: =SUM(C30:AN30) -> 0 | AP30: =AO30*25 -> 0
B31: 4.5 mm Progress | AO31: =SUM(C31:AN31) -> 0 | AP31: =AO31*25 -> 0
B32: 6 mm Metabolica | AO32: =SUM(C32:AN32) -> 0 | AP32: =AO32*25 -> 0
B33: 7 mm Metabolica | AO33: =SUM(C33:AN33) -> 0 | AP33: =AO33*25 -> 0
B34: 8 mm Progress | AO34: =SUM(C34:AN34) -> 0 | AP34: =AO34*25 -> 0
AO35: =SUM(C35:AN35) -> 0 | AP35: =AO35*25 -> 0
A37: Jueves | B37: 3 mm progress ex | AO37: =SUM(C37:AN37) -> 0 | AP37: =AO37*25 -> 0
B38: 4,5 mm metabólica | AO38: =SUM(C38:AN38) -> 0 | AP38: =AO38*25 -> 0
B39: 4.5 mm Progress | AO39: =SUM(C39:AN39) -> 0 | AP39: =AO39*25 -> 0
B40: 6 mm Metabolica | AO40: =SUM(C40:AN40) -> 0 | AP40: =AO40*25 -> 0
B41: 7 mm Metabolica | AO41: =SUM(C41:AN41) -> 0 | AP41: =AO41*25 -> 0
B42: 8 mm Progress | AO42: =SUM(C42:AN42) -> 0 | AP42: =AO42*25 -> 0
AO43: =SUM(C43:AN43) -> 0 | AP43: =AO43*25 -> 0
A44: Viernes | B44: 3 mm progress ex | AO44: =SUM(C44:AN44) -> 0 | AP44: =AO44*25 -> 0
B45: 4,5 mm metabólica | AO45: =SUM(C45:AN45) -> 0 | AP45: =AO45*25 -> 0
...

Sheet 8
C2: Oriente | I2: Poniente | O2: Nor Oriente | U2: Nor central | AA2: Nor Poniente | AG2: Central | AK2: J | AL2: H | AM2: Total
B3: Alimento ( sacos) | C3: 1 | D3: 2 | E3: 3 | F3: 4 | G3: 5 | H3: 6 | I3: 1 | J3: 2 | K3: 3 | L3: 4 | M3: 5 | N3: 6 | O3: 1 | P3: 2 | Q3: 3 | R3: 4 | S3: 5 | T3: 6 | U3: 1 | V3: 2 | W3: 3 | X3: 4 | Y3: 5 | Z3: 6 | AA3: 1 | AB3: 2 | AC3: 3 | AD3: 4 | AE3: 5 | AF3: 6 | AG3: 1 | AH3: 2 | AI3: 3 | AJ3: 4 | AM3: Sacos | AN3: Kg
A4: Lunes | B4: 3 mm progress ex | AM4: =SUM(C4:AL4) -> 0 | AN4: =AM4*25 -> 0
B5: 4,5 mm metabólica | AM5: =SUM(C5:AL5) -> 0 | AN5: =AM5*25 -> 0
B6: 6 mm metabólica | AM6: =SUM(C6:AL6) -> 0 | AN6: =AM6*25 -> 0
B7: 6 mm Progress | AM7: =SUM(C7:AL7) -> 0 | AN7: =AM7*25 -> 0
AM8: =SUM(C8:AL8) -> 0 | AN8: =AM8*25 -> 0
B9: 8 mm Sturgeon Rep. | AM9: =SUM(C9:AL9) -> 0 | AN9: =AM9*25 -> 0
AM10: =SUM(C10:AL10) -> 0 | AN10: =AM10*25 -> 0
AM11: =SUM(C11:AL11) -> 0 | AN11: =AM11*25 -> 0
A12: Martes | B12: 3 mm progress ex | AM12: =SUM(C12:AL12) -> 0 | AN12: =AM12*25 -> 0
B13: 4,5 mm metabólica | AM13: =SUM(C13:AL13) -> 0 | AN13: =AM13*25 -> 0
B14: 6 mm metabólica | AM14: =SUM(C14:AL14) -> 0 | AN14: =AM14*25 -> 0
B15: 6 mm Progress | AM15: =SUM(C15:AL15) -> 0 | AN15: =AM15*25 -> 0
AM16: =SUM(C16:AL16) -> 0 | AN16: =AM16*25 -> 0
B17: 8 mm Sturgeon Rep. | AM17: =SUM(C17:AL17) -> 0 | AN17: =AM17*25 -> 0
AM18: =SUM(C18:AL18) -> 0 | AN18: =AM18*25 -> 0
AM19: =SUM(C19:AL19) -> 0 | AN19: =AM19*25 -> 0
A20: Miércoles | B20: 3 mm progress ex | AM20: =SUM(C20:AL20) -> 0 | AN20: =AM20*25 -> 0
B21: 4,5 mm metabólica | AM21: =SUM(C21:AL21) -> 0 | AN21: =AM21*25 -> 0
B22: 6 mm metabólica | AM22: =SUM(C22:AL22) -> 0 | AN22: =AM22*25 -> 0
B23: 6 mm Progress | AM23: =SUM(C23:AL23) -> 0 | AN23: =AM23*25 -> 0
AM24: =SUM(C24:AL24) -> 0 | AN24: =AM24*25 -> 0
B25: 8 mm Sturgeon Rep. | AM25: =SUM(C25:AL25) -> 0 | AN25: =AM25*25 -> 0
AM26: =SUM(C26:AL26) -> 0 | AN26: =AM26*25 -> 0
AM27: =SUM(C27:AL27) -> 0 | AN27: =AM27*25 -> 0
A28: Jueves | B28: 3 mm progress ex | AM28: =SUM(C28:AL28) -> 0 | AN28: =AM28*25 -> 0
B29: 4,5 mm metabólica | AM29: =SUM(C29:AL29) -> 0 | AN29: =AM29*25 -> 0
B30: 6 mm metabólica | AM30: =SUM(C30:AL30) -> 0 | AN30: =AM30*25 -> 0
B31: 6 mm Progress | AM31: =SUM(C31:AL31) -> 0 | AN31: =AM31*25 -> 0
AM32: =SUM(C32:AL32) -> 0 | AN32: =AM32*25 -> 0
B33: 8 mm Sturgeon Rep. | AM33: =SUM(C33:AL33) -> 0 | AN33: =AM33*25 -> 0
AM34: =SUM(C34:AL34) -> 0 | AN34: =AM34*25 -> 0
A35: Viernes | B35: 3 mm progress ex | AM35: =SUM(C35:AL35) -> 0 | AN35: =AM35*25 -> 0
B36: 4,5 mm metabólica | AM36: =SUM(C36:AL36) -> 0 | AN36: =AM36*25 -> 0
B37: 6 mm metabólica | AM37: =SUM(C37:AL37) -> 0 | AN37: =AM37*25 -> 0
B38: 6 mm Progress | AM38: =SUM(C38:AL38) -> 0 | AN38: =AM38*25 -> 0
AM39: =SUM(C39:AL39) -> 0 | AN39: =AM39*25 -> 0
B40: 8 mm Sturgeon Rep. | AM40: =SUM(C40:AL40) -> 0 | AN40: =AM40*25 -> 0
AM41: =SUM(C41:AL41) -> 0 | AN41: =AM41*25 -> 0
...

Sheet 9
C2: Oriente | I2: Poniente | O2: Nor Oriente | U2: Nor central | AA2: Nor Poniente | AG2: Central | AK2: J | AL2: H | AM2: Total
B3: Alimento ( sacos) | C3: 1 | D3: 2 | E3: 3 | F3: 4 | G3: 5 | H3: 6 | I3: 1 | J3: 2 | K3: 3 | L3: 4 | M3: 5 | N3: 6 | O3: 1 | P3: 2 | Q3: 3 | R3: 4 | S3: 5 | T3: 6 | U3: 1 | V3: 2 | W3: 3 | X3: 4 | Y3: 5 | Z3: 6 | AA3: 1 | AB3: 2 | AC3: 3 | AD3: 4 | AE3: 5 | AF3: 6 | AG3: 1 | AH3: 2 | AI3: 3 | AJ3: 4 | AM3: Sacos | AN3: Kg
A4: Lunes | B4: 3 mm progress ex | AM4: =SUM(C4:AL4) -> 0 | AN4: =AM4*25 -> 0
B5: 4,5 mm metabólica | AM5: =SUM(C5:AL5) -> 0 | AN5: =AM5*25 -> 0
B6: 6 mm metabólica | AM6: =SUM(C6:AL6) -> 0 | AN6: =AM6*25 -> 0
B7: 6 mm Progress | AM7: =SUM(C7:AL7) -> 0 | AN7: =AM7*25 -> 0
B8: 6 mm Sturgeon Rep. | AM8: =SUM(C8:AL8) -> 0 | AN8: =AM8*25 -> 0
B9: 8 mm Sturgeon Rep. | AM9: =SUM(C9:AL9) -> 0 | AN9: =AM9*25 -> 0
AM10: =SUM(C10:AL10) -> 0 | AN10: =AM10*25 -> 0
AM11: =SUM(C11:AL11) -> 0 | AN11: =AM11*25 -> 0
A12: Martes | B12: 3 mm progress ex | AM12: =SUM(C12:AL12) -> 0 | AN12: =AM12*25 -> 0
B13: 4,5 mm metabólica | AM13: =SUM(C13:AL13) -> 0 | AN13: =AM13*25 -> 0
B14: 6 mm metabólica | AM14: =SUM(C14:AL14) -> 0 | AN14: =AM14*25 -> 0
B15: 6 mm Progress | AM15: =SUM(C15:AL15) -> 0 | AN15: =AM15*25 -> 0
B16: 6 mm Sturgeon Rep. | AM16: =SUM(C16:AL16) -> 0 | AN16: =AM16*25 -> 0
B17: 8 mm Sturgeon Rep. | AM17: =SUM(C17:AL17) -> 0 | AN17: =AM17*25 -> 0
AM18: =SUM(C18:AL18) -> 0 | AN18: =AM18*25 -> 0
AM19: =SUM(C19:AL19) -> 0 | AN19: =AM19*25 -> 0
A20: Miércoles | B20: 3 mm progress ex | AM20: =SUM(C20:AL20) -> 0 | AN20: =AM20*25 -> 0
B21: 4,5 mm metabólica | AM21: =SUM(C21:AL21) -> 0 | AN21: =AM21*25 -> 0
B22: 6 mm metabólica | AM22: =SUM(C22:AL22) -> 0 | AN22: =AM22*25 -> 0
B23: 6 mm Progress | AM23: =SUM(C23:AL23) -> 0 | AN23: =AM23*25 -> 0
B24: 6 mm Sturgeon Rep. | AM24: =SUM(C24:AL24) -> 0 | AN24: =AM24*25 -> 0
B25: 8 mm Sturgeon Rep. | AM25: =SUM(C25:AL25) -> 0 | AN25: =AM25*25 -> 0
AM26: =SUM(C26:AL26) -> 0 | AN26: =AM26*25 -> 0
AM27: =SUM(C27:AL27) -> 0 | AN27: =AM27*25 -> 0
A28: Jueves | B28: 3 mm progress ex | AM28: =SUM(C28:AL28) -> 0 | AN28: =AM28*25 -> 0
B29: 4,5 mm metabólica | AM29: =SUM(C29:AL29) -> 0 | AN29: =AM29*25 -> 0
B30: 6 mm metabólica | AM30: =SUM(C30:AL30) -> 0 | AN30: =AM30*25 -> 0
B31: 6 mm Progress | AM31: =SUM(C31:AL31) -> 0 | AN31: =AM31*25 -> 0
B32: 6 mm Sturgeon Rep. | AM32: =SUM(C32:AL32) -> 0 | AN32: =AM32*25 -> 0
B33: 8 mm Sturgeon Rep. | AM33: =SUM(C33:AL33) -> 0 | AN33: =AM33*25 -> 0
AM34: =SUM(C34:AL34) -> 0 | AN34: =AM34*25 -> 0
A35: Viernes | B35: 3 mm progress ex | AM35: =SUM(C35:AL35) -> 0 | AN35: =AM35*25 -> 0
B36: 4,5 mm metabólica | AM36: =SUM(C36:AL36) -> 0 | AN36: =AM36*25 -> 0
B37: 6 mm metabólica | AM37: =SUM(C37:AL37) -> 0 | AN37: =AM37*25 -> 0
B38: 6 mm Progress | AM38: =SUM(C38:AL38) -> 0 | AN38: =AM38*25 -> 0
B39: 6 mm Sturgeon Rep. | AM39: =SUM(C39:AL39) -> 0 | AN39: =AM39*25 -> 0
B40: 8 mm Sturgeon Rep. | AM40: =SUM(C40:AL40) -> 0 | AN40: =AM40*25 -> 0
AM41: =SUM(C41:AL41) -> 0 | AN41: =AM41*25 -> 0
...

Sheet 10
C2: Oriente | I2: Poniente | O2: Nor Oriente | U2: Nor central | AA2: Nor Poniente | AG2: Central | AK2: J | AL2: H | AM2: Total
B3: Alimento ( sacos) | C3: 1 | D3: 2 | E3: 3 | F3: 4 | G3: 5 | H3: 6 | I3: 1 | J3: 2 | K3: 3 | L3: 4 | M3: 5 | N3: 6 | O3: 1 | P3: 2 | Q3: 3 | R3: 4 | S3: 5 | T3: 6 | U3: 1 | V3: 2 | W3: 3 | X3: 4 | Y3: 5 | Z3: 6 | AA3: 1 | AB3: 2 | AC3: 3 | AD3: 4 | AE3: 5 | AF3: 6 | AG3: 1 | AH3: 2 | AI3: 3 | AJ3: 4 | AM3: Sacos | AN3: Kg
A4: Lunes | B4: 3 mm progress ex | AM4: =SUM(C4:AL4) -> 0 | AN4: =AM4*25 -> 0
B5: 4,5 mm metabólica | AM5: =SUM(C5:AL5) -> 0 | AN5: =AM5*25 -> 0
B6: 6 mm metabólica | AM6: =SUM(C6:AL6) -> 0 | AN6: =AM6*25 -> 0
B7: 6 mm Progress | AM7: =SUM(C7:AL7) -> 0 | AN7: =AM7*25 -> 0
B8: 6 mm Sturgeon Rep. | AM8: =SUM(C8:AL8) -> 0 | AN8: =AM8*25 -> 0
B9: 8 mm Sturgeon Rep. | AM9: =SUM(C9:AL9) -> 0 | AN9: =AM9*25 -> 0
AM10: =SUM(C10:AL10) -> 0 | AN10: =AM10*25 -> 0
AM11: =SUM(C11:AL11) -> 0 | AN11: =AM11*25 -> 0
A12: Martes | B12: 3 mm progress ex | AM12: =SUM(C12:AL12) -> 0 | AN12: =AM12*25 -> 0
B13: 4,5 mm metabólica | AM13: =SUM(C13:AL13) -> 0 | AN13: =AM13*25 -> 0
B14: 6 mm metabólica | AM14: =SUM(C14:AL14) -> 0 | AN14: =AM14*25 -> 0
B15: 6 mm Progress | AM15: =SUM(C15:AL15) -> 0 | AN15: =AM15*25 -> 0
B16: 6 mm Sturgeon Rep. | AM16: =SUM(C16:AL16) -> 0 | AN16: =AM16*25 -> 0
B17: 8 mm Sturgeon Rep. | AM17: =SUM(C17:AL17) -> 0 | AN17: =AM17*25 -> 0
AM18: =SUM(C18:AL18) -> 0 | AN18: =AM18*25 -> 0
AM19: =SUM(C19:AL19) -> 0 | AN19: =AM19*25 -> 0
A20: Miércoles | B20: 3 mm progress ex | AM20: =SUM(C20:AL20) -> 0 | AN20: =AM20*25 -> 0
B21: 4,5 mm metabólica | AM21: =SUM(C21:AL21) -> 0 | AN21: =AM21*25 -> 0
B22: 6 mm metabólica | AM22: =SUM(C22:AL22) -> 0 | AN22: =AM22*25 -> 0
B23: 6 mm Progress | AM23: =SUM(C23:AL23) -> 0 | AN23: =AM23*25 -> 0
B24: 6 mm Sturgeon Rep. | AM24: =SUM(C24:AL24) -> 0 | AN24: =AM24*25 -> 0
B25: 8 mm Sturgeon Rep. | AM25: =SUM(C25:AL25) -> 0 | AN25: =AM25*25 -> 0
AM26: =SUM(C26:AL26) -> 0 | AN26: =AM26*25 -> 0
AM27: =SUM(C27:AL27) -> 0 | AN27: =AM27*25 -> 0
A28: Jueves | B28: 3 mm progress ex | AM28: =SUM(C28:AL28) -> 0 | AN28: =AM28*25 -> 0
B29: 4,5 mm metabólica | AM29: =SUM(C29:AL29) -> 0 | AN29: =AM29*25 -> 0
B30: 6 mm metabólica | AM30: =SUM(C30:AL30) -> 0 | AN30: =AM30*25 -> 0
B31: 6 mm Progress | AM31: =SUM(C31:AL31) -> 0 | AN31: =AM31*25 -> 0
B32: 6 mm Sturgeon Rep. | AM32: =SUM(C32:AL32) -> 0 | AN32: =AM32*25 -> 0
B33: 8 mm Sturgeon Rep. | AM33: =SUM(C33:AL33) -> 0 | AN33: =AM33*25 -> 0
AM34: =SUM(C34:AL34) -> 0 | AN34: =AM34*25 -> 0
A35: Viernes | B35: 3 mm progress ex | AM35: =SUM(C35:AL35) -> 0 | AN35: =AM35*25 -> 0
B36: 4,5 mm metabólica | AM36: =SUM(C36:AL36) -> 0 | AN36: =AM36*25 -> 0
B37: 6 mm metabólica | AM37: =SUM(C37:AL37) -> 0 | AN37: =AM37*25 -> 0
B38: 6 mm Progress | AM38: =SUM(C38:AL38) -> 0 | AN38: =AM38*25 -> 0
B39: 6 mm Sturgeon Rep. | AM39: =SUM(C39:AL39) -> 0 | AN39: =AM39*25 -> 0
B40: 8 mm Sturgeon Rep. | AM40: =SUM(C40:AL40) -> 0 | AN40: =AM40*25 -> 0
AM41: =SUM(C41:AL41) -> 0 | AN41: =AM41*25 -> 0
...

Sheet Total
A1: Alimento | B1: SO1 | C1: SO2 | D1: SO3 | E1: SO4 | F1: SO5 | G1: SO6 | H1: SP1 | I1: SP2 | J1: SP3 | K1: SP4 | L1: SP5 | M1: SP6 | N1: NO1 | O1: NO2 | P1: NO3 | Q1: NO4 | R1: NO5 | S1: NO6 | T1: NC1 | U1: NC2 | V1: NC3 | W1: NC4 | X1: NC5 | Y1: NC6 | Z1: NP1 | AA1: NP2 | AB1: NP3 | AC1: NP4 | AD1: NP5 | AE1: NP6 | AF1: C1 | AG1: C2 | AH1: C3 | AI1: C4 | AJ1: C5 | AK1: C6 | AL1: J | AM1: H
A2: ='1'!B13 -> 3 mm progress ex | B2: ='1'!C74+'2'!C74+'3'!C74+'4'!C74+'5'!C74 -> 0 | C2: ='1'!D74+'2'!D74+'3'!D74+'4'!D74+'5'!D74 -> 0 | D2: ='1'!E74+'2'!E74+'3'!E74+'4'!E74+'5'!E74 -> 0 | E2: ='1'!F74+'2'!F74+'3'!F74+'4'!F74+'5'!F74 -> 0 | F2: ='1'!G74+'2'!G74+'3'!G74+'4'!G74+'5'!G74 -> 0 | G2: ='1'!H74+'2'!H74+'3'!H74+'4'!H74+'5'!H74 -> 0 | H2: ='1'!I74+'2'!I74+'3'!I74+'4'!I74+'5'!I74 -> 0 | I2: ='1'!J74+'2'!J74+'3'!J74+'4'!J74+'5'!J74 -> 0 | ... AM2: ='1'!AN74+'2'!AN74+'3'!AN74+'4'!AN74+'5'!AN74 -> 0 | AN2: =SUM(B2:AM2) -> 29 | AO2: =AN2*25 -> 725
A3: ='1'!B14 -> 4,5 mm metabólica | B3: ='1'!C75+'2'!C75+'3'!C75+'4'!C75+'5'!C75 -> 0 | C3: ='1'!D75+'2'!D75+'3'!D75+'4'!D75+'5'!D75 -> 0 | D3: ='1'!E75+'2'!E75+'3'!E75+'4'!E75+'5'!E75 -> 0 | E3: ='1'!F75+'2'!F75+'3'!F75+'4'!F75+'5'!F75 -> 0 | F3: ='1'!G75+'2'!G75+'3'!G75+'4'!G75+'5'!G75 -> 0 | G3: ='1'!H75+'2'!H75+'3'!H75+'4'!H75+'5'!H75 -> 0 | H3: ='1'!I75+'2'!I75+'3'!I75+'4'!I75+'5'!I75 -> 0 | I3: ='1'!J75+'2'!J75+'3'!J75+'4'!J75+'5'!J75 -> 0 | ... AM3: ='1'!AN75+'2'!AN75+'3'!AN75+'4'!AN75+'5'!AN75 -> 0 | AN3: =SUM(B3:AM3) -> 0 | AO3: =AN3*25 -> 0
A4: ='1'!B15 -> 4.5 mm Progress | B4: ='1'!C76+'2'!C76+'3'!C76+'4'!C76+'5'!C76 -> 0 | C4: ='1'!D76+'2'!D76+'3'!D76+'4'!D76+'5'!D76 -> 0 | D4: ='1'!E76+'2'!E76+'3'!E76+'4'!E76+'5'!E76 -> 0 | E4: ='1'!F76+'2'!F76+'3'!F76+'4'!F76+'5'!F76 -> 0 | F4: ='1'!G76+'2'!G76+'3'!G76+'4'!G76+'5'!G76 -> 0 | G4: ='1'!H76+'2'!H76+'3'!H76+'4'!H76+'5'!H76 -> 0 | H4: ='1'!I76+'2'!I76+'3'!I76+'4'!I76+'5'!I76 -> 0 | I4: ='1'!J76+'2'!J76+'3'!J76+'4'!J76+'5'!J76 -> 0 | ... AM4: ='1'!AN76+'2'!AN76+'3'!AN76+'4'!AN76+'5'!AN76 -> 0 | AN4: =SUM(B4:AM4) -> 42 | AO4: =AN4*25 -> 1050
A5: ='1'!B16 -> 6 mm Metabolica | B5: ='1'!C77+'2'!C77+'3'!C77+'4'!C77+'5'!C77 -> 0 | C5: ='1'!D77+'2'!D77+'3'!D77+'4'!D77+'5'!D77 -> 0 | D5: ='1'!E77+'2'!E77+'3'!E77+'4'!E77+'5'!E77 -> 0 | E5: ='1'!F77+'2'!F77+'3'!F77+'4'!F77+'5'!F77 -> 0 | F5: ='1'!G77+'2'!G77+'3'!G77+'4'!G77+'5'!G77 -> 0 | G5: ='1'!H77+'2'!H77+'3'!H77+'4'!H77+'5'!H77 -> 0 | H5: ='1'!I77+'2'!I77+'3'!I77+'4'!I77+'5'!I77 -> 0 | I5: ='1'!J77+'2'!J77+'3'!J77+'4'!J77+'5'!J77 -> 0 | ... AM5: ='1'!AN77+'2'!AN77+'3'!AN77+'4'!AN77+'5'!AN77 -> 0 | AN5: =SUM(B5:AM5) -> 0 | AO5: =AN5*25 -> 0
A6: ='1'!B17 -> 6 mm Progress | B6: ='1'!C78+'2'!C78+'3'!C78+'4'!C78+'5'!C78 -> 0 | C6: ='1'!D78+'2'!D78+'3'!D78+'4'!D78+'5'!D78 -> 0 | D6: ='1'!E78+'2'!E78+'3'!E78+'4'!E78+'5'!E78 -> 0 | E6: ='1'!F78+'2'!F78+'3'!F78+'4'!F78+'5'!F78 -> 0 | F6: ='1'!G78+'2'!G78+'3'!G78+'4'!G78+'5'!G78 -> 0 | G6: ='1'!H78+'2'!H78+'3'!H78+'4'!H78+'5'!H78 -> 0 | H6: ='1'!I78+'2'!I78+'3'!I78+'4'!I78+'5'!I78 -> 0 | I6: ='1'!J78+'2'!J78+'3'!J78+'4'!J78+'5'!J78 -> 0 | ... AM6: ='1'!AN78+'2'!AN78+'3'!AN78+'4'!AN78+'5'!AN78 -> 0 | AN6: =SUM(B6:AM6) -> 59 | AO6: =AN6*25 -> 1475
A7: ='1'!B18 -> 8 mm Progress | B7: ='1'!C79+'2'!C79+'3'!C79+'4'!C79+'5'!C79 -> 0 | C7: ='1'!D79+'2'!D79+'3'!D79+'4'!D79+'5'!D79 -> 0 | D7: ='1'!E79+'2'!E79+'3'!E79+'4'!E79+'5'!E79 -> 0 | E7: ='1'!F79+'2'!F79+'3'!F79+'4'!F79+'5'!F79 -> 0 | F7: ='1'!G79+'2'!G79+'3'!G79+'4'!G79+'5'!G79 -> 0 | G7: ='1'!H79+'2'!H79+'3'!H79+'4'!H79+'5'!H79 -> 0 | H7: ='1'!I79+'2'!I79+'3'!I79+'4'!I79+'5'!I79 -> 0 | I7: ='1'!J79+'2'!J79+'3'!J79+'4'!J79+'5'!J79 -> 0 | ... AM7: ='1'!AN79+'2'!AN79+'3'!AN79+'4'!AN79+'5'!AN79 -> 0 | AN7: =SUM(B7:AM7) -> 87 | AO7: =AN7*25 -> 2175
A8: ='1'!B19 -> 8 mm Reproductor | B8: ='1'!C80+'2'!C80+'3'!C80+'4'!C80+'5'!C80 -> 0 | C8: ='1'!D80+'2'!D80+'3'!D80+'4'!D80+'5'!D80 -> 0 | D8: ='1'!E80+'2'!E80+'3'!E80+'4'!E80+'5'!E80 -> 0 | E8: ='1'!F80+'2'!F80+'3'!F80+'4'!F80+'5'!F80 -> 0 | F8: ='1'!G80+'2'!G80+'3'!G80+'4'!G80+'5'!G80 -> 0 | G8: ='1'!H80+'2'!H80+'3'!H80+'4'!H80+'5'!H80 -> 0 | H8: ='1'!I80+'2'!I80+'3'!I80+'4'!I80+'5'!I80 -> 0 | I8: ='1'!J80+'2'!J80+'3'!J80+'4'!J80+'5'!J80 -> 0 | ... AM8: ='1'!AN80+'2'!AN80+'3'!AN80+'4'!AN80+'5'!AN80 -> 0 | AN8: =SUM(B8:AM8) -> 152 | AO8: =AN8*25 -> 3800
AO9: =SUM(AO2:AO8) -> 9225
A11: Alimentacion Consumida Mensual
A13: Ubicación | C13: Origen | G13: ='1'!B13 -> 3 mm progress ex | H13: ='1'!B14 -> 4,5 mm metabólica | I13: ='1'!B15 -> 4.5 mm Progress | J13: ='1'!B16 -> 6 mm Metabolica | K13: ='1'!B17 -> 6 mm Progress | L13: ='1'!B18 -> 8 mm Progress | M13: ='1'!B19 -> 8 mm Reproductor
A15: Lag. Sur Oriente | B15: SO1 | C15: Iberia | G15: =B2 -> 0 | H15: =B3 -> 0 | I15: =B4 -> 0 | J15: =B5 -> 0 | K15: =B6 -> 0 | L15: =B$7 -> 0 | M15: =B8 -> 0
B16: SO2 | C16: Iberia | G16: =C2 -> 0 | H16: =C3 -> 0 | I16: =C4 -> 0 | J16: =C5 -> 0 | K16: =C6 -> 0 | L16: =C7 -> 0 | M16: =C$8 -> 0 | N16: =+B16 -> SO2 | O16: =B8 -> 0 | P16: =C8 -> 0 | Q16: =D8 -> 0 | R16: =E8 -> 0 | S16: =F8 -> 0 | T16: =G8 -> 0 | U16: =H8 -> 0 | V16: =I8 -> 0 | ... BH16: =AU8 -> 0
B17: SO3 | C17: Fátima | G17: =D2 -> 0 | I17: =D4 -> 0 | J17: =D5 -> 0 | K17: =D6 -> 0 | L17: =D7 -> 0 | M17: =D8 -> 0 | N17: =+B17 -> SO3 | Q17: c8 | R17: b8 | S17: d8
B18: SO4 | C18: Oscetra | G18: =E2 -> 0 | H18: =E3 -> 0 | I18: =E4 -> 0 | J18: =E5 -> 0 | K18: =E6 -> 0 | L18: =E7 -> 0 | M18: =E8 -> 0 | N18: =+B18 -> SO4
B19: SO5 | C19: Oscetra | G19: =F2 -> 0 | H19: =F3 -> 0 | I19: =F4 -> 0 | J19: =F5 -> 0 | K19: =F6 -> 0 | L19: =F7 -> 0 | M19: =F8 -> 0 | N19: =+B19 -> SO5
B20: SO6 | C20: Fátima | G20: =G2 -> 0 | H20: =G3 -> 0 | I20: =G4 -> 0 | J20: =G5 -> 0 | K20: =G6 -> 0 | L20: =G7 -> 0 | M20: =G8 -> 0 | N20: =+B20 -> SO6
A21: Lag. Sur Poniente | B21: SP1 | C21: Rosario | G21: =H2 -> 0 | H21: =H3 -> 0 | I21: =H4 -> 0 | J21: =H5 -> 0 | K21: =H6 -> 0 | L21: =H7 -> 0 | M21: =H8 -> 0
B22: SP2 | C22: Guadalupe | G22: =I2 -> 0 | H22: =I3 -> 0 | I22: =I4 -> 0 | J22: =I5 -> 0 | K22: =I6 -> 0 | L22: =I7 -> 0 | M22: =I8 -> 0
B23: SP3 | C23: Fátima | G23: =J2 -> 11 | H23: =J3 -> 0 | I23: =J4 -> 1 | J23: =J5 -> 0 | K23: =J6 -> 0 | L23: =J7 -> 0 | M23: =J8 -> 0
B24: SP4 | C24: Fátima | G24: =K2 -> 10 | H24: =K3 -> 0 | I24: =K4 -> 1 | J24: =K5 -> 0 | K24: =K6 -> 0 | L24: =K7 -> 0 | M24: =K8 -> 0
B25: SP5 | C25: Fátima | G25: =L2 -> 0 | H25: =L3 -> 0 | I25: =L4 -> 0 | J25: =L5 -> 0 | K25: =L6 -> 0 | L25: =L7 -> 0 | M25: =L8 -> 0
B26: SP6 | C26: Del Carmen | G26: =M2 -> 0 | H26: =M3 -> 0 | I26: =M4 -> 0 | J26: =M5 -> 0 | K26: =M6 -> 0 | L26: =M7 -> 0 | M26: =M8 -> 0
A27: Lag Nor Oriente | B27: NO1 | C27: Rosario | G27: =N2 -> 0 | H27: =N3 -> 0 | I27: =N4 -> 3 | J27: =N5 -> 0 | K27: =N6 -> 20 | L27: =N7 -> 0 | M27: =N8 -> 0
B28: NO2 | G28: =O2 -> 0 | H28: =O3 -> 0 | I28: =O4 -> 13 | J28: =O5 -> 0 | K28: =O6 -> 1 | L28: =O7 -> 0 | M28: =O8 -> 0
B29: NO3 | G29: =P2 -> 0 | H29: =P3 -> 0 | I29: =P4 -> 13 | J29: =P5 -> 0 | K29: =P6 -> 0 | L29: =P7 -> 0 | M29: =P8 -> 0
B30: NO4 | G30: =Q2 -> 0 | H30: =Q3 -> 0 | I30: =Q4 -> 0 | J30: =Q5 -> 0 | K30: =Q6 -> 7 | L30: =Q7 -> 3 | M30: =Q8 -> 6
B31: NO5 | G31: =R2 -> 0 | H31: =R3 -> 0 | I31: =R4 -> 0 | J31: =R5 -> 0 | K31: =R6 -> 9 | L31: =R7 -> 5 | M31: =R8 -> 9
B32: NO6 | C32: Rosario | G32: =S2 -> 0 | H32: =S3 -> 0 | I32: =S4 -> 2 | J32: =S5 -> 0 | K32: =S6 -> 3 | L32: =S7 -> 3 | M32: =S8 -> 0
A33: Laguna Nor Central | B33: NC1 | G33: =T2 -> 0 | H33: =T3 -> 0 | I33: =T4 -> 0 | J33: =T5 -> 0 | K33: =T6 -> 6 | L33: =T7 -> 5 | M33: =T8 -> 10
B34: NC2 | G34: =U2 -> 0 | H34: =U3 -> 0 | I34: =U4 -> 0 | J34: =U5 -> 0 | K34: =U6 -> 9 | L34: =U7 -> 7 | M34: =U8 -> 13
B35: NC3 | G35: =V2 -> 0 | H35: =V3 -> 0 | I35: =V4 -> 0 | J35: =V5 -> 0 | K35: =V6 -> 1 | L35: =V7 -> 8 | M35: =V8 -> 12
B36: NC4 | G36: =W2 -> 0 | H36: =W3 -> 0 | I36: =W4 -> 0 | J36: =W5 -> 0 | K36: =W6 -> 1 | L36: =W7 -> 8 | M36: =W8 -> 16
B37: NC5 | G37: =X2 -> 0 | H37: =X3 -> 0 | I37: =X4 -> 0 | J37: =X5 -> 0 | K37: =X6 -> 1 | L37: =X7 -> 5 | M37: =X8 -> 9
B38: NC6 | G38: =Y2 -> 0 | H38: =Y3 -> 0 | I38: =Y4 -> 0 | J38: =Y5 -> 0 | K38: =Y6 -> 1 | L38: =Y7 -> 5 | M38: =Y8 -> 11
A39: Laguna Nor Poniente | B39: NP1 | G39: =Z2 -> 0 | H39: =Z3 -> 0 | I39: =Z4 -> 0 | J39: =Z5 -> 0 | K39: =Z6 -> 0 | L39: =Z7 -> 8 | M39: =Z8 -> 12
B40: NP2 | G40: =AA2 -> 0 | H40: =AA3 -> 0 | I40: =AA4 -> 0 | J40: =AA5 -> 0 | K40: =AA6 -> 0 | L40: =AA7 -> 8 | M40: =AA8 -> 9
B41: NP3 | G41: =AB2 -> 0 | H41: =AB3 -> 0 | I41: =AB4 -> 0 | J41: =AB5 -> 0 | K41: =AB6 -> 0 | L41: =AB7 -> 4 | M41: =AB8 -> 10
B42: NP4 | G42: =AC2 -> 0 | H42: =AC3 -> 0 | I42: =AC4 -> 0 | J42: =AC5 -> 0 | K42: =AC6 -> 0 | L42: =AC7 -> 4 | M42: =AC8 -> 9
B43: NP5 | G43: =AD2 -> 0 | H43: =AD3 -> 0 | I43: =AD4 -> 0 | J43: =AD5 -> 0 | K43: =AD6 -> 0 | L43: =AD7 -> 3 | M43: =AD8 -> 7
...

Sheet Hoja3
D2: Noviembre
A3: Etiquetas de fila | B3: Suma de 8 mm Reproductor | C3: Suma de 3 mm progress ex | D3: Suma de 4,5 mm metabólica | E3: Suma de 4.5 mm Progress | F3: Suma de 6 mm Metabolica | G3: Suma de 6 mm Progress | H3: Suma de 8 mm Progress
A4: Candelaria | B4: 0 | C4: 275 | D4: 0 | E4: 25 | F4: 0 | G4: 0 | H4: 0
A5: Del Carmen | B5: 375 | C5: 0 | D5: 0 | E5: 0 | F5: 0 | G5: 400 | H5: 200
A6: Dolores | B6: 150 | C6: 0 | D6: 0 | E6: 0 | F6: 0 | G6: 0 | H6: 75
A7: Ocetra | B7: 3275 | C7: 0 | D7: 0 | E7: 0 | F7: 0 | G7: 475 | H7: 1825
A8: pilar | B8: 0 | C8: 0 | D8: 0 | E8: 650 | F8: 0 | G8: 25 | H8: 0
A9: Rosa/Lourdes | B9: 0 | C9: 200 | D9: 0 | E9: 225 | F9: 0 | G9: 0 | H9: 0
A10: Rosario | B10: 0 | C10: 0 | D10: 0 | E10: 125 | F10: 0 | G10: 575 | H10: 75
A11: Victoria | B11: 0 | C11: 250 | D11: 0 | E11: 25 | F11: 0 | G11: 0 | H11: 0
A12: (en blanco) | B12: 0 | C12: 0 | D12: 0 | E12: 0 | F12: 0 | G12: 0 | H12: 0
A13: Caridad | B13: 0 | C13: 150 | D13: 0 | E13: 0 | F13: 0 | G13: 0 | H13: 0
A14: Total general | B14: 3800 | C14: 875 | D14: 0 | E14: 1050 | F14: 0 | G14: 1475 | H14: 2175

Sheet Total Consumo Mensual
A1: Registro | B1: PC 01.1 | D1: Programa de Crianza
A2: Versión: | B2: 0.24
A3: Fecha: | B3: 44701 | D3: RESUMEN MENSUAL EXISTENCIAS
A4: Elaborado Por: | B4: A - Vial
A5: Modificado por: | B5: R - Gatica | J5: Enero
A6: Aprobado Por | B6: A - Vial | D6: Acuícola Alas S.A., Ruta 5 sur, Km 338, VII región, Parral
A7: Hojas: | B7: 1 de 3
A9: Alimentacion Consumida Mensual
A11: Ubicación | C11: Origen | D11: 0.2 Infa | E11: 0.4 infa | F11: 1.3 thalassa | G11: =Total!G13 -> 3 mm progress ex | H11: =Total!H13 -> 4,5 mm metabólica | I11: =Total!I13 -> 4.5 mm Progress | J11: =Total!J13 -> 6 mm Metabolica | K11: =Total!K13 -> 6 mm Progress | L11: =Total!L13 -> 8 mm Progress | M11: =Total!M13 -> 8 mm Reproductor
A12: Lag. Sur Oriente | B12: SO1 | C12: Ocetra | G12: =Total!G15*25 -> 0 | H12: =Total!H15*25 -> 0 | I12: =Total!I15*25 -> 0 | J12: =Total!J15*25 -> 0 | K12: =Total!K15*25 -> 0 | L12: =Total!L15*25 -> 0 | M12: =Total!M15*25 -> 0 | N12: =+B12 -> SO1
B13: SO2 | C13: Ocetra | G13: =Total!G16*25 -> 0 | H13: =Total!H16*25 -> 0 | I13: =Total!I16*25 -> 0 | J13: =Total!J16*25 -> 0 | K13: =Total!K16*25 -> 0 | L13: =Total!L16*25 -> 0 | M13: =Total!M16*25 -> 0 | N13: =+B13 -> SO2
B14: SO3 | C14: Ocetra | G14: =Total!G17*25 -> 0 | H14: =Total!H17*25 -> 0 | I14: =Total!I17*25 -> 0 | J14: =Total!J17*25 -> 0 | K14: =Total!K17*25 -> 0 | L14: =Total!L17*25 -> 0 | M14: =Total!M17*25 -> 0 | N14: =+B14 -> SO3
B15: SO4 | C15: Ocetra | G15: =Total!G18*25 -> 0 | H15: =Total!H18*25 -> 0 | I15: =Total!I18*25 -> 0 | J15: =Total!J18*25 -> 0 | K15: =Total!K18*25 -> 0 | L15: =Total!L18*25 -> 0 | M15: =Total!M18*25 -> 0 | N15: =+B15 -> SO4
B16: SO5 | C16: Ocetra | G16: =Total!G19*25 -> 0 | H16: =Total!H19*25 -> 0 | I16: =Total!I19*25 -> 0 | J16: =Total!J19*25 -> 0 | K16: =Total!K19*25 -> 0 | L16: =Total!L19*25 -> 0 | M16: =Total!M19*25 -> 0 | N16: =+B16 -> SO5
B17: SO6 | C17: Ocetra | G17: =Total!G20*25 -> 0 | H17: =Total!H20*25 -> 0 | I17: =Total!I20*25 -> 0 | J17: =Total!J20*25 -> 0 | K17: =Total!K20*25 -> 0 | L17: =Total!L20*25 -> 0 | M17: =Total!M20*25 -> 0 | N17: =+B17 -> SO6
A18: Lag. Sur Poniente | B18: SP1 | C18: Rosario | G18: =Total!G21*25 -> 0 | H18: =Total!H21*25 -> 0 | I18: =Total!I21*25 -> 0 | J18: =Total!J21*25 -> 0 | K18: =Total!K21*25 -> 0 | L18: =Total!L21*25 -> 0 | M18: =Total!M21*25 -> 0
B19: SP2 | C19: Ocetra | G19: =Total!G22*25 -> 0 | H19: =Total!H22*25 -> 0 | I19: =Total!I22*25 -> 0 | J19: =Total!J22*25 -> 0 | K19: =Total!K22*25 -> 0 | L19: =Total!L22*25 -> 0 | M19: =Total!M22*25 -> 0
B20: SP3 | C20: Candelaria | G20: =Total!G23*25 -> 275 | H20: =Total!H23*25 -> 0 | I20: =Total!I23*25 -> 25 | J20: =Total!J23*25 -> 0 | K20: =Total!K23*25 -> 0 | L20: =Total!L23*25 -> 0 | M20: =Total!M23*25 -> 0
B21: SP4 | C21: Victoria | G21: =Total!G24*25 -> 250 | H21: =Total!H24*25 -> 0 | I21: =Total!I24*25 -> 25 | J21: =Total!J24*25 -> 0 | K21: =Total!K24*25 -> 0 | L21: =Total!L24*25 -> 0 | M21: =Total!M24*25 -> 0
B22: SP5 | C22: Ocetra | G22: =Total!G25*25 -> 0 | H22: =Total!H25*25 -> 0 | I22: =Total!I25*25 -> 0 | J22: =Total!J25*25 -> 0 | K22: =Total!K25*25 -> 0 | L22: =Total!L25*25 -> 0 | M22: =Total!M25*25 -> 0
B23: SP6 | C23: Del Carmen | G23: =Total!G26*25 -> 0 | H23: =Total!H26*25 -> 0 | I23: =Total!I26*25 -> 0 | J23: =Total!J26*25 -> 0 | K23: =Total!K26*25 -> 0 | L23: =Total!L26*25 -> 0 | M23: =Total!M26*25 -> 0
A24: Lag Nor Oriente | B24: NO1 | C24: Rosario | G24: =Total!G27*25 -> 0 | H24: =Total!H27*25 -> 0 | I24: =Total!I27*25 -> 75 | J24: =Total!J27*25 -> 0 | K24: =Total!K27*25 -> 500 | L24: =Total!L27*25 -> 0 | M24: =Total!M27*25 -> 0
B25: NO2 | C25: pilar | G25: =Total!G28*25 -> 0 | H25: =Total!H28*25 -> 0 | I25: =Total!I28*25 -> 325 | J25: =Total!J28*25 -> 0 | K25: =Total!K28*25 -> 25 | L25: =Total!L28*25 -> 0 | M25: =Total!M28*25 -> 0
B26: NO3 | C26: pilar | G26: =Total!G29*25 -> 0 | H26: =Total!H29*25 -> 0 | I26: =Total!I29*25 -> 325 | J26: =Total!J29*25 -> 0 | K26: =Total!K29*25 -> 0 | L26: =Total!L29*25 -> 0 | M26: =Total!M29*25 -> 0
B27: NO4 | C27: Del carmen | G27: =Total!G30*25 -> 0 | H27: =Total!H30*25 -> 0 | I27: =Total!I30*25 -> 0 | J27: =Total!J30*25 -> 0 | K27: =Total!K30*25 -> 175 | L27: =Total!L30*25 -> 75 | M27: =Total!M30*25 -> 150
B28: NO5 | C28: Del carmen | G28: =Total!G31*25 -> 0 | H28: =Total!H31*25 -> 0 | I28: =Total!I31*25 -> 0 | J28: =Total!J31*25 -> 0 | K28: =Total!K31*25 -> 225 | L28: =Total!L31*25 -> 125 | M28: =Total!M31*25 -> 225
B29: NO6 | C29: Rosario | G29: =Total!G32*25 -> 0 | H29: =Total!H32*25 -> 0 | I29: =Total!I32*25 -> 50 | J29: =Total!J32*25 -> 0 | K29: =Total!K32*25 -> 75 | L29: =Total!L32*25 -> 75 | M29: =Total!M32*25 -> 0
A30: Laguna Nor Central | B30: NC1 | C30: Ocetra | G30: =Total!G33*25 -> 0 | H30: =Total!H33*25 -> 0 | I30: =Total!I33*25 -> 0 | J30: =Total!J33*25 -> 0 | K30: =Total!K33*25 -> 150 | L30: =Total!L33*25 -> 125 | M30: =Total!M33*25 -> 250
B31: NC2 | C31: Ocetra | G31: =Total!G34*25 -> 0 | H31: =Total!H34*25 -> 0 | I31: =Total!I34*25 -> 0 | J31: =Total!J34*25 -> 0 | K31: =Total!K34*25 -> 225 | L31: =Total!L34*25 -> 175 | M31: =Total!M34*25 -> 325
B32: NC3 | C32: Ocetra | G32: =Total!G35*25 -> 0 | H32: =Total!H35*25 -> 0 | I32: =Total!I35*25 -> 0 | J32: =Total!J35*25 -> 0 | K32: =Total!K35*25 -> 25 | L32: =Total!L35*25 -> 200 | M32: =Total!M35*25 -> 300
B33: NC4 | C33: Ocetra | G33: =Total!G36*25 -> 0 | H33: =Total!H36*25 -> 0 | I33: =Total!I36*25 -> 0 | J33: =Total!J36*25 -> 0 | K33: =Total!K36*25 -> 25 | L33: =Total!L36*25 -> 200 | M33: =Total!M36*25 -> 400
B34: NC5 | C34: Ocetra | G34: =Total!G37*25 -> 0 | H34: =Total!H37*25 -> 0 | I34: =Total!I37*25 -> 0 | J34: =Total!J37*25 -> 0 | K34: =Total!K37*25 -> 25 | L34: =Total!L37*25 -> 125 | M34: =Total!M37*25 -> 225
B35: NC6 | C35: Ocetra | G35: =Total!G38*25 -> 0 | H35: =Total!H38*25 -> 0 | I35: =Total!I38*25 -> 0 | J35: =Total!J38*25 -> 0 | K35: =Total!K38*25 -> 25 | L35: =Total!L38*25 -> 125 | M35: =Total!M38*25 -> 275
A36: Laguna Nor Poniente | B36: NP1 | C36: Ocetra | G36: =Total!G39*25 -> 0 | H36: =Total!H39*25 -> 0 | I36: =Total!I39*25 -> 0 | J36: =Total!J39*25 -> 0 | K36: =Total!K39*25 -> 0 | L36: =Total!L39*25 -> 200 | M36: =Total!M39*25 -> 300
B37: NP2 | C37: Ocetra | G37: =Total!G40*25 -> 0 | H37: =Total!H40*25 -> 0 | I37: =Total!I40*25 -> 0 | J37: =Total!J40*25 -> 0 | K37: =Total!K40*25 -> 0 | L37: =Total!L40*25 -> 200 | M37: =Total!M40*25 -> 225
B38: NP3 | C38: Ocetra | G38: =Total!G41*25 -> 0 | H38: =Total!H41*25 -> 0 | I38: =Total!I41*25 -> 0 | J38: =Total!J41*25 -> 0 | K38: =Total!K41*25 -> 0 | L38: =Total!L41*25 -> 100 | M38: =Total!M41*25 -> 250
B39: NP4 | C39: Ocetra | G39: =Total!G42*25 -> 0 | H39: =Total!H42*25 -> 0 | I39: =Total!I42*25 -> 0 | J39: =Total!J42*25 -> 0 | K39: =Total!K42*25 -> 0 | L39: =Total!L42*25 -> 100 | M39: =Total!M42*25 -> 225
B40: NP5 | C40: Ocetra | G40: =Total!G43*25 -> 0 | H40: =Total!H43*25 -> 0 | I40: =Total!I43*25 -> 0 | J40: =Total!J43*25 -> 0 | K40: =Total!K43*25 -> 0 | L40: =Total!L43*25 -> 75 | M40: =Total!M43*25 -> 175
B41: NP6 | C41: Ocetra | G41: =Total!G44*25 -> 0 | H41: =Total!H44*25 -> 0 | I41: =Total!I44*25 -> 0 | J41: =Total!J44*25 -> 0 | K41: =Total!K44*25 -> 0 | L41: =Total!L44*25 -> 0 | M41: =Total!M44*25 -> 25
A42: Laguna Central | B42: C1 | C42: Dolores | G42: =Total!G45*25 -> 0 | H42: =Total!H45*25 -> 0 | I42: =Total!I45*25 -> 0 | J42: =Total!J45*25 -> 0 | K42: =Total!K45*25 -> 0 | L42: =Total!L45*25 -> 75 | M42: =Total!M45*25 -> 150 | N42: =+B42 -> C1
...

Sheet Hoja1

Sheet Hoja2
B1: SO1 | C1: SO2 | D1: SO3 | E1: SO4 | F1: SO5 | G1: SO6 | H1: SP1 | I1: SP2 | J1: SP3 | K1: SP4 | L1: SP5 | M1: SP6 | N1: NO1 | O1: NO2 | P1: NO3 | Q1: NO4 | R1: NO5 | S1: NO6 | T1: NC1 | U1: NC2 | V1: NC3 | W1: NC4 | X1: NC5 | Y1: NC6 | Z1: NP1 | AA1: NP2 | AB1: NP3 | AC1: NP4 | AD1: NP5 | AE1: NP6 | AF1: C1 | AG1: C2 | AH1: C3 | AI1: C4
B2: =Total!B2 -> 0 | C2: =Total!C2 -> 0 | D2: =Total!D2 -> 0 | E2: =Total!E2 -> 0 | F2: =Total!F2 -> 0 | G2: =Total!G2 -> 0 | H2: =Total!H2 -> 0 | I2: =Total!I2 -> 0 | ... AH2: =Total!AH2 -> 0 | AI2: =Total!AK2 -> 8
B3: =Total!B3 -> 0 | C3: =Total!C3 -> 0 | D3: =Total!D3 -> 0 | E3: =Total!E3 -> 0 | F3: =Total!F3 -> 0 | G3: =Total!G3 -> 0 | H3: =Total!H3 -> 0 | I3: =Total!I3 -> 0 | ... AH3: =Total!AH3 -> 0 | AI3: =Total!AK3 -> 0
B4: =Total!B4 -> 0 | C4: =Total!C4 -> 0 | D4: =Total!D4 -> 0 | E4: =Total!E4 -> 0 | F4: =Total!F4 -> 0 | G4: =Total!G4 -> 0 | H4: =Total!H4 -> 0 | I4: =Total!I4 -> 0 | ... AH4: =Total!AH4 -> 0 | AI4: =Total!AK4 -> 9
B5: =Total!B5 -> 0 | C5: =Total!C5 -> 0 | D5: =Total!D5 -> 0 | E5: =Total!E5 -> 0 | F5: =Total!F5 -> 0 | G5: =Total!G5 -> 0 | H5: =Total!H5 -> 0 | I5: =Total!I5 -> 0 | ... AH5: =Total!AH5 -> 0 | AI5: =Total!AK5 -> 0
B6: =Total!B6 -> 0 | C6: =Total!C6 -> 0 | D6: =Total!D6 -> 0 | E6: =Total!E6 -> 0 | F6: =Total!F6 -> 0 | G6: =Total!G6 -> 0 | H6: =Total!H6 -> 0 | I6: =Total!I6 -> 0 | ... AH6: =Total!AH6 -> 0 | AI6: =Total!AK6 -> 0
B7: =Total!B7 -> 0 | C7: =Total!C7 -> 0 | D7: =Total!D7 -> 0 | E7: =Total!E7 -> 0 | F7: =Total!F7 -> 0 | G7: =Total!G7 -> 0 | H7: =Total!H7 -> 0 | I7: =Total!I7 -> 0 | ... AH7: =Total!AH7 -> 3 | AI7: =Total!AK7 -> 0
B8: =Total!B8 -> 0 | C8: =Total!C8 -> 0 | D8: =Total!D8 -> 0 | E8: =Total!E8 -> 0 | F8: =Total!F8 -> 0 | G8: =Total!G8 -> 0 | H8: =Total!H8 -> 0 | I8: =Total!I8 -> 0 | ... AH8: =Total!AH8 -> 6 | AI8: =Total!AK8 -> 0
