Workbook

Sheet 01
B1: Registro | D1: PC 01.1 | G1: Programa de Crianza
B2: Versión: | D2: 2
B3: Fecha: | D3: 44701
B4: Elaborado Por: | D4: A - Vial
B5: Modificado por: | D5: R - Gatica | G5: Retiro de Alimentación Piscinas exteriores
B6: Aprobado Por | D6: A - Vial | S6: Mes: | T6: Abril | V6: Folio:
B7: Hojas: | D7: 1 de 3 | G7: Acuícola Alas S.A., Ruta 5 sur, Km 338, VII región, Parral
B9: Dia: | C9: 1 al 5 de abril 2026 | O9: Dia: | P9: 6 al 12 de abril 2026
C10: Thalassa 0.9 -1.6 | D10: Thalassa 1.3 - 2.0 | E10: 3 mm progress ex | F10: 4.5 mm Progress | G10: 6 mm Progress | H10: 8 mm Progress | I10: 8 mm Reproductor | M10: Total | P10: =C10 -> Thalassa 0.9 -1.6 | Q10: =D10 -> Thalassa 1.3 - 2.0 | R10: =E10 -> 3 mm progress ex | S10: =F10 -> 4.5 mm Progress | T10: =G10 -> 6 mm Progress | U10: =H10 -> 8 mm Progress | V10: =I10 -> 8 mm Reproductor | Z10: Total
A11: Caridad | B11: SO1 | E11: 2 | M11: =SUM(C11:L11) -> 2 | O11: SO1 | R11: 2 | Z11: =SUM(P11:Y11) -> 2
A12: Pilar | B12: SO2 | G12: 2 | M12: =SUM(C12:L12) -> 2 | O12: SO2 | T12: 2 | V12: 3 | Z12: =SUM(P12:Y12) -> 5
A13: Ocetra | B13: SO3 | G13: 1 | M13: =SUM(C13:L13) -> 1 | O13: SO3 | T13: 1 | V13: 1 | Z13: =SUM(P13:Y13) -> 2
A14: Candelaria | B14: SO4 | E14: 2 | G14: 1 | M14: =SUM(C14:L14) -> 3 | O14: SO4 | R14: 2 | T14: 2 | Z14: =SUM(P14:Y14) -> 4
A15: Dolores | B15: SO5 | M15: =SUM(C15:L15) -> 0 | O15: SO5 | V15: 1 | Z15: =SUM(P15:Y15) -> 1
A16: Caridad | B16: SO6 | E16: 2 | M16: =SUM(C16:L16) -> 2 | O16: SO6 | R16: 2 | Z16: =SUM(P16:Y16) -> 2
B17: SP1 | M17: =SUM(C17:L17) -> 0 | O17: SP1 | Z17: =SUM(P17:Y17) -> 0
B18: SP2 | M18: =SUM(C18:L18) -> 0 | O18: SP2 | Z18: =SUM(P18:Y18) -> 0
B19: SP3 | M19: =SUM(C19:L19) -> 0 | O19: SP3 | Z19: =SUM(P19:Y19) -> 0
B20: SP4 | M20: =SUM(C20:L20) -> 0 | O20: SP4 | Z20: =SUM(P20:Y20) -> 0
B21: SP5 | M21: =SUM(C21:L21) -> 0 | O21: SP5 | Z21: =SUM(P21:Y21) -> 0
B22: SP6 | M22: =SUM(C22:L22) -> 0 | O22: SP6 | Z22: =SUM(P22:Y22) -> 0
A23: Rosario | B23: NO1 | G23: 3 | M23: =SUM(C23:L23) -> 3 | O23: NO1 | T23: 2 | Z23: =SUM(P23:Y23) -> 2
A24: Pilar | B24: NO2 | G24: 2 | M24: =SUM(C24:L24) -> 2 | O24: NO2 | T24: 2 | Z24: =SUM(P24:Y24) -> 2
A25: Pilar | B25: NO3 | G25: 2 | M25: =SUM(C25:L25) -> 2 | O25: NO3 | T25: 2 | Z25: =SUM(P25:Y25) -> 2
A26: Del carmen | B26: NO4 | G26: 2 | M26: =SUM(C26:L26) -> 2 | O26: NO4 | T26: 2 | Z26: =SUM(P26:Y26) -> 2
A27: Victoria | B27: NO5 | E27: 2 | G27: 1 | M27: =SUM(C27:L27) -> 3 | O27: NO5 | R27: 2 | T27: 2 | Z27: =SUM(P27:Y27) -> 4
A28: Rosario | B28: NO6 | G28: 3 | M28: =SUM(C28:L28) -> 3 | O28: NO6 | T28: 3 | Z28: =SUM(P28:Y28) -> 3
A29: Ocetra | B29: NC1 | H29: 1 | M29: =SUM(C29:L29) -> 1 | O29: NC1 | U29: 1 | Z29: =SUM(P29:Y29) -> 1
A30: Ocetra | B30: NC2 | M30: =SUM(C30:L30) -> 0 | O30: NC2 | Z30: =SUM(P30:Y30) -> 0
A31: Ocetra | B31: NC3 | G31: 2 | M31: =SUM(C31:L31) -> 2 | O31: NC3 | T31: 3 | Z31: =SUM(P31:Y31) -> 3
A32: Rosa | B32: NC4 | F32: 1 | G32: 2 | H32: 0 | M32: =SUM(C32:L32) -> 3 | O32: NC4 | S32: 1 | T32: 3 | U32: 0 | Z32: =SUM(P32:Y32) -> 4
A33: Ocetra | B33: NC5 | M33: =SUM(C33:L33) -> 0 | O33: NC5 | Z33: =SUM(P33:Y33) -> 0
A34: Ocetra | B34: NC6 | M34: =SUM(C34:L34) -> 0 | O34: NC6 | Z34: =SUM(P34:Y34) -> 0
A35: Ocetra | B35: NP1 | M35: =SUM(C35:L35) -> 0 | O35: NP1 | Z35: =SUM(P35:Y35) -> 0
A36: Ocetra | B36: NP2 | M36: =SUM(C36:L36) -> 0 | O36: NP2 | U36: 1 | Z36: =SUM(P36:Y36) -> 1
A37: Ocetra | B37: NP3 | G37: 2 | M37: =SUM(C37:L37) -> 2 | O37: NP3 | T37: 2 | Z37: =SUM(P37:Y37) -> 2
A38: Ocetra | B38: NP4 | G38: 2 | M38: =SUM(C38:L38) -> 2 | O38: NP4 | T38: 2 | Z38: =SUM(P38:Y38) -> 2
A39: Ocetra | B39: NP5 | M39: =SUM(C39:L39) -> 0 | O39: NP5 | Z39: =SUM(P39:Y39) -> 0
A40: Ocetra | B40: NP6 | M40: =SUM(C40:L40) -> 0 | O40: NP6 | U40: 1 | Z40: =SUM(P40:Y40) -> 1
A41: ocetra | B41: C1 | M41: =SUM(C41:L41) -> 0 | O41: C1 | Z41: =SUM(P41:Y41) -> 0
...

Sheet 02
B1: Registro | D1: PC 01.1 | G1: Programa de Crianza
B2: Versión: | D2: 2
B3: Fecha: | D3: 44701
B4: Elaborado Por: | D4: A - Vial
B5: Modificado por: | D5: R - Gatica | G5: Retiro de Alimentación Piscinas exteriores
B6: Aprobado Por | D6: A - Vial | S6: Mes: | T6: ='01'!T6 -> Abril | V6: Folio:
B7: Hojas: | D7: 1 de 3 | G7: Acuícola Alas S.A., Ruta 5 sur, Km 338, VII región, Parral
B9: Dia: | C9: Lunes 15 de diciembre | O9: Dia: | P9: Lunes 22 Diciembre
C10: Thalassa 0.9 -1.6 | D10: Thalassa 1.3 - 2.0 | E10: 3 mm progress ex | F10: 4.5 mm Progress | G10: 6 mm Progress | H10: 8 mm Progress | I10: 8 mm Reproductor | M10: Total | P10: =C10 -> Thalassa 0.9 -1.6 | Q10: =D10 -> Thalassa 1.3 - 2.0 | R10: =E10 -> 3 mm progress ex | S10: =F10 -> 4.5 mm Progress | T10: =G10 -> 6 mm Progress | U10: =H10 -> 8 mm Progress | V10: =I10 -> 8 mm Reproductor | Z10: Total
A11: Caridad | B11: SO1 | E11: 2 | M11: =SUM(C11:L11) -> 2 | O11: SO1 | R11: 2 | Z11: =SUM(P11:Y11) -> 2
A12: Pilar | B12: SO2 | G12: 2 | M12: =SUM(C12:L12) -> 2 | O12: SO2 | T12: 2 | Z12: =SUM(P12:Y12) -> 2
A13: Ocetra | B13: SO3 | G13: 1 | H13: 1 | I13: 1 | M13: =SUM(C13:L13) -> 3 | O13: SO3 | T13: 1 | U13: 1 | V13: 1 | Z13: =SUM(P13:Y13) -> 3
A14: Candelaria | B14: SO4 | E14: 2 | M14: =SUM(C14:L14) -> 2 | O14: SO4 | R14: 2 | Z14: =SUM(P14:Y14) -> 2
A15: Dolores | B15: SO5 | H15: 1 | I15: 1 | M15: =SUM(C15:L15) -> 2 | O15: SO5 | U15: 1 | V15: 1 | Z15: =SUM(P15:Y15) -> 2
A16: Caridad | B16: SO6 | E16: 2 | M16: =SUM(C16:L16) -> 2 | O16: SO6 | R16: 2 | Z16: =SUM(P16:Y16) -> 2
B17: SP1 | M17: =SUM(C17:L17) -> 0 | O17: SP1 | Z17: =SUM(P17:Y17) -> 0
B18: SP2 | M18: =SUM(C18:L18) -> 0 | O18: SP2 | Z18: =SUM(P18:Y18) -> 0
B19: SP3 | M19: =SUM(C19:L19) -> 0 | O19: SP3 | Z19: =SUM(P19:Y19) -> 0
B20: SP4 | M20: =SUM(C20:L20) -> 0 | O20: SP4 | Z20: =SUM(P20:Y20) -> 0
B21: SP5 | M21: =SUM(C21:L21) -> 0 | O21: SP5 | Z21: =SUM(P21:Y21) -> 0
B22: SP6 | M22: =SUM(C22:L22) -> 0 | O22: SP6 | Z22: =SUM(P22:Y22) -> 0
A23: Rosario | B23: NO1 | G23: 2 | H23: 1 | M23: =SUM(C23:L23) -> 3 | O23: NO1 | T23: 2 | U23: 1 | Z23: =SUM(P23:Y23) -> 3
A24: Pilar | B24: NO2 | G24: 2 | M24: =SUM(C24:L24) -> 2 | O24: NO2 | T24: 2 | Z24: =SUM(P24:Y24) -> 2
A25: Pilar | B25: NO3 | G25: 2 | M25: =SUM(C25:L25) -> 2 | O25: NO3 | T25: 2 | Z25: =SUM(P25:Y25) -> 2
A26: Del carmen | B26: NO4 | G26: 2 | M26: =SUM(C26:L26) -> 2 | O26: NO4 | T26: 2 | Z26: =SUM(P26:Y26) -> 2
A27: Victoria | B27: NO5 | E27: 2 | M27: =SUM(C27:L27) -> 2 | O27: NO5 | R27: 2 | Z27: =SUM(P27:Y27) -> 2
A28: Rosario | B28: NO6 | G28: 2 | H28: 1 | M28: =SUM(C28:L28) -> 3 | O28: NO6 | T28: 2 | U28: 1 | Z28: =SUM(P28:Y28) -> 3
A29: Ocetra | B29: NC1 | H29: 2 | I29: 2 | M29: =SUM(C29:L29) -> 4 | O29: NC1 | U29: 1 | V29: 2 | Z29: =SUM(P29:Y29) -> 3
A30: Ocetra | B30: NC2 | H30: 2 | I30: 2 | M30: =SUM(C30:L30) -> 4 | O30: NC2 | V30: 2 | Z30: =SUM(P30:Y30) -> 2
A31: Ocetra | B31: NC3 | G31: 3 | H31: 1 | I31: 2 | M31: =SUM(C31:L31) -> 6 | O31: NC3 | T31: 3 | V31: 2 | Z31: =SUM(P31:Y31) -> 5
A32: Rosa | B32: NC4 | F32: 1 | G32: 3 | H32: 0 | M32: =SUM(C32:L32) -> 4 | O32: NC4 | S32: 1 | T32: 3 | U32: 0 | Z32: =SUM(P32:Y32) -> 4
A33: Ocetra | B33: NC5 | H33: 1 | I33: 1 | M33: =SUM(C33:L33) -> 2 | O33: NC5 | U33: 1 | V33: 1 | Z33: =SUM(P33:Y33) -> 2
A34: Ocetra | B34: NC6 | I34: 1 | M34: =SUM(C34:L34) -> 1 | O34: NC6 | V34: 1 | Z34: =SUM(P34:Y34) -> 1
A35: Ocetra | B35: NP1 | H35: 1 | I35: 1 | M35: =SUM(C35:L35) -> 2 | O35: NP1 | U35: 1 | V35: 6 | Z35: =SUM(P35:Y35) -> 7
A36: Ocetra | B36: NP2 | H36: 2 | I36: 1 | M36: =SUM(C36:L36) -> 3 | O36: NP2 | U36: 2 | V36: 5 | Z36: =SUM(P36:Y36) -> 7
A37: Ocetra | B37: NP3 | G37: 2 | I37: 1 | M37: =SUM(C37:L37) -> 3 | O37: NP3 | T37: 2 | V37: 1 | Z37: =SUM(P37:Y37) -> 3
A38: Ocetra | B38: NP4 | G38: 2 | I38: 1 | M38: =SUM(C38:L38) -> 3 | O38: NP4 | T38: 2 | V38: 1 | Z38: =SUM(P38:Y38) -> 3
A39: Ocetra | B39: NP5 | I39: 2 | M39: =SUM(C39:L39) -> 2 | O39: NP5 | V39: 2 | Z39: =SUM(P39:Y39) -> 2
A40: Ocetra | B40: NP6 | H40: 1 | M40: =SUM(C40:L40) -> 1 | O40: NP6 | U40: 1 | Z40: =SUM(P40:Y40) -> 1
A41: Dolores | B41: C1 | I41: 1 | M41: =SUM(C41:L41) -> 1 | O41: C1 | V41: 1 | Z41: =SUM(P41:Y41) -> 1
...

Sheet 03
A1: Registro | C1: PC 01.1 | F1: Programa de Crianza
A2: Versión: | C2: 2
A3: Fecha: | C3: 44701
A4: Elaborado Por: | C4: A - Vial
A5: Modificado por: | C5: R - Gatica | F5: Retiro de Alimentación Piscinas exteriores
A6: Aprobado Por | C6: A - Vial | R6: Mes: | S6: ='01'!T6 -> Abril | U6: Folio:
A7: Hojas: | C7: 1 de 3 | F7: Acuícola Alas S.A., Ruta 5 sur, Km 338, VII región, Parral
A9: Dia: | B9: Lunes 15 Septiembre | N9: Dia: | O9: Miercoles 19
B10: Thalassa 0.9 -1.6 | C10: Thalassa 1.3 - 2.0 | D10: 3 mm progress ex | E10: 4.5 mm Progress | F10: 6 mm Progress | G10: 8 mm Progress | H10: 8 mm Reproductor | I10: Ewos Micro PSZ LE 100 4.0 mm | J10: Ewos Micro PSZ LE 250 6.0 mm | K10: Ewos Breed 800 70A 9.5 mm | L10: Total | O10: =B10 -> Thalassa 0.9 -1.6 | P10: =C10 -> Thalassa 1.3 - 2.0 | Q10: =D10 -> 3 mm progress ex | R10: =E10 -> 4.5 mm Progress | S10: =F10 -> 6 mm Progress | T10: =G10 -> 8 mm Progress | U10: =H10 -> 8 mm Reproductor | V10: =I10 -> Ewos Micro PSZ LE 100 4.0 mm | ... X10: =K10 -> Ewos Breed 800 70A 9.5 mm | Y10: Total
A11: SO1 | L11: =SUM(B11:K11) -> 0 | N11: SO1 | Y11: =SUM(O11:X11) -> 0
A12: SO2 | L12: =SUM(B12:K12) -> 0 | N12: SO2 | Y12: =SUM(O12:X12) -> 0
A13: SO3 | L13: =SUM(B13:K13) -> 0 | N13: SO3 | Y13: =SUM(O13:X13) -> 0
A14: SO4 | L14: =SUM(B14:K14) -> 0 | N14: SO4 | Y14: =SUM(O14:X14) -> 0
A15: SO5 | L15: =SUM(B15:K15) -> 0 | N15: SO5 | Y15: =SUM(O15:X15) -> 0
A16: SO6 | L16: =SUM(B16:K16) -> 0 | N16: SO6 | Y16: =SUM(O16:X16) -> 0
A17: SP1 | L17: =SUM(B17:K17) -> 0 | N17: SP1 | Y17: =SUM(O17:X17) -> 0
A18: SP2 | L18: =SUM(B18:K18) -> 0 | N18: SP2 | Y18: =SUM(O18:X18) -> 0
A19: SP3 | L19: =SUM(B19:K19) -> 0 | N19: SP3 | Y19: =SUM(O19:X19) -> 0
A20: SP4 | L20: =SUM(B20:K20) -> 0 | N20: SP4 | Y20: =SUM(O20:X20) -> 0
A21: SP5 | L21: =SUM(B21:K21) -> 0 | N21: SP5 | Y21: =SUM(O21:X21) -> 0
A22: SP6 | L22: =SUM(B22:K22) -> 0 | N22: SP6 | Y22: =SUM(O22:X22) -> 0
... A49: Jaula | L49: =SUM(B49:K49) -> 0 | N49: Jaula | Y49: =SUM(O49:X49) -> 0
A50: Total | B50: =SUM(B11:B49) -> 0 | C50: =SUM(C11:C49) -> 0 | D50: =SUM(D11:D49) -> 0 | E50: =SUM(E11:E49) -> 0 | F50: =SUM(F11:F49) -> 0 | G50: =SUM(G11:G49) -> 0 | H50: =SUM(H11:H49) -> 0 | I50: =SUM(I11:I49) -> 0 | ... L50: =SUM(L11:L49) -> 0 | N50: Total | O50: =SUM(O11:O49) -> 0 | P50: =SUM(P11:P49) -> 0 | Q50: =SUM(Q11:Q49) -> 0 | R50: =SUM(R11:R49) -> 0 | S50: =SUM(S11:S49) -> 0 | T50: =SUM(T11:T49) -> 0 | U50: =SUM(U11:U49) -> 0 | V50: =SUM(V11:V49) -> 0 | ... Y50: =SUM(Y11:Y49) -> 0
A56: Dia: | N56: Dia:
B57: =B10 -> Thalassa 0.9 -1.6 | C57: =C10 -> Thalassa 1.3 - 2.0 | D57: =D10 -> 3 mm progress ex | E57: =E10 -> 4.5 mm Progress | F57: =F10 -> 6 mm Progress | G57: =G10 -> 8 mm Progress | H57: =H10 -> 8 mm Reproductor | I57: =I10 -> Ewos Micro PSZ LE 100 4.0 mm | ... K57: =K10 -> Ewos Breed 800 70A 9.5 mm | L57: Total | O57: =B10 -> Thalassa 0.9 -1.6 | P57: =C10 -> Thalassa 1.3 - 2.0 | Q57: =D10 -> 3 mm progress ex | R57: =E10 -> 4.5 mm Progress | S57: =F10 -> 6 mm Progress | T57: =G10 -> 8 mm Progress | U57: =H10 -> 8 mm Reproductor | V57: =I10 -> Ewos Micro PSZ LE 100 4.0 mm | ... X57: =K10 -> Ewos Breed 800 70A 9.5 mm | Y57: Total
A58: SO1 | L58: =SUM(B58:K58) -> 0 | N58: SO1 | Y58: =SUM(O58:X58) -> 0
A59: SO2 | L59: =SUM(B59:K59) -> 0 | N59: SO2 | Y59: =SUM(O59:X59) -> 0
A60: SO3 | L60: =SUM(B60:K60) -> 0 | N60: SO3 | Y60: =SUM(O60:X60) -> 0
A61: SO4 | L61: =SUM(B61:K61) -> 0 | N61: SO4 | Y61: =SUM(O61:X61) -> 0
A62: SO5 | L62: =SUM(B62:K62) -> 0 | N62: SO5 | Y62: =SUM(O62:X62) -> 0
A63: SO6 | L63: =SUM(B63:K63) -> 0 | N63: SO6 | Y63: =SUM(O63:X63) -> 0
A64: SP1 | L64: =SUM(B64:K64) -> 0 | N64: SP1 | Y64: =SUM(O64:X64) -> 0
A65: SP2 | L65: =SUM(B65:K65) -> 0 | N65: SP2 | Y65: =SUM(O65:X65) -> 0
A66: SP3 | L66: =SUM(B66:K66) -> 0 | N66: SP3 | Y66: =SUM(O66:X66) -> 0
A67: SP4 | L67: =SUM(B67:K67) -> 0 | N67: SP4 | Y67: =SUM(O67:X67) -> 0
A68: SP5 | L68: =SUM(B68:K68) -> 0 | N68: SP5 | Y68: =SUM(O68:X68) -> 0
A69: SP6 | L69: =SUM(B69:K69) -> 0 | N69: SP6 | Y69: =SUM(O69:X69) -> 0
... A96: Jaula | L96: =SUM(B96:K96) -> 0 | N96: Jaula | Y96: =SUM(O96:X96) -> 0
A97: Total | B97: =SUM(B58:B96) -> 0 | C97: =SUM(C58:C96) -> 0 | D97: =SUM(D58:D96) -> 0 | E97: =SUM(E58:E96) -> 0 | F97: =SUM(F58:F96) -> 0 | G97: =SUM(G58:G96) -> 0 | H97: =SUM(H58:H96) -> 0 | I97: =SUM(I58:I96) -> 0 | ... L97: =SUM(L58:L96) -> 0 | N97: Total | O97: =SUM(O58:O96) -> 0 | P97: =SUM(P58:P96) -> 0 | Q97: =SUM(Q58:Q96) -> 0 | R97: =SUM(R58:R96) -> 0 | S97: =SUM(S58:S96) -> 0 | T97: =SUM(T58:T96) -> 0 | U97: =SUM(U58:U96) -> 0 | V97: =SUM(V58:V96) -> 0 | ... Y97: =SUM(Y58:Y96) -> 0

Sheet 04
A1: Registro | C1: PC 01.1 | F1: Programa de Crianza
A2: Versión: | C2: 2
A3: Fecha: | C3: 44701
A4: Elaborado Por: | C4: A - Vial
A5: Modificado por: | C5: R - Gatica | F5: Retiro de Alimentación Piscinas exteriores
A6: Aprobado Por | C6: A - Vial | R6: Mes: | S6: ='01'!T6 -> Abril | U6: Folio:
A7: Hojas: | C7: 1 de 3 | F7: Acuícola Alas S.A., Ruta 5 sur, Km 338, VII región, Parral
A9: Dia: | B9: Lunes 22 Septiembre | N9: Dia: | O9: Miercoles 26
B10: Thalassa 0.9 -1.6 | C10: Thalassa 1.3 - 2.0 | D10: 3 mm progress ex | E10: 4.5 mm Progress | F10: 6 mm Progress | G10: 8 mm Progress | H10: 8 mm Reproductor | I10: Ewos Micro PSZ LE 100 4.0 mm | J10: Ewos Micro PSZ LE 250 6.0 mm | K10: Ewos Breed 800 70A 9.5 mm | L10: Total | O10: =B10 -> Thalassa 0.9 -1.6 | P10: =C10 -> Thalassa 1.3 - 2.0 | Q10: =D10 -> 3 mm progress ex | R10: =E10 -> 4.5 mm Progress | S10: =F10 -> 6 mm Progress | T10: =G10 -> 8 mm Progress | U10: =H10 -> 8 mm Reproductor | V10: =I10 -> Ewos Micro PSZ LE 100 4.0 mm | ... X10: =K10 -> Ewos Breed 800 70A 9.5 mm | Y10: Total
A11: SO1 | L11: =SUM(B11:K11) -> 0 | N11: SO1 | Y11: =SUM(O11:X11) -> 0
A12: SO2 | L12: =SUM(B12:K12) -> 0 | N12: SO2 | Y12: =SUM(O12:X12) -> 0
A13: SO3 | L13: =SUM(B13:K13) -> 0 | N13: SO3 | Y13: =SUM(O13:X13) -> 0
A14: SO4 | L14: =SUM(B14:K14) -> 0 | N14: SO4 | Y14: =SUM(O14:X14) -> 0
A15: SO5 | L15: =SUM(B15:K15) -> 0 | N15: SO5 | Y15: =SUM(O15:X15) -> 0
A16: SO6 | L16: =SUM(B16:K16) -> 0 | N16: SO6 | Y16: =SUM(O16:X16) -> 0
A17: SP1 | L17: =SUM(B17:K17) -> 0 | N17: SP1 | Y17: =SUM(O17:X17) -> 0
A18: SP2 | L18: =SUM(B18:K18) -> 0 | N18: SP2 | Y18: =SUM(O18:X18) -> 0
A19: SP3 | L19: =SUM(B19:K19) -> 0 | N19: SP3 | Y19: =SUM(O19:X19) -> 0
A20: SP4 | L20: =SUM(B20:K20) -> 0 | N20: SP4 | Y20: =SUM(O20:X20) -> 0
A21: SP5 | L21: =SUM(B21:K21) -> 0 | N21: SP5 | Y21: =SUM(O21:X21) -> 0
A22: SP6 | L22: =SUM(B22:K22) -> 0 | N22: SP6 | Y22: =SUM(O22:X22) -> 0
... A49: Jaula | L49: =SUM(B49:K49) -> 0 | N49: Jaula | Y49: =SUM(O49:X49) -> 0
A50: Total | B50: =SUM(B11:B49) -> 0 | C50: =SUM(C11:C49) -> 0 | D50: =SUM(D11:D49) -> 0 | E50: =SUM(E11:E49) -> 0 | F50: =SUM(F11:F49) -> 0 | G50: =SUM(G11:G49) -> 0 | H50: =SUM(H11:H49) -> 0 | I50: =SUM(I11:I49) -> 0 | ... L50: =SUM(L11:L49) -> 0 | N50: Total | O50: =SUM(O11:O49) -> 0 | P50: =SUM(P11:P49) -> 0 | Q50: =SUM(Q11:Q49) -> 0 | R50: =SUM(R11:R49) -> 0 | S50: =SUM(S11:S49) -> 0 | T50: =SUM(T11:T49) -> 0 | U50: =SUM(U11:U49) -> 0 | V50: =SUM(V11:V49) -> 0 | ... Y50: =SUM(Y11:Y49) -> 0
A56: Dia: | N56: Dia:
B57: =B10 -> Thalassa 0.9 -1.6 | C57: =C10 -> Thalassa 1.3 - 2.0 | D57: =D10 -> 3 mm progress ex | E57: =E10 -> 4.5 mm Progress | F57: =F10 -> 6 mm Progress | G57: =G10 -> 8 mm Progress | H57: =H10 -> 8 mm Reproductor | I57: =I10 -> Ewos Micro PSZ LE 100 4.0 mm | ... K57: =K10 -> Ewos Breed 800 70A 9.5 mm | L57: Total | O57: =B10 -> Thalassa 0.9 -1.6 | P57: =C10 -> Thalassa 1.3 - 2.0 | Q57: =D10 -> 3 mm progress ex | R57: =E10 -> 4.5 mm Progress | S57: =F10 -> 6 mm Progress | T57: =G10 -> 8 mm Progress | U57: =H10 -> 8 mm Reproductor | V57: =I10 -> Ewos Micro PSZ LE 100 4.0 mm | ... X57: =K10 -> Ewos Breed 800 70A 9.5 mm | Y57: Total
A58: SO1 | L58: =SUM(B58:K58) -> 0 | N58: SO1 | Y58: =SUM(O58:X58) -> 0
A59: SO2 | L59: =SUM(B59:K59) -> 0 | N59: SO2 | Y59: =SUM(O59:X59) -> 0
A60: SO3 | L60: =SUM(B60:K60) -> 0 | N60: SO3 | Y60: =SUM(O60:X60) -> 0
A61: SO4 | L61: =SUM(B61:K61) -> 0 | N61: SO4 | Y61: =SUM(O61:X61) -> 0
A62: SO5 | L62: =SUM(B62:K62) -> 0 | N62: SO5 | Y62: =SUM(O62:X62) -> 0
A63: SO6 | L63: =SUM(B63:K63) -> 0 | N63: SO6 | Y63: =SUM(O63:X63) -> 0
A64: SP1 | L64: =SUM(B64:K64) -> 0 | N64: SP1 | Y64: =SUM(O64:X64) -> 0
A65: SP2 | L65: =SUM(B65:K65) -> 0 | N65: SP2 | Y65: =SUM(O65:X65) -> 0
A66: SP3 | L66: =SUM(B66:K66) -> 0 | N66: SP3 | Y66: =SUM(O66:X66) -> 0
A67: SP4 | L67: =SUM(B67:K67) -> 0 | N67: SP4 | Y67: =SUM(O67:X67) -> 0
A68: SP5 | L68: =SUM(B68:K68) -> 0 | N68: SP5 | Y68: =SUM(O68:X68) -> 0
A69: SP6 | L69: =SUM(B69:K69) -> 0 | N69: SP6 | Y69: =SUM(O69:X69) -> 0
... A96: Jaula | L96: =SUM(B96:K96) -> 0 | N96: Jaula | Y96: =SUM(O96:X96) -> 0
A97: Total | B97: =SUM(B58:B96) -> 0 | C97: =SUM(C58:C96) -> 0 | D97: =SUM(D58:D96) -> 0 | E97: =SUM(E58:E96) -> 0 | F97: =SUM(F58:F96) -> 0 | G97: =SUM(G58:G96) -> 0 | H97: =SUM(H58:H96) -> 0 | I97: =SUM(I58:I96) -> 0 | ... L97: =SUM(L58:L96) -> 0 | N97: Total | O97: =SUM(O58:O96) -> 0 | P97: =SUM(P58:P96) -> 0 | Q97: =SUM(Q58:Q96) -> 0 | R97: =SUM(R58:R96) -> 0 | S97: =SUM(S58:S96) -> 0 | T97: =SUM(T58:T96) -> 0 | U97: =SUM(U58:U96) -> 0 | V97: =SUM(V58:V96) -> 0 | ... Y97: =SUM(Y58:Y96) -> 0

Sheet 05
A1: Registro | C1: PC 01.1 | F1: Programa de Crianza
A2: Versión: | C2: 2
A3: Fecha: | C3: 44701
A4: Elaborado Por: | C4: A - Vial
A5: Modificado por: | C5: R - Gatica | F5: Retiro de Alimentación Piscinas exteriores
A6: Aprobado Por | C6: A - Vial | R6: Mes: | S6: ='01'!T6 -> Abril | U6: Folio:
A7: Hojas: | C7: 1 de 3 | F7: Acuícola Alas S.A., Ruta 5 sur, Km 338, VII región, Parral
A9: Dia: | B9: Lunes 29 Septiembre | N9: Dia:
B10: Thalassa 0.9 -1.6 | C10: Thalassa 1.3 - 2.0 | D10: 3 mm progress ex | E10: 4.5 mm Progress | F10: 6 mm Progress | G10: 8 mm Progress | H10: 8 mm Reproductor | L10: Total | O10: =B10 -> Thalassa 0.9 -1.6 | P10: =C10 -> Thalassa 1.3 - 2.0 | Q10: =D10 -> 3 mm progress ex | R10: =E10 -> 4.5 mm Progress | S10: =F10 -> 6 mm Progress | T10: =G10 -> 8 mm Progress | U10: =H10 -> 8 mm Reproductor | V10: =I10 -> 0 | ... X10: =K10 -> 0 | Y10: Total
A11: SO1 | L11: =SUM(B11:K11) -> 0 | N11: SO1 | Y11: =SUM(O11:X11) -> 0
A12: SO2 | L12: =SUM(B12:K12) -> 0 | N12: SO2 | Y12: =SUM(O12:X12) -> 0
A13: SO3 | L13: =SUM(B13:K13) -> 0 | N13: SO3 | Y13: =SUM(O13:X13) -> 0
A14: SO4 | L14: =SUM(B14:K14) -> 0 | N14: SO4 | Y14: =SUM(O14:X14) -> 0
A15: SO5 | L15: =SUM(B15:K15) -> 0 | N15: SO5 | Y15: =SUM(O15:X15) -> 0
A16: SO6 | L16: =SUM(B16:K16) -> 0 | N16: SO6 | Y16: =SUM(O16:X16) -> 0
A17: SP1 | L17: =SUM(B17:K17) -> 0 | N17: SP1 | Y17: =SUM(O17:X17) -> 0
A18: SP2 | L18: =SUM(B18:K18) -> 0 | N18: SP2 | Y18: =SUM(O18:X18) -> 0
A19: SP3 | L19: =SUM(B19:K19) -> 0 | N19: SP3 | Y19: =SUM(O19:X19) -> 0
A20: SP4 | L20: =SUM(B20:K20) -> 0 | N20: SP4 | Y20: =SUM(O20:X20) -> 0
A21: SP5 | L21: =SUM(B21:K21) -> 0 | N21: SP5 | Y21: =SUM(O21:X21) -> 0
A22: SP6 | L22: =SUM(B22:K22) -> 0 | N22: SP6 | Y22: =SUM(O22:X22) -> 0
... A49: Jaula | L49: =SUM(B49:K49) -> 0 | N49: Jaula | Y49: =SUM(O49:X49) -> 0
A50: Total | B50: =SUM(B11:B49) -> 0 | C50: =SUM(C11:C49) -> 0 | D50: =SUM(D11:D49) -> 0 | E50: =SUM(E11:E49) -> 0 | F50: =SUM(F11:F49) -> 0 | G50: =SUM(G11:G49) -> 0 | H50: =SUM(H11:H49) -> 0 | I50: =SUM(I11:I49) -> 0 | ... L50: =SUM(L11:L49) -> 0 | N50: Total | O50: =SUM(O11:O49) -> 0 | P50: =SUM(P11:P49) -> 0 | Q50: =SUM(Q11:Q49) -> 0 | R50: =SUM(R11:R49) -> 0 | S50: =SUM(S11:S49) -> 0 | T50: =SUM(T11:T49) -> 0 | U50: =SUM(U11:U49) -> 0 | V50: =SUM(V11:V49) -> 0 | ... Y50: =SUM(Y11:Y49) -> 0
A56: Dia: | N56: Dia:
B57: =B10 -> Thalassa 0.9 -1.6 | C57: =C10 -> Thalassa 1.3 - 2.0 | D57: =D10 -> 3 mm progress ex | E57: =E10 -> 4.5 mm Progress | F57: =F10 -> 6 mm Progress | G57: =G10 -> 8 mm Progress | H57: =H10 -> 8 mm Reproductor | I57: =I10 -> 0 | ... K57: =K10 -> 0 | L57: Total | O57: =B10 -> Thalassa 0.9 -1.6 | P57: =C10 -> Thalassa 1.3 - 2.0 | Q57: =D10 -> 3 mm progress ex | R57: =E10 -> 4.5 mm Progress | S57: =F10 -> 6 mm Progress | T57: =G10 -> 8 mm Progress | U57: =H10 -> 8 mm Reproductor | V57: =I10 -> 0 | ... X57: =K10 -> 0 | Y57: Total
A58: SO1 | L58: =SUM(B58:K58) -> 0 | N58: SO1 | Y58: =SUM(O58:X58) -> 0
A59: SO2 | L59: =SUM(B59:K59) -> 0 | N59: SO2 | Y59: =SUM(O59:X59) -> 0
A60: SO3 | L60: =SUM(B60:K60) -> 0 | N60: SO3 | Y60: =SUM(O60:X60) -> 0
A61: SO4 | L61: =SUM(B61:K61) -> 0 | N61: SO4 | Y61: =SUM(O61:X61) -> 0
A62: SO5 | L62: =SUM(B62:K62) -> 0 | N62: SO5 | Y62: =SUM(O62:X62) -> 0
A63: SO6 | L63: =SUM(B63:K63) -> 0 | N63: SO6 | Y63: =SUM(O63:X63) -> 0
A64: SP1 | L64: =SUM(B64:K64) -> 0 | N64: SP1 | Y64: =SUM(O64:X64) -> 0
A65: SP2 | L65: =SUM(B65:K65) -> 0 | N65: SP2 | Y65: =SUM(O65:X65) -> 0
A66: SP3 | L66: =SUM(B66:K66) -> 0 | N66: SP3 | Y66: =SUM(O66:X66) -> 0
A67: SP4 | L67: =SUM(B67:K67) -> 0 | N67: SP4 | Y67: =SUM(O67:X67) -> 0
A68: SP5 | L68: =SUM(B68:K68) -> 0 | N68: SP5 | Y68: =SUM(O68:X68) -> 0
A69: SP6 | L69: =SUM(B69:K69) -> 0 | N69: SP6 | Y69: =SUM(O69:X69) -> 0
... A96: Jaula | L96: =SUM(B96:K96) -> 0 | N96: Jaula | Y96: =SUM(O96:X96) -> 0
A97: Total | B97: =SUM(B58:B96) -> 0 | C97: =SUM(C58:C96) -> 0 | D97: =SUM(D58:D96) -> 0 | E97: =SUM(E58:E96) -> 0 | F97: =SUM(F58:F96) -> 0 | G97: =SUM(G58:G96) -> 0 | H97: =SUM(H58:H96) -> 0 | I97: =SUM(I58:I96) -> 0 | ... L97: =SUM(L58:L96) -> 0 | N97: Total | O97: =SUM(O58:O96) -> 0 | P97: =SUM(P58:P96) -> 0 | Q97: =SUM(Q58:Q96) -> 0 | R97: =SUM(R58:R96) -> 0 | S97: =SUM(S58:S96) -> 0 | T97: =SUM(T58:T96) -> 0 | U97: =SUM(U58:U96) -> 0 | V97: =SUM(V58:V96) -> 0 | ... Y97: =SUM(Y58:Y96) -> 0

Sheet 06
A1: Registro | C1: PC 01.1 | F1: Programa de Crianza
A2: Versión: | C2: 2
A3: Fecha: | C3: 44701
A4: Elaborado Por: | C4: A - Vial
A5: Modificado por: | C5: R - Gatica | F5: Retiro de Alimentación Piscinas exteriores
A6: Aprobado Por | C6: A - Vial | R6: Mes: | S6: ='01'!T6 -> Abril | U6: Folio:
A7: Hojas: | C7: 1 de 3 | F7: Acuícola Alas S.A., Ruta 5 sur, Km 338, VII región, Parral
A9: Dia: | N9: Dia:
B10: Thalassa 0.9 -1.6 | C10: Thalassa 1.3 - 2.0 | D10: 3 mm progress ex | E10: 4.5 mm Progress | F10: 6 mm Progress | G10: 8 mm Progress | H10: 8 mm Reproductor | L10: Total | O10: =B10 -> Thalassa 0.9 -1.6 | P10: =C10 -> Thalassa 1.3 - 2.0 | Q10: =D10 -> 3 mm progress ex | R10: =E10 -> 4.5 mm Progress | S10: =F10 -> 6 mm Progress | T10: =G10 -> 8 mm Progress | U10: =H10 -> 8 mm Reproductor | V10: =I10 -> 0 | ... X10: =K10 -> 0 | Y10: Total
A11: SO1 | L11: =SUM(B11:K11) -> 0 | N11: SO1 | Y11: =SUM(O11:X11) -> 0
A12: SO2 | L12: =SUM(B12:K12) -> 0 | N12: SO2 | Y12: =SUM(O12:X12) -> 0
A13: SO3 | L13: =SUM(B13:K13) -> 0 | N13: SO3 | Y13: =SUM(O13:X13) -> 0
A14: SO4 | L14: =SUM(B14:K14) -> 0 | N14: SO4 | Y14: =SUM(O14:X14) -> 0
A15: SO5 | L15: =SUM(B15:K15) -> 0 | N15: SO5 | Y15: =SUM(O15:X15) -> 0
A16: SO6 | L16: =SUM(B16:K16) -> 0 | N16: SO6 | Y16: =SUM(O16:X16) -> 0
A17: SP1 | L17: =SUM(B17:K17) -> 0 | N17: SP1 | Y17: =SUM(O17:X17) -> 0
A18: SP2 | L18: =SUM(B18:K18) -> 0 | N18: SP2 | Y18: =SUM(O18:X18) -> 0
A19: SP3 | L19: =SUM(B19:K19) -> 0 | N19: SP3 | Y19: =SUM(O19:X19) -> 0
A20: SP4 | L20: =SUM(B20:K20) -> 0 | N20: SP4 | Y20: =SUM(O20:X20) -> 0
A21: SP5 | L21: =SUM(B21:K21) -> 0 | N21: SP5 | Y21: =SUM(O21:X21) -> 0
A22: SP6 | L22: =SUM(B22:K22) -> 0 | N22: SP6 | Y22: =SUM(O22:X22) -> 0
... A49: Jaula | L49: =SUM(B49:K49) -> 0 | N49: Jaula | Y49: =SUM(O49:X49) -> 0
A50: Total | B50: =SUM(B11:B49) -> 0 | C50: =SUM(C11:C49) -> 0 | D50: =SUM(D11:D49) -> 0 | E50: =SUM(E11:E49) -> 0 | F50: =SUM(F11:F49) -> 0 | G50: =SUM(G11:G49) -> 0 | H50: =SUM(H11:H49) -> 0 | I50: =SUM(I11:I49) -> 0 | ... L50: =SUM(L11:L49) -> 0 | N50: Total | O50: =SUM(O11:O49) -> 0 | P50: =SUM(P11:P49) -> 0 | Q50: =SUM(Q11:Q49) -> 0 | R50: =SUM(R11:R49) -> 0 | S50: =SUM(S11:S49) -> 0 | T50: =SUM(T11:T49) -> 0 | U50: =SUM(U11:U49) -> 0 | V50: =SUM(V11:V49) -> 0 | ... Y50: =SUM(Y11:Y49) -> 0
A56: Dia: | N56: Dia:
B57: =B10 -> Thalassa 0.9 -1.6 | C57: =C10 -> Thalassa 1.3 - 2.0 | D57: =D10 -> 3 mm progress ex | E57: =E10 -> 4.5 mm Progress | F57: =F10 -> 6 mm Progress | G57: =G10 -> 8 mm Progress | H57: =H10 -> 8 mm Reproductor | I57: =I10 -> 0 | ... K57: =K10 -> 0 | L57: Total | O57: =B10 -> Thalassa 0.9 -1.6 | P57: =C10 -> Thalassa 1.3 - 2.0 | Q57: =D10 -> 3 mm progress ex | R57: =E10 -> 4.5 mm Progress | S57: =F10 -> 6 mm Progress | T57: =G10 -> 8 mm Progress | U57: =H10 -> 8 mm Reproductor | V57: =I10 -> 0 | ... X57: =K10 -> 0 | Y57: Total
A58: SO1 | L58: =SUM(B58:K58) -> 0 | N58: SO1 | Y58: =SUM(O58:X58) -> 0
A59: SO2 | L59: =SUM(B59:K59) -> 0 | N59: SO2 | Y59: =SUM(O59:X59) -> 0
A60: SO3 | L60: =SUM(B60:K60) -> 0 | N60: SO3 | Y60: =SUM(O60:X60) -> 0
A61: SO4 | L61: =SUM(B61:K61) -> 0 | N61: SO4 | Y61: =SUM(O61:X61) -> 0
A62: SO5 | L62: =SUM(B62:K62) -> 0 | N62: SO5 | Y62: =SUM(O62:X62) -> 0
A63: SO6 | L63: =SUM(B63:K63) -> 0 | N63: SO6 | Y63: =SUM(O63:X63) -> 0
A64: SP1 | L64: =SUM(B64:K64) -> 0 | N64: SP1 | Y64: =SUM(O64:X64) -> 0
A65: SP2 | L65: =SUM(B65:K65) -> 0 | N65: SP2 | Y65: =SUM(O65:X65) -> 0
A66: SP3 | L66: =SUM(B66:K66) -> 0 | N66: SP3 | Y66: =SUM(O66:X66) -> 0
A67: SP4 | L67: =SUM(B67:K67) -> 0 | N67: SP4 | Y67: =SUM(O67:X67) -> 0
A68: SP5 | L68: =SUM(B68:K68) -> 0 | N68: SP5 | Y68: =SUM(O68:X68) -> 0
A69: SP6 | L69: =SUM(B69:K69) -> 0 | N69: SP6 | Y69: =SUM(O69:X69) -> 0
... A96: Jaula | L96: =SUM(B96:K96) -> 0 | N96: Jaula | Y96: =SUM(O96:X96) -> 0
A97: Total | B97: =SUM(B58:B96) -> 0 | C97: =SUM(C58:C96) -> 0 | D97: =SUM(D58:D96) -> 0 | E97: =SUM(E58:E96) -> 0 | F97: =SUM(F58:F96) -> 0 | G97: =SUM(G58:G96) -> 0 | H97: =SUM(H58:H96) -> 0 | I97: =SUM(I58:I96) -> 0 | ... L97: =SUM(L58:L96) -> 0 | N97: Total | O97: =SUM(O58:O96) -> 0 | P97: =SUM(P58:P96) -> 0 | Q97: =SUM(Q58:Q96) -> 0 | R97: =SUM(R58:R96) -> 0 | S97: =SUM(S58:S96) -> 0 | T97: =SUM(T58:T96) -> 0 | U97: =SUM(U58:U96) -> 0 | V97: =SUM(V58:V96) -> 0 | ... Y97: =SUM(Y58:Y96) -> 0

Sheet 07
A1: Registro | C1: PC 01.1 | F1: Programa de Crianza
A2: Versión: | C2: 2
A3: Fecha: | C3: 44701
A4: Elaborado Por: | C4: A - Vial
A5: Modificado por: | C5: R - Gatica | F5: Retiro de Alimentación Piscinas exteriores
A6: Aprobado Por | C6: A - Vial | R6: Mes: | S6: ='01'!T6 -> Abril | U6: Folio:
A7: Hojas: | C7: 1 de 3 | F7: Acuícola Alas S.A., Ruta 5 sur, Km 338, VII región, Parral
A9: Dia: | N9: Dia:
B10: Thalassa 0.9 -1.6 | C10: Thalassa 1.3 - 2.0 | D10: 3 mm progress ex | E10: 4.5 mm Progress | F10: 6 mm Progress | G10: 8 mm Progress | H10: 8 mm Reproductor | L10: Total | O10: =B10 -> Thalassa 0.9 -1.6 | P10: =C10 -> Thalassa 1.3 - 2.0 | Q10: =D10 -> 3 mm progress ex | R10: =E10 -> 4.5 mm Progress | S10: =F10 -> 6 mm Progress | T10: =G10 -> 8 mm Progress | U10: =H10 -> 8 mm Reproductor | V10: =I10 -> 0 | ... X10: =K10 -> 0 | Y10: Total
A11: SO1 | L11: =SUM(B11:K11) -> 0 | N11: SO1 | Y11: =SUM(O11:X11) -> 0
A12: SO2 | L12: =SUM(B12:K12) -> 0 | N12: SO2 | Y12: =SUM(O12:X12) -> 0
A13: SO3 | L13: =SUM(B13:K13) -> 0 | N13: SO3 | Y13: =SUM(O13:X13) -> 0
A14: SO4 | L14: =SUM(B14:K14) -> 0 | N14: SO4 | Y14: =SUM(O14:X14) -> 0
A15: SO5 | L15: =SUM(B15:K15) -> 0 | N15: SO5 | Y15: =SUM(O15:X15) -> 0
A16: SO6 | L16: =SUM(B16:K16) -> 0 | N16: SO6 | Y16: =SUM(O16:X16) -> 0
A17: SP1 | L17: =SUM(B17:K17) -> 0 | N17: SP1 | Y17: =SUM(O17:X17) -> 0
A18: SP2 | L18: =SUM(B18:K18) -> 0 | N18: SP2 | Y18: =SUM(O18:X18) -> 0
A19: SP3 | L19: =SUM(B19:K19) -> 0 | N19: SP3 | Y19: =SUM(O19:X19) -> 0
A20: SP4 | L20: =SUM(B20:K20) -> 0 | N20: SP4 | Y20: =SUM(O20:X20) -> 0
A21: SP5 | L21: =SUM(B21:K21) -> 0 | N21: SP5 | Y21: =SUM(O21:X21) -> 0
A22: SP6 | L22: =SUM(B22:K22) -> 0 | N22: SP6 | Y22: =SUM(O22:X22) -> 0
... A49: Jaula | L49: =SUM(B49:K49) -> 0 | N49: Jaula | Y49: =SUM(O49:X49) -> 0
A50: Total | B50: =SUM(B11:B49) -> 0 | C50: =SUM(C11:C49) -> 0 | D50: =SUM(D11:D49) -> 0 | E50: =SUM(E11:E49) -> 0 | F50: =SUM(F11:F49) -> 0 | G50: =SUM(G11:G49) -> 0 | H50: =SUM(H11:H49) -> 0 | I50: =SUM(I11:I49) -> 0 | ... L50: =SUM(L11:L49) -> 0 | N50: Total | O50: =SUM(O11:O49) -> 0 | P50: =SUM(P11:P49) -> 0 | Q50: =SUM(Q11:Q49) -> 0 | R50: =SUM(R11:R49) -> 0 | S50: =SUM(S11:S49) -> 0 | T50: =SUM(T11:T49) -> 0 | U50: =SUM(U11:U49) -> 0 | V50: =SUM(V11:V49) -> 0 | ... Y50: =SUM(Y11:Y49) -> 0
A56: Dia: | N56: Dia:
B57: =B10 -> Thalassa 0.9 -1.6 | C57: =C10 -> Thalassa 1.3 - 2.0 | D57: =D10 -> 3 mm progress ex | E57: =E10 -> 4.5 mm Progress | F57: =F10 -> 6 mm Progress | G57: =G10 -> 8 mm Progress | H57: =H10 -> 8 mm Reproductor | I57: =I10 -> 0 | ... K57: =K10 -> 0 | L57: Total | O57: =B10 -> Thalassa 0.9 -1.6 | P57: =C10 -> Thalassa 1.3 - 2.0 | Q57: =D10 -> 3 mm progress ex | R57: =E10 -> 4.5 mm Progress | S57: =F10 -> 6 mm Progress | T57: =G10 -> 8 mm Progress | U57: =H10 -> 8 mm Reproductor | V57: =I10 -> 0 | ... X57: =K10 -> 0 | Y57: Total
A58: SO1 | L58: =SUM(B58:K58) -> 0 | N58: SO1 | Y58: =SUM(O58:X58) -> 0
A59: SO2 | L59: =SUM(B59:K59) -> 0 | N59: SO2 | Y59: =SUM(O59:X59) -> 0
A60: SO3 | L60: =SUM(B60:K60) -> 0 | N60: SO3 | Y60: =SUM(O60:X60) -> 0
A61: SO4 | L61: =SUM(B61:K61) -> 0 | N61: SO4 | Y61: =SUM(O61:X61) -> 0
A62: SO5 | L62: =SUM(B62:K62) -> 0 | N62: SO5 | Y62: =SUM(O62:X62) -> 0
A63: SO6 | L63: =SUM(B63:K63) -> 0 | N63: SO6 | Y63: =SUM(O63:X63) -> 0
A64: SP1 | L64: =SUM(B64:K64) -> 0 | N64: SP1 | Y64: =SUM(O64:X64) -> 0
A65: SP2 | L65: =SUM(B65:K65) -> 0 | N65: SP2 | Y65: =SUM(O65:X65) -> 0
A66: SP3 | L66: =SUM(B66:K66) -> 0 | N66: SP3 | Y66: =SUM(O66:X66) -> 0
A67: SP4 | L67: =SUM(B67:K67) -> 0 | N67: SP4 | Y67: =SUM(O67:X67) -> 0
A68: SP5 | L68: =SUM(B68:K68) -> 0 | N68: SP5 | Y68: =SUM(O68:X68) -> 0
A69: SP6 | L69: =SUM(B69:K69) -> 0 | N69: SP6 | Y69: =SUM(O69:X69) -> 0
... A96: Jaula | L96: =SUM(B96:K96) -> 0 | N96: Jaula | Y96: =SUM(O96:X96) -> 0
A97: Total | B97: =SUM(B58:B96) -> 0 | C97: =SUM(C58:C96) -> 0 | D97: =SUM(D58:D96) -> 0 | E97: =SUM(E58:E96) -> 0 | F97: =SUM(F58:F96) -> 0 | G97: =SUM(G58:G96) -> 0 | H97: =SUM(H58:H96) -> 0 | I97: =SUM(I58:I96) -> 0 | ... L97: =SUM(L58:L96) -> 0 | N97: Total | O97: =SUM(O58:O96) -> 0 | P97: =SUM(P58:P96) -> 0 | Q97: =SUM(Q58:Q96) -> 0 | R97: =SUM(R58:R96) -> 0 | S97: =SUM(S58:S96) -> 0 | T97: =SUM(T58:T96) -> 0 | U97: =SUM(U58:U96) -> 0 | V97: =SUM(V58:V96) -> 0 | ... Y97: =SUM(Y58:Y96) -> 0

Sheet 08
A1: Registro | C1: PC 01.1 | F1: Programa de Crianza
A2: Versión: | C2: 2
A3: Fecha: | C3: 44701
A4: Elaborado Por: | C4: A - Vial
A5: Modificado por: | C5: R - Gatica | F5: Retiro de Alimentación Piscinas exteriores
A6: Aprobado Por | C6: A - Vial | R6: Mes: | S6: ='01'!T6 -> Abril | U6: Folio:
A7: Hojas: | C7: 1 de 3 | F7: Acuícola Alas S.A., Ruta 5 sur, Km 338, VII región, Parral
A9: Dia: | N9: Dia:
B10: Thalassa 0.9 -1.6 | C10: Thalassa 1.3 - 2.0 | D10: 3 mm progress ex | E10: 4.5 mm Progress | F10: 6 mm Progress | G10: 8 mm Progress | H10: 8 mm Reproductor | L10: Total | O10: =B10 -> Thalassa 0.9 -1.6 | P10: =C10 -> Thalassa 1.3 - 2.0 | Q10: =D10 -> 3 mm progress ex | R10: =E10 -> 4.5 mm Progress | S10: =F10 -> 6 mm Progress | T10: =G10 -> 8 mm Progress | U10: =H10 -> 8 mm Reproductor | V10: =I10 -> 0 | ... X10: =K10 -> 0 | Y10: Total
A11: SO1 | L11: =SUM(B11:K11) -> 0 | N11: SO1 | Y11: =SUM(O11:X11) -> 0
A12: SO2 | L12: =SUM(B12:K12) -> 0 | N12: SO2 | Y12: =SUM(O12:X12) -> 0
A13: SO3 | L13: =SUM(B13:K13) -> 0 | N13: SO3 | Y13: =SUM(O13:X13) -> 0
A14: SO4 | L14: =SUM(B14:K14) -> 0 | N14: SO4 | Y14: =SUM(O14:X14) -> 0
A15: SO5 | L15: =SUM(B15:K15) -> 0 | N15: SO5 | Y15: =SUM(O15:X15) -> 0
A16: SO6 | L16: =SUM(B16:K16) -> 0 | N16: SO6 | Y16: =SUM(O16:X16) -> 0
A17: SP1 | L17: =SUM(B17:K17) -> 0 | N17: SP1 | Y17: =SUM(O17:X17) -> 0
A18: SP2 | L18: =SUM(B18:K18) -> 0 | N18: SP2 | Y18: =SUM(O18:X18) -> 0
A19: SP3 | L19: =SUM(B19:K19) -> 0 | N19: SP3 | Y19: =SUM(O19:X19) -> 0
A20: SP4 | L20: =SUM(B20:K20) -> 0 | N20: SP4 | Y20: =SUM(O20:X20) -> 0
A21: SP5 | L21: =SUM(B21:K21) -> 0 | N21: SP5 | Y21: =SUM(O21:X21) -> 0
A22: SP6 | L22: =SUM(B22:K22) -> 0 | N22: SP6 | Y22: =SUM(O22:X22) -> 0
... A49: Jaula | L49: =SUM(B49:K49) -> 0 | N49: Jaula | Y49: =SUM(O49:X49) -> 0
A50: Total | B50: =SUM(B11:B49) -> 0 | C50: =SUM(C11:C49) -> 0 | D50: =SUM(D11:D49) -> 0 | E50: =SUM(E11:E49) -> 0 | F50: =SUM(F11:F49) -> 0 | G50: =SUM(G11:G49) -> 0 | H50: =SUM(H11:H49) -> 0 | I50: =SUM(I11:I49) -> 0 | ... L50: =SUM(L11:L49) -> 0 | N50: Total | O50: =SUM(O11:O49) -> 0 | P50: =SUM(P11:P49) -> 0 | Q50: =SUM(Q11:Q49) -> 0 | R50: =SUM(R11:R49) -> 0 | S50: =SUM(S11:S49) -> 0 | T50: =SUM(T11:T49) -> 0 | U50: =SUM(U11:U49) -> 0 | V50: =SUM(V11:V49) -> 0 | ... Y50: =SUM(Y11:Y49) -> 0
A56: Dia: | N56: Dia:
B57: =B10 -> Thalassa 0.9 -1.6 | C57: =C10 -> Thalassa 1.3 - 2.0 | D57: =D10 -> 3 mm progress ex | E57: =E10 -> 4.5 mm Progress | F57: =F10 -> 6 mm Progress | G57: =G10 -> 8 mm Progress | H57: =H10 -> 8 mm Reproductor | I57: =I10 -> 0 | ... K57: =K10 -> 0 | L57: Total | O57: =B10 -> Thalassa 0.9 -1.6 | P57: =C10 -> Thalassa 1.3 - 2.0 | Q57: =D10 -> 3 mm progress ex | R57: =E10 -> 4.5 mm Progress | S57: =F10 -> 6 mm Progress | T57: =G10 -> 8 mm Progress | U57: =H10 -> 8 mm Reproductor | V57: =I10 -> 0 | ... X57: =K10 -> 0 | Y57: Total
A58: SO1 | L58: =SUM(B58:K58) -> 0 | N58: SO1 | Y58: =SUM(O58:X58) -> 0
A59: SO2 | L59: =SUM(B59:K59) -> 0 | N59: SO2 | Y59: =SUM(O59:X59) -> 0
A60: SO3 | L60: =SUM(B60:K60) -> 0 | N60: SO3 | Y60: =SUM(O60:X60) -> 0
A61: SO4 | L61: =SUM(B61:K61) -> 0 | N61: SO4 | Y61: =SUM(O61:X61) -> 0
A62: SO5 | L62: =SUM(B62:K62) -> 0 | N62: SO5 | Y62: =SUM(O62:X62) -> 0
A63: SO6 | L63: =SUM(B63:K63) -> 0 | N63: SO6 | Y63: =SUM(O63:X63) -> 0
A64: SP1 | L64: =SUM(B64:K64) -> 0 | N64: SP1 | Y64: =SUM(O64:X64) -> 0
A65: SP2 | L65: =SUM(B65:K65) -> 0 | N65: SP2 | Y65: =SUM(O65:X65) -> 0
A66: SP3 | L66: =SUM(B66:K66) -> 0 | N66: SP3 | Y66: =SUM(O66:X66) -> 0
A67: SP4 | L67: =SUM(B67:K67) -> 0 | N67: SP4 | Y67: =SUM(O67:X67) -> 0
A68: SP5 | L68: =SUM(B68:K68) -> 0 | N68: SP5 | Y68: =SUM(O68:X68) -> 0
A69: SP6 | L69: =SUM(B69:K69) -> 0 | N69: SP6 | Y69: =SUM(O69:X69) -> 0
... A96: Jaula | L96: =SUM(B96:K96) -> 0 | N96: Jaula | Y96: =SUM(O96:X96) -> 0
A97: Total | B97: =SUM(B58:B96) -> 0 | C97: =SUM(C58:C96) -> 0 | D97: =SUM(D58:D96) -> 0 | E97: =SUM(E58:E96) -> 0 | F97: =SUM(F58:F96) -> 0 | G97: =SUM(G58:G96) -> 0 | H97: =SUM(H58:H96) -> 0 | I97: =SUM(I58:I96) -> 0 | ... L97: =SUM(L58:L96) -> 0 | N97: Total | O97: =SUM(O58:O96) -> 0 | P97: =SUM(P58:P96) -> 0 | Q97: =SUM(Q58:Q96) -> 0 | R97: =SUM(R58:R96) -> 0 | S97: =SUM(S58:S96) -> 0 | T97: =SUM(T58:T96) -> 0 | U97: =SUM(U58:U96) -> 0 | V97: =SUM(V58:V96) -> 0 | ... Y97: =SUM(Y58:Y96) -> 0

Sheet 09
A1: Registro | C1: PC 01.1 | F1: Programa de Crianza
A2: Versión: | C2: 2
A3: Fecha: | C3: 44701
A4: Elaborado Por: | C4: A - Vial
A5: Modificado por: | C5: R - Gatica | F5: Retiro de Alimentación Piscinas exteriores
A6: Aprobado Por | C6: A - Vial | R6: Mes: | S6: ='01'!T6 -> Abril | U6: Folio:
A7: Hojas: | C7: 1 de 3 | F7: Acuícola Alas S.A., Ruta 5 sur, Km 338, VII región, Parral
A9: Dia: | N9: Dia:
B10: Thalassa 0.9 -1.6 | C10: Thalassa 1.3 - 2.0 | D10: 3 mm progress ex | E10: 4.5 mm Progress | F10: 6 mm Progress | G10: 8 mm Progress | H10: 8 mm Reproductor | L10: Total | O10: =B10 -> Thalassa 0.9 -1.6 | P10: =C10 -> Thalassa 1.3 - 2.0 | Q10: =D10 -> 3 mm progress ex | R10: =E10 -> 4.5 mm Progress | S10: =F10 -> 6 mm Progress | T10: =G10 -> 8 mm Progress | U10: =H10 -> 8 mm Reproductor | V10: =I10 -> 0 | ... X10: =K10 -> 0 | Y10: Total
A11: SO1 | L11: =SUM(B11:K11) -> 0 | N11: SO1 | Y11: =SUM(O11:X11) -> 0
A12: SO2 | L12: =SUM(B12:K12) -> 0 | N12: SO2 | Y12: =SUM(O12:X12) -> 0
A13: SO3 | L13: =SUM(B13:K13) -> 0 | N13: SO3 | Y13: =SUM(O13:X13) -> 0
A14: SO4 | L14: =SUM(B14:K14) -> 0 | N14: SO4 | Y14: =SUM(O14:X14) -> 0
A15: SO5 | L15: =SUM(B15:K15) -> 0 | N15: SO5 | Y15: =SUM(O15:X15) -> 0
A16: SO6 | L16: =SUM(B16:K16) -> 0 | N16: SO6 | Y16: =SUM(O16:X16) -> 0
A17: SP1 | L17: =SUM(B17:K17) -> 0 | N17: SP1 | Y17: =SUM(O17:X17) -> 0
A18: SP2 | L18: =SUM(B18:K18) -> 0 | N18: SP2 | Y18: =SUM(O18:X18) -> 0
A19: SP3 | L19: =SUM(B19:K19) -> 0 | N19: SP3 | Y19: =SUM(O19:X19) -> 0
A20: SP4 | L20: =SUM(B20:K20) -> 0 | N20: SP4 | Y20: =SUM(O20:X20) -> 0
A21: SP5 | L21: =SUM(B21:K21) -> 0 | N21: SP5 | Y21: =SUM(O21:X21) -> 0
A22: SP6 | L22: =SUM(B22:K22) -> 0 | N22: SP6 | Y22: =SUM(O22:X22) -> 0
... A49: Jaula | L49: =SUM(B49:K49) -> 0 | N49: Jaula | Y49: =SUM(O49:X49) -> 0
A50: Total | B50: =SUM(B11:B49) -> 0 | C50: =SUM(C11:C49) -> 0 | D50: =SUM(D11:D49) -> 0 | E50: =SUM(E11:E49) -> 0 | F50: =SUM(F11:F49) -> 0 | G50: =SUM(G11:G49) -> 0 | H50: =SUM(H11:H49) -> 0 | I50: =SUM(I11:I49) -> 0 | ... L50: =SUM(L11:L49) -> 0 | N50: Total | O50: =SUM(O11:O49) -> 0 | P50: =SUM(P11:P49) -> 0 | Q50: =SUM(Q11:Q49) -> 0 | R50: =SUM(R11:R49) -> 0 | S50: =SUM(S11:S49) -> 0 | T50: =SUM(T11:T49) -> 0 | U50: =SUM(U11:U49) -> 0 | V50: =SUM(V11:V49) -> 0 | ... Y50: =SUM(Y11:Y49) -> 0
A56: Dia: | N56: Dia:
B57: =B10 -> Thalassa 0.9 -1.6 | C57: =C10 -> Thalassa 1.3 - 2.0 | D57: =D10 -> 3 mm progress ex | E57: =E10 -> 4.5 mm Progress | F57: =F10 -> 6 mm Progress | G57: =G10 -> 8 mm Progress | H57: =H10 -> 8 mm Reproductor | I57: =I10 -> 0 | ... K57: =K10 -> 0 | L57: Total | O57: =B10 -> Thalassa 0.9 -1.6 | P57: =C10 -> Thalassa 1.3 - 2.0 | Q57: =D10 -> 3 mm progress ex | R57: =E10 -> 4.5 mm Progress | S57: =F10 -> 6 mm Progress | T57: =G10 -> 8 mm Progress | U57: =H10 -> 8 mm Reproductor | V57: =I10 -> 0 | ... X57: =K10 -> 0 | Y57: Total
A58: SO1 | L58: =SUM(B58:K58) -> 0 | N58: SO1 | Y58: =SUM(O58:X58) -> 0
A59: SO2 | L59: =SUM(B59:K59) -> 0 | N59: SO2 | Y59: =SUM(O59:X59) -> 0
A60: SO3 | L60: =SUM(B60:K60) -> 0 | N60: SO3 | Y60: =SUM(O60:X60) -> 0
A61: SO4 | L61: =SUM(B61:K61) -> 0 | N61: SO4 | Y61: =SUM(O61:X61) -> 0
A62: SO5 | L62: =SUM(B62:K62) -> 0 | N62: SO5 | Y62: =SUM(O62:X62) -> 0
A63: SO6 | L63: =SUM(B63:K63) -> 0 | N63: SO6 | Y63: =SUM(O63:X63) -> 0
A64: SP1 | L64: =SUM(B64:K64) -> 0 | N64: SP1 | Y64: =SUM(O64:X64) -> 0
A65: SP2 | L65: =SUM(B65:K65) -> 0 | N65: SP2 | Y65: =SUM(O65:X65) -> 0
A66: SP3 | L66: =SUM(B66:K66) -> 0 | N66: SP3 | Y66: =SUM(O66:X66) -> 0
A67: SP4 | L67: =SUM(B67:K67) -> 0 | N67: SP4 | Y67: =SUM(O67:X67) -> 0
A68: SP5 | L68: =SUM(B68:K68) -> 0 | N68: SP5 | Y68: =SUM(O68:X68) -> 0
A69: SP6 | L69: =SUM(B69:K69) -> 0 | N69: SP6 | Y69: =SUM(O69:X69) -> 0
... A96: Jaula | L96: =SUM(B96:K96) -> 0 | N96: Jaula | Y96: =SUM(O96:X96) -> 0
A97: Total | B97: =SUM(B58:B96) -> 0 | C97: =SUM(C58:C96) -> 0 | D97: =SUM(D58:D96) -> 0 | E97: =SUM(E58:E96) -> 0 | F97: =SUM(F58:F96) -> 0 | G97: =SUM(G58:G96) -> 0 | H97: =SUM(H58:H96) -> 0 | I97: =SUM(I58:I96) -> 0 | ... L97: =SUM(L58:L96) -> 0 | N97: Total | O97: =SUM(O58:O96) -> 0 | P97: =SUM(P58:P96) -> 0 | Q97: =SUM(Q58:Q96) -> 0 | R97: =SUM(R58:R96) -> 0 | S97: =SUM(S58:S96) -> 0 | T97: =SUM(T58:T96) -> 0 | U97: =SUM(U58:U96) -> 0 | V97: =SUM(V58:V96) -> 0 | ... Y97: =SUM(Y58:Y96) -> 0

Sheet Total
C2: Thalassa 0.9 -1.6 | D2: Thalassa 1.3 - 2.0 | E2: 3 mm progress ex | F2: 4.5 mm Progress | G2: 6 mm Progress | H2: 8 mm Progress | I2: 8 mm Reproductor | J2: Ewos Micro PSZ LE 100 4.0 mm | K2: Ewos Micro PSZ LE 250 6.0 mm | L2: Ewos Breed 800 70A 9.5 mm
B3: SO1 | C3: =('01'!C11+'01'!P11+'01'!C58+'01'!P58)+('02'!C11+'02'!P11+'02'!C58+'02'!P58)+('03'!B11+'03'!O11+'03'!B58+'03'!O58)+('04'!B11+'04'!O11+'04'!B58+'04'!O58)+('05'!B11+'05'!O11+'05'!B58+'05'!O58)+('06'!B11+'06'!O11+'06'!B58+'06'!O58)+('07'!B11+'07'!O11+'07'!B58+'07'!O58)+('08'!B11+'08'!O11+'08'!B58+'08'!O58)+('09'!B11+'09'!O11+'09'!B58+'09'!O58) -> 0 | D3: =('01'!D11+'01'!Q11+'01'!D58+'01'!Q58)+('02'!D11+'02'!Q11+'02'!D58+'02'!Q58)+('03'!C11+'03'!P11+'03'!C58+'03'!P58)+('04'!C11+'04'!P11+'04'!C58+'04'!P58)+('05'!C11+'05'!P11+'05'!C58+'05'!P58)+('06'!C11+'06'!P11+'06'!C58+'06'!P58)+('07'!C11+'07'!P11+'07'!C58+'07'!P58)+('08'!C11+'08'!P11+'08'!C58+'08'!P58)+('09'!C11+'09'!P11+'09'!C58+'09'!P58) -> 0 | E3: =('01'!E11+'01'!R11+'01'!E58+'01'!R58)+('02'!E11+'02'!R11+'02'!E58+'02'!R58)+('03'!D11+'03'!Q11+'03'!D58+'03'!Q58)+('04'!D11+'04'!Q11+'04'!D58+'04'!Q58)+('05'!D11+'05'!Q11+'05'!D58+'05'!Q58)+('06'!D11+'06'!Q11+'06'!D58+'06'!Q58)+('07'!D11+'07'!Q11+'07'!D58+'07'!Q58)+('08'!D11+'08'!Q11+'08'!D58+'08'!Q58)+('09'!D11+'09'!Q11+'09'!D58+'09'!Q58) -> 12 | F3: =('01'!F11+'01'!S11+'01'!F58+'01'!S58)+('02'!F11+'02'!S11+'02'!F58+'02'!S58)+('03'!E11+'03'!R11+'03'!E58+'03'!R58)+('04'!E11+'04'!R11+'04'!E58+'04'!R58)+('05'!E11+'05'!R11+'05'!E58+'05'!R58)+('06'!E11+'06'!R11+'06'!E58+'06'!R58)+('07'!E11+'07'!R11+'07'!E58+'07'!R58)+('08'!E11+'08'!R11+'08'!E58+'08'!R58)+('09'!E11+'09'!R11+'09'!E58+'09'!R58) -> 0 | G3: =('01'!G11+'01'!T11+'01'!G58+'01'!T58)+('02'!G11+'02'!T11+'02'!G58+'02'!T58)+('03'!F11+'03'!S11+'03'!F58+'03'!S58)+('04'!F11+'04'!S11+'04'!F58+'04'!S58)+('05'!F11+'05'!S11+'05'!F58+'05'!S58)+('06'!F11+'06'!S11+'06'!F58+'06'!S58)+('07'!F11+'07'!S11+'07'!F58+'07'!S58)+('08'!F11+'08'!S11+'08'!F58+'08'!S58)+('09'!F11+'09'!S11+'09'!F58+'09'!S58) -> 0 | H3: =('01'!H11+'01'!U11+'01'!H58+'01'!U58)+('02'!H11+'02'!U11+'02'!H58+'02'!U58)+('03'!G11+'03'!T11+'03'!G58+'03'!T58)+('04'!G11+'04'!T11+'04'!G58+'04'!T58)+('05'!G11+'05'!T11+'05'!G58+'05'!T58)+('06'!G11+'06'!T11+'06'!G58+'06'!T58)+('07'!G11+'07'!T11+'07'!G58+'07'!T58)+('08'!G11+'08'!T11+'08'!G58+'08'!T58)+('09'!G11+'09'!T11+'09'!G58+'09'!T58) -> 0 | I3: =('01'!I11+'01'!V11+'01'!I58+'01'!V58)+('02'!I11+'02'!V11+'02'!I58+'02'!V58)+('03'!H11+'03'!U11+'03'!H58+'03'!U58)+('04'!H11+'04'!U11+'04'!H58+'04'!U58)+('05'!H11+'05'!U11+'05'!H58+'05'!U58)+('06'!H11+'06'!U11+'06'!H58+'06'!U58)+('07'!H11+'07'!U11+'07'!H58+'07'!U58)+('08'!H11+'08'!U11+'08'!H58+'08'!U58)+('09'!H11+'09'!U11+'09'!H58+'09'!U58) -> 0 | J3: =('01'!J11+'01'!W11+'01'!J58+'01'!W58)+('02'!J11+'02'!W11+'02'!J58+'02'!W58)+('03'!I11+'03'!V11+'03'!I58+'03'!V58)+('04'!I11+'04'!V11+'04'!I58+'04'!V58)+('05'!I11+'05'!V11+'05'!I58+'05'!V58)+('06'!I11+'06'!V11+'06'!I58+'06'!V58)+('07'!I11+'07'!V11+'07'!I58+'07'!V58)+('08'!I11+'08'!V11+'08'!I58+'08'!V58)+('09'!I11+'09'!V11+'09'!I58+'09'!V58) -> 0 | ... L3: =('01'!L11+'01'!Y11+'01'!L58+'01'!Y58)+('02'!L11+'02'!Y11+'02'!L58+'02'!Y58)+('03'!K11+'03'!X11+'03'!K58+'03'!X58)+('04'!K11+'04'!X11+'04'!K58+'04'!X58)+('05'!K11+'05'!X11+'05'!K58+'05'!X58)+('06'!K11+'06'!X11+'06'!K58+'06'!X58)+('07'!K11+'07'!X11+'07'!K58+'07'!X58)+('08'!K11+'08'!X11+'08'!K58+'08'!X58)+('09'!K11+'09'!X11+'09'!K58+'09'!X58) -> 0 | M3: =SUM(C3:L3) -> 12 | N3: =M3*25 -> 300
B4: SO2 | C4: =('01'!C12+'01'!P12+'01'!C59+'01'!P59)+('02'!C12+'02'!P12+'02'!C59+'02'!P59)+('03'!B12+'03'!O12+'03'!B59+'03'!O59)+('04'!B12+'04'!O12+'04'!B59+'04'!O59)+('05'!B12+'05'!O12+'05'!B59+'05'!O59)+('06'!B12+'06'!O12+'06'!B59+'06'!O59)+('07'!B12+'07'!O12+'07'!B59+'07'!O59)+('08'!B12+'08'!O12+'08'!B59+'08'!O59)+('09'!B12+'09'!O12+'09'!B59+'09'!O59) -> 0 | D4: =('01'!D12+'01'!Q12+'01'!D59+'01'!Q59)+('02'!D12+'02'!Q12+'02'!D59+'02'!Q59)+('03'!C12+'03'!P12+'03'!C59+'03'!P59)+('04'!C12+'04'!P12+'04'!C59+'04'!P59)+('05'!C12+'05'!P12+'05'!C59+'05'!P59)+('06'!C12+'06'!P12+'06'!C59+'06'!P59)+('07'!C12+'07'!P12+'07'!C59+'07'!P59)+('08'!C12+'08'!P12+'08'!C59+'08'!P59)+('09'!C12+'09'!P12+'09'!C59+'09'!P59) -> 0 | E4: =('01'!E12+'01'!R12+'01'!E59+'01'!R59)+('02'!E12+'02'!R12+'02'!E59+'02'!R59)+('03'!D12+'03'!Q12+'03'!D59+'03'!Q59)+('04'!D12+'04'!Q12+'04'!D59+'04'!Q59)+('05'!D12+'05'!Q12+'05'!D59+'05'!Q59)+('06'!D12+'06'!Q12+'06'!D59+'06'!Q59)+('07'!D12+'07'!Q12+'07'!D59+'07'!Q59)+('08'!D12+'08'!Q12+'08'!D59+'08'!Q59)+('09'!D12+'09'!Q12+'09'!D59+'09'!Q59) -> 0 | F4: =('01'!F12+'01'!S12+'01'!F59+'01'!S59)+('02'!F12+'02'!S12+'02'!F59+'02'!S59)+('03'!E12+'03'!R12+'03'!E59+'03'!R59)+('04'!E12+'04'!R12+'04'!E59+'04'!R59)+('05'!E12+'05'!R12+'05'!E59+'05'!R59)+('06'!E12+'06'!R12+'06'!E59+'06'!R59)+('07'!E12+'07'!R12+'07'!E59+'07'!R59)+('08'!E12+'08'!R12+'08'!E59+'08'!R59)+('09'!E12+'09'!R12+'09'!E59+'09'!R59) -> 0 | G4: =('01'!G12+'01'!T12+'01'!G59+'01'!T59)+('02'!G12+'02'!T12+'02'!G59+'02'!T59)+('03'!F12+'03'!S12+'03'!F59+'03'!S59)+('04'!F12+'04'!S12+'04'!F59+'04'!S59)+('05'!F12+'05'!S12+'05'!F59+'05'!S59)+('06'!F12+'06'!S12+'06'!F59+'06'!S59)+('07'!F12+'07'!S12+'07'!F59+'07'!S59)+('08'!F12+'08'!S12+'08'!F59+'08'!S59)+('09'!F12+'09'!S12+'09'!F59+'09'!S59) -> 12 | H4: =('01'!H12+'01'!U12+'01'!H59+'01'!U59)+('02'!H12+'02'!U12+'02'!H59+'02'!U59)+('03'!G12+'03'!T12+'03'!G59+'03'!T59)+('04'!G12+'04'!T12+'04'!G59+'04'!T59)+('05'!G12+'05'!T12+'05'!G59+'05'!T59)+('06'!G12+'06'!T12+'06'!G59+'06'!T59)+('07'!G12+'07'!T12+'07'!G59+'07'!T59)+('08'!G12+'08'!T12+'08'!G59+'08'!T59)+('09'!G12+'09'!T12+'09'!G59+'09'!T59) -> 0 | I4: =('01'!I12+'01'!V12+'01'!I59+'01'!V59)+('02'!I12+'02'!V12+'02'!I59+'02'!V59)+('03'!H12+'03'!U12+'03'!H59+'03'!U59)+('04'!H12+'04'!U12+'04'!H59+'04'!U59)+('05'!H12+'05'!U12+'05'!H59+'05'!U59)+('06'!H12+'06'!U12+'06'!H59+'06'!U59)+('07'!H12+'07'!U12+'07'!H59+'07'!U59)+('08'!H12+'08'!U12+'08'!H59+'08'!U59)+('09'!H12+'09'!U12+'09'!H59+'09'!U59) -> 9 | J4: =('01'!J12+'01'!W12+'01'!J59+'01'!W59)+('02'!J12+'02'!W12+'02'!J59+'02'!W59)+('03'!I12+'03'!V12+'03'!I59+'03'!V59)+('04'!I12+'04'!V12+'04'!I59+'04'!V59)+('05'!I12+'05'!V12+'05'!I59+'05'!V59)+('06'!I12+'06'!V12+'06'!I59+'06'!V59)+('07'!I12+'07'!V12+'07'!I59+'07'!V59)+('08'!I12+'08'!V12+'08'!I59+'08'!V59)+('09'!I12+'09'!V12+'09'!I59+'09'!V59) -> 0 | ... L4: =('01'!L12+'01'!Y12+'01'!L59+'01'!Y59)+('02'!L12+'02'!Y12+'02'!L59+'02'!Y59)+('03'!K12+'03'!X12+'03'!K59+'03'!X59)+('04'!K12+'04'!X12+'04'!K59+'04'!X59)+('05'!K12+'05'!X12+'05'!K59+'05'!X59)+('06'!K12+'06'!X12+'06'!K59+'06'!X59)+('07'!K12+'07'!X12+'07'!K59+'07'!X59)+('08'!K12+'08'!X12+'08'!K59+'08'!X59)+('09'!K12+'09'!X12+'09'!K59+'09'!X59) -> 0 | M4: =SUM(C4:L4) -> 21 | N4: =M4*25 -> 525
B5: SO3 | C5: =('01'!C13+'01'!P13+'01'!C60+'01'!P60)+('02'!C13+'02'!P13+'02'!C60+'02'!P60)+('03'!B13+'03'!O13+'03'!B60+'03'!O60)+('04'!B13+'04'!O13+'04'!B60+'04'!O60)+('05'!B13+'05'!O13+'05'!B60+'05'!O60)+('06'!B13+'06'!O13+'06'!B60+'06'!O60)+('07'!B13+'07'!O13+'07'!B60+'07'!O60)+('08'!B13+'08'!O13+'08'!B60+'08'!O60)+('09'!B13+'09'!O13+'09'!B60+'09'!O60) -> 0 | D5: =('01'!D13+'01'!Q13+'01'!D60+'01'!Q60)+('02'!D13+'02'!Q13+'02'!D60+'02'!Q60)+('03'!C13+'03'!P13+'03'!C60+'03'!P60)+('04'!C13+'04'!P13+'04'!C60+'04'!P60)+('05'!C13+'05'!P13+'05'!C60+'05'!P60)+('06'!C13+'06'!P13+'06'!C60+'06'!P60)+('07'!C13+'07'!P13+'07'!C60+'07'!P60)+('08'!C13+'08'!P13+'08'!C60+'08'!P60)+('09'!C13+'09'!P13+'09'!C60+'09'!P60) -> 0 | E5: =('01'!E13+'01'!R13+'01'!E60+'01'!R60)+('02'!E13+'02'!R13+'02'!E60+'02'!R60)+('03'!D13+'03'!Q13+'03'!D60+'03'!Q60)+('04'!D13+'04'!Q13+'04'!D60+'04'!Q60)+('05'!D13+'05'!Q13+'05'!D60+'05'!Q60)+('06'!D13+'06'!Q13+'06'!D60+'06'!Q60)+('07'!D13+'07'!Q13+'07'!D60+'07'!Q60)+('08'!D13+'08'!Q13+'08'!D60+'08'!Q60)+('09'!D13+'09'!Q13+'09'!D60+'09'!Q60) -> 0 | F5: =('01'!F13+'01'!S13+'01'!F60+'01'!S60)+('02'!F13+'02'!S13+'02'!F60+'02'!S60)+('03'!E13+'03'!R13+'03'!E60+'03'!R60)+('04'!E13+'04'!R13+'04'!E60+'04'!R60)+('05'!E13+'05'!R13+'05'!E60+'05'!R60)+('06'!E13+'06'!R13+'06'!E60+'06'!R60)+('07'!E13+'07'!R13+'07'!E60+'07'!R60)+('08'!E13+'08'!R13+'08'!E60+'08'!R60)+('09'!E13+'09'!R13+'09'!E60+'09'!R60) -> 0 | G5: =('01'!G13+'01'!T13+'01'!G60+'01'!T60)+('02'!G13+'02'!T13+'02'!G60+'02'!T60)+('03'!F13+'03'!S13+'03'!F60+'03'!S60)+('04'!F13+'04'!S13+'04'!F60+'04'!S60)+('05'!F13+'05'!S13+'05'!F60+'05'!S60)+('06'!F13+'06'!S13+'06'!F60+'06'!S60)+('07'!F13+'07'!S13+'07'!F60+'07'!S60)+('08'!F13+'08'!S13+'08'!F60+'08'!S60)+('09'!F13+'09'!S13+'09'!F60+'09'!S60) -> 6 | H5: =('01'!H13+'01'!U13+'01'!H60+'01'!U60)+('02'!H13+'02'!U13+'02'!H60+'02'!U60)+('03'!G13+'03'!T13+'03'!G60+'03'!T60)+('04'!G13+'04'!T13+'04'!G60+'04'!T60)+('05'!G13+'05'!T13+'05'!G60+'05'!T60)+('06'!G13+'06'!T13+'06'!G60+'06'!T60)+('07'!G13+'07'!T13+'07'!G60+'07'!T60)+('08'!G13+'08'!T13+'08'!G60+'08'!T60)+('09'!G13+'09'!T13+'09'!G60+'09'!T60) -> 4 | I5: =('01'!I13+'01'!V13+'01'!I60+'01'!V60)+('02'!I13+'02'!V13+'02'!I60+'02'!V60)+('03'!H13+'03'!U13+'03'!H60+'03'!U60)+('04'!H13+'04'!U13+'04'!H60+'04'!U60)+('05'!H13+'05'!U13+'05'!H60+'05'!U60)+('06'!H13+'06'!U13+'06'!H60+'06'!U60)+('07'!H13+'07'!U13+'07'!H60+'07'!U60)+('08'!H13+'08'!U13+'08'!H60+'08'!U60)+('09'!H13+'09'!U13+'09'!H60+'09'!U60) -> 5 | J5: =('01'!J13+'01'!W13+'01'!J60+'01'!W60)+('02'!J13+'02'!W13+'02'!J60+'02'!W60)+('03'!I13+'03'!V13+'03'!I60+'03'!V60)+('04'!I13+'04'!V13+'04'!I60+'04'!V60)+('05'!I13+'05'!V13+'05'!I60+'05'!V60)+('06'!I13+'06'!V13+'06'!I60+'06'!V60)+('07'!I13+'07'!V13+'07'!I60+'07'!V60)+('08'!I13+'08'!V13+'08'!I60+'08'!V60)+('09'!I13+'09'!V13+'09'!I60+'09'!V60) -> 0 | ... L5: =('01'!L13+'01'!Y13+'01'!L60+'01'!Y60)+('02'!L13+'02'!Y13+'02'!L60+'02'!Y60)+('03'!K13+'03'!X13+'03'!K60+'03'!X60)+('04'!K13+'04'!X13+'04'!K60+'04'!X60)+('05'!K13+'05'!X13+'05'!K60+'05'!X60)+('06'!K13+'06'!X13+'06'!K60+'06'!X60)+('07'!K13+'07'!X13+'07'!K60+'07'!X60)+('08'!K13+'08'!X13+'08'!K60+'08'!X60)+('09'!K13+'09'!X13+'09'!K60+'09'!X60) -> 0 | M5: =SUM(C5:L5) -> 15 | N5: =M5*25 -> 375
B6: SO4 | C6: =('01'!C14+'01'!P14+'01'!C61+'01'!P61)+('02'!C14+'02'!P14+'02'!C61+'02'!P61)+('03'!B14+'03'!O14+'03'!B61+'03'!O61)+('04'!B14+'04'!O14+'04'!B61+'04'!O61)+('05'!B14+'05'!O14+'05'!B61+'05'!O61)+('06'!B14+'06'!O14+'06'!B61+'06'!O61)+('07'!B14+'07'!O14+'07'!B61+'07'!O61)+('08'!B14+'08'!O14+'08'!B61+'08'!O61)+('09'!B14+'09'!O14+'09'!B61+'09'!O61) -> 0 | D6: =('01'!D14+'01'!Q14+'01'!D61+'01'!Q61)+('02'!D14+'02'!Q14+'02'!D61+'02'!Q61)+('03'!C14+'03'!P14+'03'!C61+'03'!P61)+('04'!C14+'04'!P14+'04'!C61+'04'!P61)+('05'!C14+'05'!P14+'05'!C61+'05'!P61)+('06'!C14+'06'!P14+'06'!C61+'06'!P61)+('07'!C14+'07'!P14+'07'!C61+'07'!P61)+('08'!C14+'08'!P14+'08'!C61+'08'!P61)+('09'!C14+'09'!P14+'09'!C61+'09'!P61) -> 0 | E6: =('01'!E14+'01'!R14+'01'!E61+'01'!R61)+('02'!E14+'02'!R14+'02'!E61+'02'!R61)+('03'!D14+'03'!Q14+'03'!D61+'03'!Q61)+('04'!D14+'04'!Q14+'04'!D61+'04'!Q61)+('05'!D14+'05'!Q14+'05'!D61+'05'!Q61)+('06'!D14+'06'!Q14+'06'!D61+'06'!Q61)+('07'!D14+'07'!Q14+'07'!D61+'07'!Q61)+('08'!D14+'08'!Q14+'08'!D61+'08'!Q61)+('09'!D14+'09'!Q14+'09'!D61+'09'!Q61) -> 12 | F6: =('01'!F14+'01'!S14+'01'!F61+'01'!S61)+('02'!F14+'02'!S14+'02'!F61+'02'!S61)+('03'!E14+'03'!R14+'03'!E61+'03'!R61)+('04'!E14+'04'!R14+'04'!E61+'04'!R61)+('05'!E14+'05'!R14+'05'!E61+'05'!R61)+('06'!E14+'06'!R14+'06'!E61+'06'!R61)+('07'!E14+'07'!R14+'07'!E61+'07'!R61)+('08'!E14+'08'!R14+'08'!E61+'08'!R61)+('09'!E14+'09'!R14+'09'!E61+'09'!R61) -> 0 | G6: =('01'!G14+'01'!T14+'01'!G61+'01'!T61)+('02'!G14+'02'!T14+'02'!G61+'02'!T61)+('03'!F14+'03'!S14+'03'!F61+'03'!S61)+('04'!F14+'04'!S14+'04'!F61+'04'!S61)+('05'!F14+'05'!S14+'05'!F61+'05'!S61)+('06'!F14+'06'!S14+'06'!F61+'06'!S61)+('07'!F14+'07'!S14+'07'!F61+'07'!S61)+('08'!F14+'08'!S14+'08'!F61+'08'!S61)+('09'!F14+'09'!S14+'09'!F61+'09'!S61) -> 3 | H6: =('01'!H14+'01'!U14+'01'!H61+'01'!U61)+('02'!H14+'02'!U14+'02'!H61+'02'!U61)+('03'!G14+'03'!T14+'03'!G61+'03'!T61)+('04'!G14+'04'!T14+'04'!G61+'04'!T61)+('05'!G14+'05'!T14+'05'!G61+'05'!T61)+('06'!G14+'06'!T14+'06'!G61+'06'!T61)+('07'!G14+'07'!T14+'07'!G61+'07'!T61)+('08'!G14+'08'!T14+'08'!G61+'08'!T61)+('09'!G14+'09'!T14+'09'!G61+'09'!T61) -> 0 | I6: =('01'!I14+'01'!V14+'01'!I61+'01'!V61)+('02'!I14+'02'!V14+'02'!I61+'02'!V61)+('03'!H14+'03'!U14+'03'!H61+'03'!U61)+('04'!H14+'04'!U14+'04'!H61+'04'!U61)+('05'!H14+'05'!U14+'05'!H61+'05'!U61)+('06'!H14+'06'!U14+'06'!H61+'06'!U61)+('07'!H14+'07'!U14+'07'!H61+'07'!U61)+('08'!H14+'08'!U14+'08'!H61+'08'!U61)+('09'!H14+'09'!U14+'09'!H61+'09'!U61) -> 0 | J6: =('01'!J14+'01'!W14+'01'!J61+'01'!W61)+('02'!J14+'02'!W14+'02'!J61+'02'!W61)+('03'!I14+'03'!V14+'03'!I61+'03'!V61)+('04'!I14+'04'!V14+'04'!I61+'04'!V61)+('05'!I14+'05'!V14+'05'!I61+'05'!V61)+('06'!I14+'06'!V14+'06'!I61+'06'!V61)+('07'!I14+'07'!V14+'07'!I61+'07'!V61)+('08'!I14+'08'!V14+'08'!I61+'08'!V61)+('09'!I14+'09'!V14+'09'!I61+'09'!V61) -> 0 | ... L6: =('01'!L14+'01'!Y14+'01'!L61+'01'!Y61)+('02'!L14+'02'!Y14+'02'!L61+'02'!Y61)+('03'!K14+'03'!X14+'03'!K61+'03'!X61)+('04'!K14+'04'!X14+'04'!K61+'04'!X61)+('05'!K14+'05'!X14+'05'!K61+'05'!X61)+('06'!K14+'06'!X14+'06'!K61+'06'!X61)+('07'!K14+'07'!X14+'07'!K61+'07'!X61)+('08'!K14+'08'!X14+'08'!K61+'08'!X61)+('09'!K14+'09'!X14+'09'!K61+'09'!X61) -> 0 | M6: =SUM(C6:L6) -> 15 | N6: =M6*25 -> 375
B7: SO5 | C7: =('01'!C15+'01'!P15+'01'!C62+'01'!P62)+('02'!C15+'02'!P15+'02'!C62+'02'!P62)+('03'!B15+'03'!O15+'03'!B62+'03'!O62)+('04'!B15+'04'!O15+'04'!B62+'04'!O62)+('05'!B15+'05'!O15+'05'!B62+'05'!O62)+('06'!B15+'06'!O15+'06'!B62+'06'!O62)+('07'!B15+'07'!O15+'07'!B62+'07'!O62)+('08'!B15+'08'!O15+'08'!B62+'08'!O62)+('09'!B15+'09'!O15+'09'!B62+'09'!O62) -> 0 | D7: =('01'!D15+'01'!Q15+'01'!D62+'01'!Q62)+('02'!D15+'02'!Q15+'02'!D62+'02'!Q62)+('03'!C15+'03'!P15+'03'!C62+'03'!P62)+('04'!C15+'04'!P15+'04'!C62+'04'!P62)+('05'!C15+'05'!P15+'05'!C62+'05'!P62)+('06'!C15+'06'!P15+'06'!C62+'06'!P62)+('07'!C15+'07'!P15+'07'!C62+'07'!P62)+('08'!C15+'08'!P15+'08'!C62+'08'!P62)+('09'!C15+'09'!P15+'09'!C62+'09'!P62) -> 0 | E7: =('01'!E15+'01'!R15+'01'!E62+'01'!R62)+('02'!E15+'02'!R15+'02'!E62+'02'!R62)+('03'!D15+'03'!Q15+'03'!D62+'03'!Q62)+('04'!D15+'04'!Q15+'04'!D62+'04'!Q62)+('05'!D15+'05'!Q15+'05'!D62+'05'!Q62)+('06'!D15+'06'!Q15+'06'!D62+'06'!Q62)+('07'!D15+'07'!Q15+'07'!D62+'07'!Q62)+('08'!D15+'08'!Q15+'08'!D62+'08'!Q62)+('09'!D15+'09'!Q15+'09'!D62+'09'!Q62) -> 0 | F7: =('01'!F15+'01'!S15+'01'!F62+'01'!S62)+('02'!F15+'02'!S15+'02'!F62+'02'!S62)+('03'!E15+'03'!R15+'03'!E62+'03'!R62)+('04'!E15+'04'!R15+'04'!E62+'04'!R62)+('05'!E15+'05'!R15+'05'!E62+'05'!R62)+('06'!E15+'06'!R15+'06'!E62+'06'!R62)+('07'!E15+'07'!R15+'07'!E62+'07'!R62)+('08'!E15+'08'!R15+'08'!E62+'08'!R62)+('09'!E15+'09'!R15+'09'!E62+'09'!R62) -> 0 | G7: =('01'!G15+'01'!T15+'01'!G62+'01'!T62)+('02'!G15+'02'!T15+'02'!G62+'02'!T62)+('03'!F15+'03'!S15+'03'!F62+'03'!S62)+('04'!F15+'04'!S15+'04'!F62+'04'!S62)+('05'!F15+'05'!S15+'05'!F62+'05'!S62)+('06'!F15+'06'!S15+'06'!F62+'06'!S62)+('07'!F15+'07'!S15+'07'!F62+'07'!S62)+('08'!F15+'08'!S15+'08'!F62+'08'!S62)+('09'!F15+'09'!S15+'09'!F62+'09'!S62) -> 0 | H7: =('01'!H15+'01'!U15+'01'!H62+'01'!U62)+('02'!H15+'02'!U15+'02'!H62+'02'!U62)+('03'!G15+'03'!T15+'03'!G62+'03'!T62)+('04'!G15+'04'!T15+'04'!G62+'04'!T62)+('05'!G15+'05'!T15+'05'!G62+'05'!T62)+('06'!G15+'06'!T15+'06'!G62+'06'!T62)+('07'!G15+'07'!T15+'07'!G62+'07'!T62)+('08'!G15+'08'!T15+'08'!G62+'08'!T62)+('09'!G15+'09'!T15+'09'!G62+'09'!T62) -> 4 | I7: =('01'!I15+'01'!V15+'01'!I62+'01'!V62)+('02'!I15+'02'!V15+'02'!I62+'02'!V62)+('03'!H15+'03'!U15+'03'!H62+'03'!U62)+('04'!H15+'04'!U15+'04'!H62+'04'!U62)+('05'!H15+'05'!U15+'05'!H62+'05'!U62)+('06'!H15+'06'!U15+'06'!H62+'06'!U62)+('07'!H15+'07'!U15+'07'!H62+'07'!U62)+('08'!H15+'08'!U15+'08'!H62+'08'!U62)+('09'!H15+'09'!U15+'09'!H62+'09'!U62) -> 5 | J7: =('01'!J15+'01'!W15+'01'!J62+'01'!W62)+('02'!J15+'02'!W15+'02'!J62+'02'!W62)+('03'!I15+'03'!V15+'03'!I62+'03'!V62)+('04'!I15+'04'!V15+'04'!I62+'04'!V62)+('05'!I15+'05'!V15+'05'!I62+'05'!V62)+('06'!I15+'06'!V15+'06'!I62+'06'!V62)+('07'!I15+'07'!V15+'07'!I62+'07'!V62)+('08'!I15+'08'!V15+'08'!I62+'08'!V62)+('09'!I15+'09'!V15+'09'!I62+'09'!V62) -> 0 | ... L7: =('01'!L15+'01'!Y15+'01'!L62+'01'!Y62)+('02'!L15+'02'!Y15+'02'!L62+'02'!Y62)+('03'!K15+'03'!X15+'03'!K62+'03'!X62)+('04'!K15+'04'!X15+'04'!K62+'04'!X62)+('05'!K15+'05'!X15+'05'!K62+'05'!X62)+('06'!K15+'06'!X15+'06'!K62+'06'!X62)+('07'!K15+'07'!X15+'07'!K62+'07'!X62)+('08'!K15+'08'!X15+'08'!K62+'08'!X62)+('09'!K15+'09'!X15+'09'!K62+'09'!X62) -> 0 | M7: =SUM(C7:L7) -> 9 | N7: =M7*25 -> 225
B8: SO6 | C8: =('01'!C16+'01'!P16+'01'!C63+'01'!P63)+('02'!C16+'02'!P16+'02'!C63+'02'!P63)+('03'!B16+'03'!O16+'03'!B63+'03'!O63)+('04'!B16+'04'!O16+'04'!B63+'04'!O63)+('05'!B16+'05'!O16+'05'!B63+'05'!O63)+('06'!B16+'06'!O16+'06'!B63+'06'!O63)+('07'!B16+'07'!O16+'07'!B63+'07'!O63)+('08'!B16+'08'!O16+'08'!B63+'08'!O63)+('09'!B16+'09'!O16+'09'!B63+'09'!O63) -> 0 | D8: =('01'!D16+'01'!Q16+'01'!D63+'01'!Q63)+('02'!D16+'02'!Q16+'02'!D63+'02'!Q63)+('03'!C16+'03'!P16+'03'!C63+'03'!P63)+('04'!C16+'04'!P16+'04'!C63+'04'!P63)+('05'!C16+'05'!P16+'05'!C63+'05'!P63)+('06'!C16+'06'!P16+'06'!C63+'06'!P63)+('07'!C16+'07'!P16+'07'!C63+'07'!P63)+('08'!C16+'08'!P16+'08'!C63+'08'!P63)+('09'!C16+'09'!P16+'09'!C63+'09'!P63) -> 0 | E8: =('01'!E16+'01'!R16+'01'!E63+'01'!R63)+('02'!E16+'02'!R16+'02'!E63+'02'!R63)+('03'!D16+'03'!Q16+'03'!D63+'03'!Q63)+('04'!D16+'04'!Q16+'04'!D63+'04'!Q63)+('05'!D16+'05'!Q16+'05'!D63+'05'!Q63)+('06'!D16+'06'!Q16+'06'!D63+'06'!Q63)+('07'!D16+'07'!Q16+'07'!D63+'07'!Q63)+('08'!D16+'08'!Q16+'08'!D63+'08'!Q63)+('09'!D16+'09'!Q16+'09'!D63+'09'!Q63) -> 12 | F8: =('01'!F16+'01'!S16+'01'!F63+'01'!S63)+('02'!F16+'02'!S16+'02'!F63+'02'!S63)+('03'!E16+'03'!R16+'03'!E63+'03'!R63)+('04'!E16+'04'!R16+'04'!E63+'04'!R63)+('05'!E16+'05'!R16+'05'!E63+'05'!R63)+('06'!E16+'06'!R16+'06'!E63+'06'!R63)+('07'!E16+'07'!R16+'07'!E63+'07'!R63)+('08'!E16+'08'!R16+'08'!E63+'08'!R63)+('09'!E16+'09'!R16+'09'!E63+'09'!R63) -> 0 | G8: =('01'!G16+'01'!T16+'01'!G63+'01'!T63)+('02'!G16+'02'!T16+'02'!G63+'02'!T63)+('03'!F16+'03'!S16+'03'!F63+'03'!S63)+('04'!F16+'04'!S16+'04'!F63+'04'!S63)+('05'!F16+'05'!S16+'05'!F63+'05'!S63)+('06'!F16+'06'!S16+'06'!F63+'06'!S63)+('07'!F16+'07'!S16+'07'!F63+'07'!S63)+('08'!F16+'08'!S16+'08'!F63+'08'!S63)+('09'!F16+'09'!S16+'09'!F63+'09'!S63) -> 0 | H8: =('01'!H16+'01'!U16+'01'!H63+'01'!U63)+('02'!H16+'02'!U16+'02'!H63+'02'!U63)+('03'!G16+'03'!T16+'03'!G63+'03'!T63)+('04'!G16+'04'!T16+'04'!G63+'04'!T63)+('05'!G16+'05'!T16+'05'!G63+'05'!T63)+('06'!G16+'06'!T16+'06'!G63+'06'!T63)+('07'!G16+'07'!T16+'07'!G63+'07'!T63)+('08'!G16+'08'!T16+'08'!G63+'08'!T63)+('09'!G16+'09'!T16+'09'!G63+'09'!T63) -> 0 | I8: =('01'!I16+'01'!V16+'01'!I63+'01'!V63)+('02'!I16+'02'!V16+'02'!I63+'02'!V63)+('03'!H16+'03'!U16+'03'!H63+'03'!U63)+('04'!H16+'04'!U16+'04'!H63+'04'!U63)+('05'!H16+'05'!U16+'05'!H63+'05'!U63)+('06'!H16+'06'!U16+'06'!H63+'06'!U63)+('07'!H16+'07'!U16+'07'!H63+'07'!U63)+('08'!H16+'08'!U16+'08'!H63+'08'!U63)+('09'!H16+'09'!U16+'09'!H63+'09'!U63) -> 0 | J8: =('01'!J16+'01'!W16+'01'!J63+'01'!W63)+('02'!J16+'02'!W16+'02'!J63+'02'!W63)+('03'!I16+'03'!V16+'03'!I63+'03'!V63)+('04'!I16+'04'!V16+'04'!I63+'04'!V63)+('05'!I16+'05'!V16+'05'!I63+'05'!V63)+('06'!I16+'06'!V16+'06'!I63+'06'!V63)+('07'!I16+'07'!V16+'07'!I63+'07'!V63)+('08'!I16+'08'!V16+'08'!I63+'08'!V63)+('09'!I16+'09'!V16+'09'!I63+'09'!V63) -> 0 | ... L8: =('01'!L16+'01'!Y16+'01'!L63+'01'!Y63)+('02'!L16+'02'!Y16+'02'!L63+'02'!Y63)+('03'!K16+'03'!X16+'03'!K63+'03'!X63)+('04'!K16+'04'!X16+'04'!K63+'04'!X63)+('05'!K16+'05'!X16+'05'!K63+'05'!X63)+('06'!K16+'06'!X16+'06'!K63+'06'!X63)+('07'!K16+'07'!X16+'07'!K63+'07'!X63)+('08'!K16+'08'!X16+'08'!K63+'08'!X63)+('09'!K16+'09'!X16+'09'!K63+'09'!X63) -> 0 | M8: =SUM(C8:L8) -> 12 | N8: =M8*25 -> 300
