Workbook

Sheet 1
A1: Registro: | C1: PC 02.1 | F1: Programa de Crianza
A2: Versión: | C2: 2.2
A3: Fecha: | C3: 44589 | F3: Retiro de Alimentación Piscinas exteriores
A4: Elaborado por: | C4: R - Gatica
A5: Revisado por: | C5: A -Vial | F5: Acuícola Alas S.A., Ruta 5 sur, Km 338, VII región, Parral | AC5: Folio:
A6: Aprobado por: | C6: A -Vial
A8: Nombre quien retira: | P8: Supervisor: | AB8: Agosto | AH8: 5 | AK8: 11
A9: Firma: | P9: Firma:
C11: Oriente | I11: Poniente | O11: Nor Oriente | U11: Nor central | AA11: Nor Poniente | AG11: Central | AK11: J | AL11: H | AM11: Total
B12: Alimento ( sacos) | C12: 1 | D12: 2 | E12: 3 | F12: 4 | G12: 5 | H12: 6 | I12: 1 | J12: 2 | K12: 3 | L12: 4 | M12: 5 | N12: 6 | O12: 1 | P12: 2 | Q12: 3 | R12: 4 | S12: 5 | T12: 6 | U12: 1 | V12: 2 | W12: 3 | X12: 4 | Y12: 5 | Z12: 6 | AA12: 1 | AB12: 2 | AC12: 3 | AD12: 4 | AE12: 5 | AF12: 6 | AG12: 1 | AH12: 2 | AI12: 3 | AJ12: 4 | AM12: Sacos | AN12: Kg
A13: Lunes | B13: 3 mm progress ex | K13: 1 | L13: 2 | AJ13: 1 | AM13: =SUM(C13:AL13) -> 4 | AN13: =AM13*25 -> 100
B14: 4,5 mm metabólica | O14: 3 | Q14: 2 | AM14: =SUM(C14:AL14) -> 5 | AN14: =AM14*25 -> 125
B15: 6 mm metabólica | P15: 3 | T15: 2 | AM15: =SUM(C15:AL15) -> 5 | AN15: =AM15*25 -> 125
B16: 6 mm Progress | AM16: =SUM(C16:AL16) -> 0 | AN16: =AM16*25 -> 0
B17: 8 Progress | R17: 3 | S17: 3 | AB17: 2 | AG17: 2 | AM17: =SUM(C17:AL17) -> 10 | AN17: =AM17*25 -> 250
B18: 8 mm Sturgeon Rep. | U18: 2 | V18: 2 | X18: 3 | Y18: 4 | Z18: 3 | AA18: 3 | AB18: 2 | AC18: 3 | AD18: 3 | AE18: 3 | AF18: 1 | AI18: 3 | AJ18: 2 | AM18: =SUM(C18:AL18) -> 34 | AN18: =AM18*25 -> 850
AM19: =SUM(C19:AL19) -> 0 | AN19: =AM19*25 -> 0
AM20: =SUM(C20:AL20) -> 0 | AN20: =AM20*25 -> 0
A21: Martes | B21: 3 mm progress ex | AM21: =SUM(C21:AL21) -> 0 | AN21: =AM21*25 -> 0
B22: 4,5 mm metabólica | AM22: =SUM(C22:AL22) -> 0 | AN22: =AM22*25 -> 0
B23: 6 mm metabólica | AM23: =SUM(C23:AL23) -> 0 | AN23: =AM23*25 -> 0
B24: 6 mm Progress | AM24: =SUM(C24:AL24) -> 0 | AN24: =AM24*25 -> 0
B25: 8 Metabolica | AM25: =SUM(C25:AL25) -> 0 | AN25: =AM25*25 -> 0
B26: 8 mm Sturgeon Rep. | AM26: =SUM(C26:AL26) -> 0 | AN26: =AM26*25 -> 0
AM27: =SUM(C27:AL27) -> 0 | AN27: =AM27*25 -> 0
AM28: =SUM(C28:AL28) -> 0 | AN28: =AM28*25 -> 0
A29: Miércoles | B29: 3 mm progress ex | K29: 2 | L29: 1 | AJ29: 1 | AM29: =SUM(C29:AL29) -> 4 | AN29: =AM29*25 -> 100
B30: 4,5 mm metabólica | O30: 3 | Q30: 2 | AM30: =SUM(C30:AL30) -> 5 | AN30: =AM30*25 -> 125
B31: 6 mm metabólica | P31: 3 | T31: 2 | AM31: =SUM(C31:AL31) -> 5 | AN31: =AM31*25 -> 125
B32: 6 mm Progress | AM32: =SUM(C32:AL32) -> 0 | AN32: =AM32*25 -> 0
B33: 8 Metabolica | R33: 3 | S33: 3 | AB33: 2 | AG33: 2 | AJ33: 2 | AM33: =SUM(C33:AL33) -> 12 | AN33: =AM33*25 -> 300
B34: 8 mm Sturgeon Rep. | U34: 2 | V34: 2 | X34: 3 | Y34: 4 | Z34: 3 | AA34: 3 | AB34: 2 | AC34: 3 | AD34: 3 | AE34: 3 | AF34: 1 | AI34: 3 | AM34: =SUM(C34:AL34) -> 32 | AN34: =AM34*25 -> 800
AM35: =SUM(C35:AL35) -> 0 | AN35: =AM35*25 -> 0
AM36: =SUM(C36:AL36) -> 0 | AN36: =AM36*25 -> 0
A37: Jueves | B37: 3 mm progress ex | AM37: =SUM(C37:AL37) -> 0 | AN37: =AM37*25 -> 0
B38: 4,5 mm metabólica | AM38: =SUM(C38:AL38) -> 0 | AN38: =AM38*25 -> 0
B39: 6 mm metabólica | AM39: =SUM(C39:AL39) -> 0 | AN39: =AM39*25 -> 0
B40: 6 mm Progress | AM40: =SUM(C40:AL40) -> 0 | AN40: =AM40*25 -> 0
B41: 8 Metabolica | AM41: =SUM(C41:AL41) -> 0 | AN41: =AM41*25 -> 0
B42: 8 mm Sturgeon Rep. | AM42: =SUM(C42:AL42) -> 0 | AN42: =AM42*25 -> 0
...

Sheet 2
A1: Registro: | C1: PC 02.1 | F1: Programa de Crianza
A2: Versión: | C2: 2.2
A3: Fecha: | C3: 44589 | F3: Retiro de Alimentación Piscinas exteriores
A4: Elaborado por: | C4: R - Gatica
A5: Revisado por: | C5: A -Vial | F5: Acuícola Alas S.A., Ruta 5 sur, Km 338, VII región, Parral | AC5: Folio:
A6: Aprobado por: | C6: A -Vial
A8: Nombre quien retira: | P8: Supervisor: | AB8: Agosto | AH8: 12 | AK8: 18
A9: Firma: | P9: Firma:
C11: Oriente | I11: Poniente | O11: Nor Oriente | U11: Nor central | AA11: Nor Poniente | AG11: Central | AK11: J | AL11: H | AM11: Total
B12: Alimento ( sacos) | C12: 1 | D12: 2 | E12: 3 | F12: 4 | G12: 5 | H12: 6 | I12: 1 | J12: 2 | K12: 3 | L12: 4 | M12: 5 | N12: 6 | O12: 1 | P12: 2 | Q12: 3 | R12: 4 | S12: 5 | T12: 6 | U12: 1 | V12: 2 | W12: 3 | X12: 4 | Y12: 5 | Z12: 6 | AA12: 1 | AB12: 2 | AC12: 3 | AD12: 4 | AE12: 5 | AF12: 6 | AG12: 1 | AH12: 2 | AI12: 3 | AJ12: 4 | AM12: Sacos | AN12: Kg
A13: Lunes | B13: 3 mm progress ex | K13: 2 | L13: 2 | AM13: =SUM(C13:AL13) -> 4 | AN13: =AM13*25 -> 100
B14: 4,5 mm metabólica | O14: 3 | Q14: 2 | AM14: =SUM(C14:AL14) -> 5 | AN14: =AM14*25 -> 125
B15: 6 mm metabólica | P15: 3 | T15: 2 | AM15: =SUM(C15:AL15) -> 5 | AN15: =AM15*25 -> 125
B16: 6 mm Progress | AM16: =SUM(C16:AL16) -> 0 | AN16: =AM16*25 -> 0
R17: 3 | S17: 3 | AB17: 2 | AG17: 2 | AM17: =SUM(C17:AL17) -> 10 | AN17: =AM17*25 -> 250
B18: 8 mm Sturgeon Rep. | U18: 2 | V18: 2 | X18: 3 | Y18: 4 | Z18: 3 | AA18: 3 | AB18: 2 | AC18: 3 | AD18: 3 | AE18: 3 | AF18: 1 | AI18: 3 | AJ18: 2 | AM18: =SUM(C18:AL18) -> 34 | AN18: =AM18*25 -> 850
AM19: =SUM(C19:AL19) -> 0 | AN19: =AM19*25 -> 0
AM20: =SUM(C20:AL20) -> 0 | AN20: =AM20*25 -> 0
A21: Martes | B21: 3 mm progress ex | AM21: =SUM(C21:AL21) -> 0 | AN21: =AM21*25 -> 0
B22: 4,5 mm metabólica | AM22: =SUM(C22:AL22) -> 0 | AN22: =AM22*25 -> 0
B23: 6 mm metabólica | AM23: =SUM(C23:AL23) -> 0 | AN23: =AM23*25 -> 0
B24: 6 mm Progress | AM24: =SUM(C24:AL24) -> 0 | AN24: =AM24*25 -> 0
AM25: =SUM(C25:AL25) -> 0 | AN25: =AM25*25 -> 0
B26: 8 mm Sturgeon Rep. | AM26: =SUM(C26:AL26) -> 0 | AN26: =AM26*25 -> 0
AM27: =SUM(C27:AL27) -> 0 | AN27: =AM27*25 -> 0
AM28: =SUM(C28:AL28) -> 0 | AN28: =AM28*25 -> 0
A29: Miércoles | B29: 3 mm progress ex | K29: 2 | L29: 2 | AM29: =SUM(C29:AL29) -> 4 | AN29: =AM29*25 -> 100
B30: 4,5 mm metabólica | O30: 3 | Q30: 2 | AM30: =SUM(C30:AL30) -> 5 | AN30: =AM30*25 -> 125
B31: 6 mm metabólica | P31: 3 | T31: 2 | AM31: =SUM(C31:AL31) -> 5 | AN31: =AM31*25 -> 125
B32: 6 mm Progress | AM32: =SUM(C32:AL32) -> 0 | AN32: =AM32*25 -> 0
R33: 3 | S33: 3 | U33: 2 | V33: 2 | X33: 3 | Y33: 4 | Z33: 3 | AA33: 3 | AB33: 2 | AC33: 3 | AD33: 3 | AE33: 3 | AF33: 1 | AG33: 2 | AI33: 3 | AJ33: 2 | AM33: =SUM(C33:AL33) -> 42 | AN33: =AM33*25 -> 1050
B34: 8 mm Sturgeon Rep. | AM34: =SUM(C34:AL34) -> 0 | AN34: =AM34*25 -> 0
AM35: =SUM(C35:AL35) -> 0 | AN35: =AM35*25 -> 0
AM36: =SUM(C36:AL36) -> 0 | AN36: =AM36*25 -> 0
A37: Jueves | B37: 3 mm progress ex | AM37: =SUM(C37:AL37) -> 0 | AN37: =AM37*25 -> 0
B38: 4,5 mm metabólica | AM38: =SUM(C38:AL38) -> 0 | AN38: =AM38*25 -> 0
B39: 6 mm metabólica | AM39: =SUM(C39:AL39) -> 0 | AN39: =AM39*25 -> 0
B40: 6 mm Progress | AM40: =SUM(C40:AL40) -> 0 | AN40: =AM40*25 -> 0
AM41: =SUM(C41:AL41) -> 0 | AN41: =AM41*25 -> 0
B42: 8 mm Sturgeon Rep. | AM42: =SUM(C42:AL42) -> 0 | AN42: =AM42*25 -> 0
...

Sheet 3
A1: Registro: | C1: PC 02.1 | F1: Programa de Crianza
A2: Versión: | C2: 2.2
A3: Fecha: | C3: 44589 | F3: Retiro de Alimentación Piscinas exteriores
A4: Elaborado por: | C4: R - Gatica
A5: Revisado por: | C5: A -Vial | F5: Acuícola Alas S.A., Ruta 5 sur, Km 338, VII región, Parral | AC5: Folio:
A6: Aprobado por: | C6: A -Vial
A8: Nombre quien retira: | P8: Supervisor: | AB8: Agosto | AH8: 26 | AK8: 30
A9: Firma: | P9: Firma:
C11: Oriente | I11: Poniente | O11: Nor Oriente | U11: Nor central | AA11: Nor Poniente | AG11: Central | AK11: C5 | AL11: H | AM11: Total
B12: Alimento ( sacos) | C12: 1 | D12: 2 | E12: 3 | F12: 4 | G12: 5 | H12: 6 | I12: 1 | J12: 2 | K12: 3 | L12: 4 | M12: 5 | N12: 6 | O12: 1 | P12: 2 | Q12: 3 | R12: 4 | S12: 5 | T12: 6 | U12: 1 | V12: 2 | W12: 3 | X12: 4 | Y12: 5 | Z12: 6 | AA12: 1 | AB12: 2 | AC12: 3 | AD12: 4 | AE12: 5 | AF12: 6 | AG12: 1 | AH12: 2 | AI12: 3 | AJ12: 4 | AM12: Sacos | AN12: Kg
A13: Lunes | B13: 3 mm progress ex | K13: 2 | L13: 2 | AM13: =SUM(C13:AL13) -> 4 | AN13: =AM13*25 -> 100
B14: 4,5 mm metabólica | O14: 3 | Q14: 2 | AM14: =SUM(C14:AL14) -> 5 | AN14: =AM14*25 -> 125
B15: 6 mm metabólica | P15: 3 | T15: 2 | AM15: =SUM(C15:AL15) -> 5 | AN15: =AM15*25 -> 125
B16: 6 mm Progress | AM16: =SUM(C16:AL16) -> 0 | AN16: =AM16*25 -> 0
R17: 3 | S17: 3 | U17: 2 | V17: 2 | X17: 3 | Y17: 4 | Z17: 3 | AA17: 3 | AB17: 2 | AC17: 3 | AD17: 3 | AE17: 3 | AF17: 1 | AG17: 2 | AI17: 3 | AJ17: 2 | AM17: =SUM(C17:AL17) -> 42 | AN17: =AM17*25 -> 1050
B18: 8 mm Sturgeon Rep. | AM18: =SUM(C18:AL18) -> 0 | AN18: =AM18*25 -> 0
AM19: =SUM(C19:AL19) -> 0 | AN19: =AM19*25 -> 0
AM20: =SUM(C20:AL20) -> 0 | AN20: =AM20*25 -> 0
A21: Martes | B21: 3 mm progress ex | AM21: =SUM(C21:AL21) -> 0 | AN21: =AM21*25 -> 0
B22: 4,5 mm metabólica | AM22: =SUM(C22:AL22) -> 0 | AN22: =AM22*25 -> 0
B23: 6 mm metabólica | AM23: =SUM(C23:AL23) -> 0 | AN23: =AM23*25 -> 0
B24: 6 mm Progress | AM24: =SUM(C24:AL24) -> 0 | AN24: =AM24*25 -> 0
AM25: =SUM(C25:AL25) -> 0 | AN25: =AM25*25 -> 0
B26: 8 mm Sturgeon Rep. | AM26: =SUM(C26:AL26) -> 0 | AN26: =AM26*25 -> 0
AM27: =SUM(C27:AL27) -> 0 | AN27: =AM27*25 -> 0
AM28: =SUM(C28:AL28) -> 0 | AN28: =AM28*25 -> 0
A29: Miércoles | B29: 3 mm progress ex | AM29: =SUM(C29:AL29) -> 0 | AN29: =AM29*25 -> 0
B30: 4,5 mm metabólica | AM30: =SUM(C30:AL30) -> 0 | AN30: =AM30*25 -> 0
B31: 6 mm metabólica | AM31: =SUM(C31:AL31) -> 0 | AN31: =AM31*25 -> 0
B32: 6 mm Progress | AM32: =SUM(C32:AL32) -> 0 | AN32: =AM32*25 -> 0
AM33: =SUM(C33:AL33) -> 0 | AN33: =AM33*25 -> 0
B34: 8 mm Sturgeon Rep. | AM34: =SUM(C34:AL34) -> 0 | AN34: =AM34*25 -> 0
AM35: =SUM(C35:AL35) -> 0 | AN35: =AM35*25 -> 0
AM36: =SUM(C36:AL36) -> 0 | AN36: =AM36*25 -> 0
A37: Jueves | B37: 3 mm progress ex | AM37: =SUM(C37:AL37) -> 0 | AN37: =AM37*25 -> 0
B38: 4,5 mm metabólica | AM38: =SUM(C38:AL38) -> 0 | AN38: =AM38*25 -> 0
B39: 6 mm metabólica | AM39: =SUM(C39:AL39) -> 0 | AN39: =AM39*25 -> 0
B40: 6 mm Progress | AM40: =SUM(C40:AL40) -> 0 | AN40: =AM40*25 -> 0
AM41: =SUM(C41:AL41) -> 0 | AN41: =AM41*25 -> 0
B42: 8 mm Sturgeon Rep. | AM42: =SUM(C42:AL42) -> 0 | AN42: =AM42*25 -> 0
...

Sheet 4
A1: Registro: | C1: PC 02.1 | F1: Programa de Crianza
A2: Versión: | C2: 2.2
A3: Fecha: | C3: 44589 | F3: Retiro de Alimentación Piscinas exteriores
A4: Elaborado por: | C4: R - Gatica
A5: Revisado por: | C5: A -Vial | F5: Acuícola Alas S.A., Ruta 5 sur, Km 338, VII región, Parral | AC5: Folio:
A6: Aprobado por: | C6: A -Vial
A8: Nombre quien retira: | P8: Supervisor: | AB8: Agosto | AH8: 19 | AK8: 25
A9: Firma: | P9: Firma:
C11: Oriente | I11: Poniente | O11: Nor Oriente | U11: Nor central | AA11: Nor Poniente | AG11: Central | AK11: J | AL11: H | AM11: Total
B12: Alimento ( sacos) | C12: 1 | D12: 2 | E12: 3 | F12: 4 | G12: 5 | H12: 6 | I12: 1 | J12: 2 | K12: 3 | L12: 4 | M12: 5 | N12: 6 | O12: 1 | P12: 2 | Q12: 3 | R12: 4 | S12: 5 | T12: 6 | U12: 1 | V12: 2 | W12: 3 | X12: 4 | Y12: 5 | Z12: 6 | AA12: 1 | AB12: 2 | AC12: 3 | AD12: 4 | AE12: 5 | AF12: 6 | AG12: 1 | AH12: 2 | AI12: 3 | AJ12: 4 | AM12: Sacos | AN12: Kg
A13: Lunes | B13: 3 mm progress ex | AM13: =SUM(C13:AL13) -> 0 | AN13: =AM13*25 -> 0
B14: 4,5 mm metabólica | AM14: =SUM(C14:AL14) -> 0 | AN14: =AM14*25 -> 0
B15: 6 mm metabólica | P15: 3 | T15: 2 | AM15: =SUM(C15:AL15) -> 5 | AN15: =AM15*25 -> 125
B16: 6 mm Progress | AM16: =SUM(C16:AL16) -> 0 | AN16: =AM16*25 -> 0
R17: 3 | S17: 3 | U17: 2 | V17: 2 | X17: 3 | Y17: 4 | Z17: 3 | AA17: 3 | AB17: 2 | AC17: 3 | AD17: 3 | AE17: 3 | AF17: 1 | AG17: 2 | AI17: 3 | AJ17: 2 | AM17: =SUM(C17:AL17) -> 42 | AN17: =AM17*25 -> 1050
B18: 8 mm Sturgeon Rep. | AM18: =SUM(C18:AL18) -> 0 | AN18: =AM18*25 -> 0
AM19: =SUM(C19:AL19) -> 0 | AN19: =AM19*25 -> 0
AM20: =SUM(C20:AL20) -> 0 | AN20: =AM20*25 -> 0
A21: Martes | B21: 3 mm progress ex | AM21: =SUM(C21:AL21) -> 0 | AN21: =AM21*25 -> 0
B22: 4,5 mm metabólica | AM22: =SUM(C22:AL22) -> 0 | AN22: =AM22*25 -> 0
B23: 6 mm metabólica | AM23: =SUM(C23:AL23) -> 0 | AN23: =AM23*25 -> 0
B24: 6 mm Progress | AM24: =SUM(C24:AL24) -> 0 | AN24: =AM24*25 -> 0
AM25: =SUM(C25:AL25) -> 0 | AN25: =AM25*25 -> 0
B26: 8 mm Sturgeon Rep. | AM26: =SUM(C26:AL26) -> 0 | AN26: =AM26*25 -> 0
AM27: =SUM(C27:AL27) -> 0 | AN27: =AM27*25 -> 0
AM28: =SUM(C28:AL28) -> 0 | AN28: =AM28*25 -> 0
A29: Miércoles | B29: 3 mm progress ex | AJ29: 1 | AM29: =SUM(C29:AL29) -> 1 | AN29: =AM29*25 -> 25
B30: 4,5 mm metabólica | AM30: =SUM(C30:AL30) -> 0 | AN30: =AM30*25 -> 0
B31: 6 mm metabólica | P31: 3 | T31: 2 | U31: 1 | AM31: =SUM(C31:AL31) -> 6 | AN31: =AM31*25 -> 150
B32: 6 mm Progress | AM32: =SUM(C32:AL32) -> 0 | AN32: =AM32*25 -> 0
R33: 3 | S33: 3 | AA33: 3 | AE33: 1 | AG33: 2 | AI33: 3 | AJ33: 2 | AM33: =SUM(C33:AL33) -> 17 | AN33: =AM33*25 -> 425
B34: 8 mm Sturgeon Rep. | AM34: =SUM(C34:AL34) -> 0 | AN34: =AM34*25 -> 0
AM35: =SUM(C35:AL35) -> 0 | AN35: =AM35*25 -> 0
AM36: =SUM(C36:AL36) -> 0 | AN36: =AM36*25 -> 0
A37: Jueves | B37: 3 mm progress ex | AM37: =SUM(C37:AL37) -> 0 | AN37: =AM37*25 -> 0
B38: 4,5 mm metabólica | AM38: =SUM(C38:AL38) -> 0 | AN38: =AM38*25 -> 0
B39: 6 mm metabólica | AM39: =SUM(C39:AL39) -> 0 | AN39: =AM39*25 -> 0
B40: 6 mm Progress | AM40: =SUM(C40:AL40) -> 0 | AN40: =AM40*25 -> 0
AM41: =SUM(C41:AL41) -> 0 | AN41: =AM41*25 -> 0
B42: 8 mm Sturgeon Rep. | AM42: =SUM(C42:AL42) -> 0 | AN42: =AM42*25 -> 0
...

Sheet 5
A1: Registro: | C1: PC 02.1 | F1: Programa de Crianza
A2: Versión: | C2: 2.2
A3: Fecha: | C3: 44589 | F3: Retiro de Alimentación Piscinas exteriores
A4: Elaborado por: | C4: R - Gatica
A5: Revisado por: | C5: A -Vial | F5: Acuícola Alas S.A., Ruta 5 sur, Km 338, VII región, Parral | AC5: Folio:
A6: Aprobado por: | C6: A -Vial
A8: Nombre quien retira: | P8: Supervisor: | AB8: Agosto
A9: Firma: | P9: Firma:
C11: Oriente | I11: Poniente | O11: Nor Oriente | U11: Nor central | AA11: Nor Poniente | AG11: Central | AK11: J | AL11: H | AM11: Total
B12: Alimento ( sacos) | C12: 1 | D12: 2 | E12: 3 | F12: 4 | G12: 5 | H12: 6 | I12: 1 | J12: 2 | K12: 3 | L12: 4 | M12: 5 | N12: 6 | O12: 1 | P12: 2 | Q12: 3 | R12: 4 | S12: 5 | T12: 6 | U12: 1 | V12: 2 | W12: 3 | X12: 4 | Y12: 5 | Z12: 6 | AA12: 1 | AB12: 2 | AC12: 3 | AD12: 4 | AE12: 5 | AF12: 6 | AG12: 1 | AH12: 2 | AI12: 3 | AJ12: 4 | AM12: Sacos | AN12: Kg
A13: Lunes | B13: 3 mm progress ex | AM13: =SUM(C13:AL13) -> 0 | AN13: =AM13*25 -> 0
B14: 4,5 mm metabólica | AM14: =SUM(C14:AL14) -> 0 | AN14: =AM14*25 -> 0
B15: 6 mm metabólica | AM15: =SUM(C15:AL15) -> 0 | AN15: =AM15*25 -> 0
B16: 6 mm Progress | AM16: =SUM(C16:AL16) -> 0 | AN16: =AM16*25 -> 0
AM17: =SUM(C17:AL17) -> 0 | AN17: =AM17*25 -> 0
B18: 8 mm Sturgeon Rep. | AM18: =SUM(C18:AL18) -> 0 | AN18: =AM18*25 -> 0
AM19: =SUM(C19:AL19) -> 0 | AN19: =AM19*25 -> 0
AM20: =SUM(C20:AL20) -> 0 | AN20: =AM20*25 -> 0
A21: Martes | B21: 3 mm progress ex | AM21: =SUM(C21:AL21) -> 0 | AN21: =AM21*25 -> 0
B22: 4,5 mm metabólica | AM22: =SUM(C22:AL22) -> 0 | AN22: =AM22*25 -> 0
B23: 6 mm metabólica | AM23: =SUM(C23:AL23) -> 0 | AN23: =AM23*25 -> 0
B24: 6 mm Progress | AM24: =SUM(C24:AL24) -> 0 | AN24: =AM24*25 -> 0
AM25: =SUM(C25:AL25) -> 0 | AN25: =AM25*25 -> 0
B26: 8 mm Sturgeon Rep. | AM26: =SUM(C26:AL26) -> 0 | AN26: =AM26*25 -> 0
AM27: =SUM(C27:AL27) -> 0 | AN27: =AM27*25 -> 0
AM28: =SUM(C28:AL28) -> 0 | AN28: =AM28*25 -> 0
A29: Miércoles | B29: 3 mm progress ex | AM29: =SUM(C29:AL29) -> 0 | AN29: =AM29*25 -> 0
B30: 4,5 mm metabólica | AM30: =SUM(C30:AL30) -> 0 | AN30: =AM30*25 -> 0
B31: 6 mm metabólica | AM31: =SUM(C31:AL31) -> 0 | AN31: =AM31*25 -> 0
B32: 6 mm Progress | AM32: =SUM(C32:AL32) -> 0 | AN32: =AM32*25 -> 0
AM33: =SUM(C33:AL33) -> 0 | AN33: =AM33*25 -> 0
B34: 8 mm Sturgeon Rep. | AM34: =SUM(C34:AL34) -> 0 | AN34: =AM34*25 -> 0
AM35: =SUM(C35:AL35) -> 0 | AN35: =AM35*25 -> 0
AM36: =SUM(C36:AL36) -> 0 | AN36: =AM36*25 -> 0
A37: Jueves | B37: 3 mm progress ex | AM37: =SUM(C37:AL37) -> 0 | AN37: =AM37*25 -> 0
B38: 4,5 mm metabólica | AM38: =SUM(C38:AL38) -> 0 | AN38: =AM38*25 -> 0
B39: 6 mm metabólica | AM39: =SUM(C39:AL39) -> 0 | AN39: =AM39*25 -> 0
B40: 6 mm Progress | AM40: =SUM(C40:AL40) -> 0 | AN40: =AM40*25 -> 0
AM41: =SUM(C41:AL41) -> 0 | AN41: =AM41*25 -> 0
B42: 8 mm Sturgeon Rep. | AM42: =SUM(C42:AL42) -> 0 | AN42: =AM42*25 -> 0
...

Sheet 6
A1: Registro: | C1: PC 02.1 | F1: Programa de Crianza
A2: Versión: | C2: 2.2
A3: Fecha: | C3: 44589 | F3: Retiro de Alimentación Piscinas exteriores
A4: Elaborado por: | C4: R - Gatica
A5: Revisado por: | C5: A -Vial | F5: Acuícola Alas S.A., Ruta 5 sur, Km 338, VII región, Parral | AC5: Folio:
A6: Aprobado por: | C6: A -Vial
A8: Nombre quien retira: | P8: Supervisor: | AB8: Agosto
A9: Firma: | P9: Firma:
C11: Oriente | I11: Poniente | O11: Nor Oriente | U11: Nor central | AA11: Nor Poniente | AG11: Central | AK11: J | AL11: H | AM11: Total
B12: Alimento ( sacos) | C12: 1 | D12: 2 | E12: 3 | F12: 4 | G12: 5 | H12: 6 | I12: 1 | J12: 2 | K12: 3 | L12: 4 | M12: 5 | N12: 6 | O12: 1 | P12: 2 | Q12: 3 | R12: 4 | S12: 5 | T12: 6 | U12: 1 | V12: 2 | W12: 3 | X12: 4 | Y12: 5 | Z12: 6 | AA12: 1 | AB12: 2 | AC12: 3 | AD12: 4 | AE12: 5 | AF12: 6 | AG12: 1 | AH12: 2 | AI12: 3 | AJ12: 4 | AM12: Sacos | AN12: Kg
A13: Lunes | B13: 3 mm progress ex | AM13: =SUM(C13:AL13) -> 0 | AN13: =AM13*25 -> 0
B14: 4,5 mm metabólica | AM14: =SUM(C14:AL14) -> 0 | AN14: =AM14*25 -> 0
B15: 6 mm metabólica | AM15: =SUM(C15:AL15) -> 0 | AN15: =AM15*25 -> 0
B16: 6 mm Progress | AM16: =SUM(C16:AL16) -> 0 | AN16: =AM16*25 -> 0
AM17: =SUM(C17:AL17) -> 0 | AN17: =AM17*25 -> 0
B18: 8 mm Sturgeon Rep. | AM18: =SUM(C18:AL18) -> 0 | AN18: =AM18*25 -> 0
AM19: =SUM(C19:AL19) -> 0 | AN19: =AM19*25 -> 0
AM20: =SUM(C20:AL20) -> 0 | AN20: =AM20*25 -> 0
A21: Martes | B21: 3 mm progress ex | AM21: =SUM(C21:AL21) -> 0 | AN21: =AM21*25 -> 0
B22: 4,5 mm metabólica | AM22: =SUM(C22:AL22) -> 0 | AN22: =AM22*25 -> 0
B23: 6 mm metabólica | AM23: =SUM(C23:AL23) -> 0 | AN23: =AM23*25 -> 0
B24: 6 mm Progress | AM24: =SUM(C24:AL24) -> 0 | AN24: =AM24*25 -> 0
AM25: =SUM(C25:AL25) -> 0 | AN25: =AM25*25 -> 0
B26: 8 mm Sturgeon Rep. | AM26: =SUM(C26:AL26) -> 0 | AN26: =AM26*25 -> 0
AM27: =SUM(C27:AL27) -> 0 | AN27: =AM27*25 -> 0
AM28: =SUM(C28:AL28) -> 0 | AN28: =AM28*25 -> 0
A29: Miércoles | B29: 3 mm progress ex | AM29: =SUM(C29:AL29) -> 0 | AN29: =AM29*25 -> 0
B30: 4,5 mm metabólica | AM30: =SUM(C30:AL30) -> 0 | AN30: =AM30*25 -> 0
B31: 6 mm metabólica | AM31: =SUM(C31:AL31) -> 0 | AN31: =AM31*25 -> 0
B32: 6 mm Progress | AM32: =SUM(C32:AL32) -> 0 | AN32: =AM32*25 -> 0
AM33: =SUM(C33:AL33) -> 0 | AN33: =AM33*25 -> 0
B34: 8 mm Sturgeon Rep. | AM34: =SUM(C34:AL34) -> 0 | AN34: =AM34*25 -> 0
AM35: =SUM(C35:AL35) -> 0 | AN35: =AM35*25 -> 0
AM36: =SUM(C36:AL36) -> 0 | AN36: =AM36*25 -> 0
A37: Jueves | B37: 3 mm progress ex | AM37: =SUM(C37:AL37) -> 0 | AN37: =AM37*25 -> 0
B38: 4,5 mm metabólica | AM38: =SUM(C38:AL38) -> 0 | AN38: =AM38*25 -> 0
B39: 6 mm metabólica | AM39: =SUM(C39:AL39) -> 0 | AN39: =AM39*25 -> 0
B40: 6 mm Progress | AM40: =SUM(C40:AL40) -> 0 | AN40: =AM40*25 -> 0
AM41: =SUM(C41:AL41) -> 0 | AN41: =AM41*25 -> 0
B42: 8 mm Sturgeon Rep. | AM42: =SUM(C42:AL42) -> 0 | AN42: =AM42*25 -> 0
...

Sheet 7
C2: Oriente | I2: Poniente | O2: Nor Oriente | U2: Nor central | AA2: Nor Poniente | AG2: Central | AK2: J | AL2: H | AM2: Total
B3: Alimento ( sacos) | C3: 1 | D3: 2 | E3: 3 | F3: 4 | G3: 5 | H3: 6 | I3: 1 | J3: 2 | K3: 3 | L3: 4 | M3: 5 | N3: 6 | O3: 1 | P3: 2 | Q3: 3 | R3: 4 | S3: 5 | T3: 6 | U3: 1 | V3: 2 | W3: 3 | X3: 4 | Y3: 5 | Z3: 6 | AA3: 1 | AB3: 2 | AC3: 3 | AD3: 4 | AE3: 5 | AF3: 6 | AG3: 1 | AH3: 2 | AI3: 3 | AJ3: 4 | AM3: Sacos | AN3: Kg
A4: Lunes | B4: 3 mm progress ex | AM4: =SUM(C4:AL4) -> 0 | AN4: =AM4*25 -> 0
B5: 4,5 mm metabólica | AM5: =SUM(C5:AL5) -> 0 | AN5: =AM5*25 -> 0
B6: 6 mm metabólica | AM6: =SUM(C6:AL6) -> 0 | AN6: =AM6*25 -> 0
B7: 6 mm Progress | AM7: =SUM(C7:AL7) -> 0 | AN7: =AM7*25 -> 0
AM8: =SUM(C8:AL8) -> 0 | AN8: =AM8*25 -> 0
B9: 8 mm Sturgeon Rep. | AM9: =SUM(C9:AL9) -> 0 | AN9: =AM9*25 -> 0
AM10: =SUM(C10:AL10) -> 0 | AN10: =AM10*25 -> 0
AM11: =SUM(C11:AL11) -> 0 | AN11: =AM11*25 -> 0
A12: Martes | B12: 3 mm progress ex | AM12: =SUM(C12:AL12) -> 0 | AN12: =AM12*25 -> 0
B13: 4,5 mm metabólica | AM13: =SUM(C13:AL13) -> 0 | AN13: =AM13*25 -> 0
B14: 6 mm metabólica | AM14: =SUM(C14:AL14) -> 0 | AN14: =AM14*25 -> 0
B15: 6 mm Progress | AM15: =SUM(C15:AL15) -> 0 | AN15: =AM15*25 -> 0
AM16: =SUM(C16:AL16) -> 0 | AN16: =AM16*25 -> 0
B17: 8 mm Sturgeon Rep. | AM17: =SUM(C17:AL17) -> 0 | AN17: =AM17*25 -> 0
AM18: =SUM(C18:AL18) -> 0 | AN18: =AM18*25 -> 0
AM19: =SUM(C19:AL19) -> 0 | AN19: =AM19*25 -> 0
A20: Miércoles | B20: 3 mm progress ex | AM20: =SUM(C20:AL20) -> 0 | AN20: =AM20*25 -> 0
B21: 4,5 mm metabólica | AM21: =SUM(C21:AL21) -> 0 | AN21: =AM21*25 -> 0
B22: 6 mm metabólica | AM22: =SUM(C22:AL22) -> 0 | AN22: =AM22*25 -> 0
B23: 6 mm Progress | AM23: =SUM(C23:AL23) -> 0 | AN23: =AM23*25 -> 0
AM24: =SUM(C24:AL24) -> 0 | AN24: =AM24*25 -> 0
B25: 8 mm Sturgeon Rep. | AM25: =SUM(C25:AL25) -> 0 | AN25: =AM25*25 -> 0
AM26: =SUM(C26:AL26) -> 0 | AN26: =AM26*25 -> 0
AM27: =SUM(C27:AL27) -> 0 | AN27: =AM27*25 -> 0
A28: Jueves | B28: 3 mm progress ex | AM28: =SUM(C28:AL28) -> 0 | AN28: =AM28*25 -> 0
B29: 4,5 mm metabólica | AM29: =SUM(C29:AL29) -> 0 | AN29: =AM29*25 -> 0
B30: 6 mm metabólica | AM30: =SUM(C30:AL30) -> 0 | AN30: =AM30*25 -> 0
B31: 6 mm Progress | AM31: =SUM(C31:AL31) -> 0 | AN31: =AM31*25 -> 0
AM32: =SUM(C32:AL32) -> 0 | AN32: =AM32*25 -> 0
B33: 8 mm Sturgeon Rep. | AM33: =SUM(C33:AL33) -> 0 | AN33: =AM33*25 -> 0
AM34: =SUM(C34:AL34) -> 0 | AN34: =AM34*25 -> 0
A35: Viernes | B35: 3 mm progress ex | AM35: =SUM(C35:AL35) -> 0 | AN35: =AM35*25 -> 0
B36: 4,5 mm metabólica | AM36: =SUM(C36:AL36) -> 0 | AN36: =AM36*25 -> 0
B37: 6 mm metabólica | AM37: =SUM(C37:AL37) -> 0 | AN37: =AM37*25 -> 0
B38: 6 mm Progress | AM38: =SUM(C38:AL38) -> 0 | AN38: =AM38*25 -> 0
AM39: =SUM(C39:AL39) -> 0 | AN39: =AM39*25 -> 0
B40: 8 mm Sturgeon Rep. | AM40: =SUM(C40:AL40) -> 0 | AN40: =AM40*25 -> 0
AM41: =SUM(C41:AL41) -> 0 | AN41: =AM41*25 -> 0
...

Sheet 8
C2: Oriente | I2: Poniente | O2: Nor Oriente | U2: Nor central | AA2: Nor Poniente | AG2: Central | AK2: J | AL2: H | AM2: Total
B3: Alimento ( sacos) | C3: 1 | D3: 2 | E3: 3 | F3: 4 | G3: 5 | H3: 6 | I3: 1 | J3: 2 | K3: 3 | L3: 4 | M3: 5 | N3: 6 | O3: 1 | P3: 2 | Q3: 3 | R3: 4 | S3: 5 | T3: 6 | U3: 1 | V3: 2 | W3: 3 | X3: 4 | Y3: 5 | Z3: 6 | AA3: 1 | AB3: 2 | AC3: 3 | AD3: 4 | AE3: 5 | AF3: 6 | AG3: 1 | AH3: 2 | AI3: 3 | AJ3: 4 | AM3: Sacos | AN3: Kg
A4: Lunes | B4: 3 mm progress ex | AM4: =SUM(C4:AL4) -> 0 | AN4: =AM4*25 -> 0
B5: 4,5 mm metabólica | AM5: =SUM(C5:AL5) -> 0 | AN5: =AM5*25 -> 0
B6: 6 mm metabólica | AM6: =SUM(C6:AL6) -> 0 | AN6: =AM6*25 -> 0
B7: 6 mm Progress | AM7: =SUM(C7:AL7) -> 0 | AN7: =AM7*25 -> 0
AM8: =SUM(C8:AL8) -> 0 | AN8: =AM8*25 -> 0
B9: 8 mm Sturgeon Rep. | AM9: =SUM(C9:AL9) -> 0 | AN9: =AM9*25 -> 0
AM10: =SUM(C10:AL10) -> 0 | AN10: =AM10*25 -> 0
AM11: =SUM(C11:AL11) -> 0 | AN11: =AM11*25 -> 0
A12: Martes | B12: 3 mm progress ex | AM12: =SUM(C12:AL12) -> 0 | AN12: =AM12*25 -> 0
B13: 4,5 mm metabólica | AM13: =SUM(C13:AL13) -> 0 | AN13: =AM13*25 -> 0
B14: 6 mm metabólica | AM14: =SUM(C14:AL14) -> 0 | AN14: =AM14*25 -> 0
B15: 6 mm Progress | AM15: =SUM(C15:AL15) -> 0 | AN15: =AM15*25 -> 0
AM16: =SUM(C16:AL16) -> 0 | AN16: =AM16*25 -> 0
B17: 8 mm Sturgeon Rep. | AM17: =SUM(C17:AL17) -> 0 | AN17: =AM17*25 -> 0
AM18: =SUM(C18:AL18) -> 0 | AN18: =AM18*25 -> 0
AM19: =SUM(C19:AL19) -> 0 | AN19: =AM19*25 -> 0
A20: Miércoles | B20: 3 mm progress ex | AM20: =SUM(C20:AL20) -> 0 | AN20: =AM20*25 -> 0
B21: 4,5 mm metabólica | AM21: =SUM(C21:AL21) -> 0 | AN21: =AM21*25 -> 0
B22: 6 mm metabólica | AM22: =SUM(C22:AL22) -> 0 | AN22: =AM22*25 -> 0
B23: 6 mm Progress | AM23: =SUM(C23:AL23) -> 0 | AN23: =AM23*25 -> 0
AM24: =SUM(C24:AL24) -> 0 | AN24: =AM24*25 -> 0
B25: 8 mm Sturgeon Rep. | AM25: =SUM(C25:AL25) -> 0 | AN25: =AM25*25 -> 0
AM26: =SUM(C26:AL26) -> 0 | AN26: =AM26*25 -> 0
AM27: =SUM(C27:AL27) -> 0 | AN27: =AM27*25 -> 0
A28: Jueves | B28: 3 mm progress ex | AM28: =SUM(C28:AL28) -> 0 | AN28: =AM28*25 -> 0
B29: 4,5 mm metabólica | AM29: =SUM(C29:AL29) -> 0 | AN29: =AM29*25 -> 0
B30: 6 mm metabólica | AM30: =SUM(C30:AL30) -> 0 | AN30: =AM30*25 -> 0
B31: 6 mm Progress | AM31: =SUM(C31:AL31) -> 0 | AN31: =AM31*25 -> 0
AM32: =SUM(C32:AL32) -> 0 | AN32: =AM32*25 -> 0
B33: 8 mm Sturgeon Rep. | AM33: =SUM(C33:AL33) -> 0 | AN33: =AM33*25 -> 0
AM34: =SUM(C34:AL34) -> 0 | AN34: =AM34*25 -> 0
A35: Viernes | B35: 3 mm progress ex | AM35: =SUM(C35:AL35) -> 0 | AN35: =AM35*25 -> 0
B36: 4,5 mm metabólica | AM36: =SUM(C36:AL36) -> 0 | AN36: =AM36*25 -> 0
B37: 6 mm metabólica | AM37: =SUM(C37:AL37) -> 0 | AN37: =AM37*25 -> 0
B38: 6 mm Progress | AM38: =SUM(C38:AL38) -> 0 | AN38: =AM38*25 -> 0
AM39: =SUM(C39:AL39) -> 0 | AN39: =AM39*25 -> 0
B40: 8 mm Sturgeon Rep. | AM40: =SUM(C40:AL40) -> 0 | AN40: =AM40*25 -> 0
AM41: =SUM(C41:AL41) -> 0 | AN41: =AM41*25 -> 0
...

Sheet 9
C2: Oriente | I2: Poniente | O2: Nor Oriente | U2: Nor central | AA2: Nor Poniente | AG2: Central | AK2: J | AL2: H | AM2: Total
B3: Alimento ( sacos) | C3: 1 | D3: 2 | E3: 3 | F3: 4 | G3: 5 | H3: 6 | I3: 1 | J3: 2 | K3: 3 | L3: 4 | M3: 5 | N3: 6 | O3: 1 | P3: 2 | Q3: 3 | R3: 4 | S3: 5 | T3: 6 | U3: 1 | V3: 2 | W3: 3 | X3: 4 | Y3: 5 | Z3: 6 | AA3: 1 | AB3: 2 | AC3: 3 | AD3: 4 | AE3: 5 | AF3: 6 | AG3: 1 | AH3: 2 | AI3: 3 | AJ3: 4 | AM3: Sacos | AN3: Kg
A4: Lunes | B4: 3 mm progress ex | AM4: =SUM(C4:AL4) -> 0 | AN4: =AM4*25 -> 0
B5: 4,5 mm metabólica | AM5: =SUM(C5:AL5) -> 0 | AN5: =AM5*25 -> 0
B6: 6 mm metabólica | AM6: =SUM(C6:AL6) -> 0 | AN6: =AM6*25 -> 0
B7: 6 mm Progress | AM7: =SUM(C7:AL7) -> 0 | AN7: =AM7*25 -> 0
B8: 6 mm Sturgeon Rep. | AM8: =SUM(C8:AL8) -> 0 | AN8: =AM8*25 -> 0
B9: 8 mm Sturgeon Rep. | AM9: =SUM(C9:AL9) -> 0 | AN9: =AM9*25 -> 0
AM10: =SUM(C10:AL10) -> 0 | AN10: =AM10*25 -> 0
AM11: =SUM(C11:AL11) -> 0 | AN11: =AM11*25 -> 0
A12: Martes | B12: 3 mm progress ex | AM12: =SUM(C12:AL12) -> 0 | AN12: =AM12*25 -> 0
B13: 4,5 mm metabólica | AM13: =SUM(C13:AL13) -> 0 | AN13: =AM13*25 -> 0
B14: 6 mm metabólica | AM14: =SUM(C14:AL14) -> 0 | AN14: =AM14*25 -> 0
B15: 6 mm Progress | AM15: =SUM(C15:AL15) -> 0 | AN15: =AM15*25 -> 0
B16: 6 mm Sturgeon Rep. | AM16: =SUM(C16:AL16) -> 0 | AN16: =AM16*25 -> 0
B17: 8 mm Sturgeon Rep. | AM17: =SUM(C17:AL17) -> 0 | AN17: =AM17*25 -> 0
AM18: =SUM(C18:AL18) -> 0 | AN18: =AM18*25 -> 0
AM19: =SUM(C19:AL19) -> 0 | AN19: =AM19*25 -> 0
A20: Miércoles | B20: 3 mm progress ex | AM20: =SUM(C20:AL20) -> 0 | AN20: =AM20*25 -> 0
B21: 4,5 mm metabólica | AM21: =SUM(C21:AL21) -> 0 | AN21: =AM21*25 -> 0
B22: 6 mm metabólica | AM22: =SUM(C22:AL22) -> 0 | AN22: =AM22*25 -> 0
B23: 6 mm Progress | AM23: =SUM(C23:AL23) -> 0 | AN23: =AM23*25 -> 0
B24: 6 mm Sturgeon Rep. | AM24: =SUM(C24:AL24) -> 0 | AN24: =AM24*25 -> 0
B25: 8 mm Sturgeon Rep. | AM25: =SUM(C25:AL25) -> 0 | AN25: =AM25*25 -> 0
AM26: =SUM(C26:AL26) -> 0 | AN26: =AM26*25 -> 0
AM27: =SUM(C27:AL27) -> 0 | AN27: =AM27*25 -> 0
A28: Jueves | B28: 3 mm progress ex | AM28: =SUM(C28:AL28) -> 0 | AN28: =AM28*25 -> 0
B29: 4,5 mm metabólica | AM29: =SUM(C29:AL29) -> 0 | AN29: =AM29*25 -> 0
B30: 6 mm metabólica | AM30: =SUM(C30:AL30) -> 0 | AN30: =AM30*25 -> 0
B31: 6 mm Progress | AM31: =SUM(C31:AL31) -> 0 | AN31: =AM31*25 -> 0
B32: 6 mm Sturgeon Rep. | AM32: =SUM(C32:AL32) -> 0 | AN32: =AM32*25 -> 0
B33: 8 mm Sturgeon Rep. | AM33: =SUM(C33:AL33) -> 0 | AN33: =AM33*25 -> 0
AM34: =SUM(C34:AL34) -> 0 | AN34: =AM34*25 -> 0
A35: Viernes | B35: 3 mm progress ex | AM35: =SUM(C35:AL35) -> 0 | AN35: =AM35*25 -> 0
B36: 4,5 mm metabólica | AM36: =SUM(C36:AL36) -> 0 | AN36: =AM36*25 -> 0
B37: 6 mm metabólica | AM37: =SUM(C37:AL37) -> 0 | AN37: =AM37*25 -> 0
B38: 6 mm Progress | AM38: =SUM(C38:AL38) -> 0 | AN38: =AM38*25 -> 0
B39: 6 mm Sturgeon Rep. | AM39: =SUM(C39:AL39) -> 0 | AN39: =AM39*25 -> 0
B40: 8 mm Sturgeon Rep. | AM40: =SUM(C40:AL40) -> 0 | AN40: =AM40*25 -> 0
AM41: =SUM(C41:AL41) -> 0 | AN41: =AM41*25 -> 0
...

Sheet 10
C2: Oriente | I2: Poniente | O2: Nor Oriente | U2: Nor central | AA2: Nor Poniente | AG2: Central | AK2: J | AL2: H | AM2: Total
B3: Alimento ( sacos) | C3: 1 | D3: 2 | E3: 3 | F3: 4 | G3: 5 | H3: 6 | I3: 1 | J3: 2 | K3: 3 | L3: 4 | M3: 5 | N3: 6 | O3: 1 | P3: 2 | Q3: 3 | R3: 4 | S3: 5 | T3: 6 | U3: 1 | V3: 2 | W3: 3 | X3: 4 | Y3: 5 | Z3: 6 | AA3: 1 | AB3: 2 | AC3: 3 | AD3: 4 | AE3: 5 | AF3: 6 | AG3: 1 | AH3: 2 | AI3: 3 | AJ3: 4 | AM3: Sacos | AN3: Kg
A4: Lunes | B4: 3 mm progress ex | AM4: =SUM(C4:AL4) -> 0 | AN4: =AM4*25 -> 0
B5: 4,5 mm metabólica | AM5: =SUM(C5:AL5) -> 0 | AN5: =AM5*25 -> 0
B6: 6 mm metabólica | AM6: =SUM(C6:AL6) -> 0 | AN6: =AM6*25 -> 0
B7: 6 mm Progress | AM7: =SUM(C7:AL7) -> 0 | AN7: =AM7*25 -> 0
B8: 6 mm Sturgeon Rep. | AM8: =SUM(C8:AL8) -> 0 | AN8: =AM8*25 -> 0
B9: 8 mm Sturgeon Rep. | AM9: =SUM(C9:AL9) -> 0 | AN9: =AM9*25 -> 0
AM10: =SUM(C10:AL10) -> 0 | AN10: =AM10*25 -> 0
AM11: =SUM(C11:AL11) -> 0 | AN11: =AM11*25 -> 0
A12: Martes | B12: 3 mm progress ex | AM12: =SUM(C12:AL12) -> 0 | AN12: =AM12*25 -> 0
B13: 4,5 mm metabólica | AM13: =SUM(C13:AL13) -> 0 | AN13: =AM13*25 -> 0
B14: 6 mm metabólica | AM14: =SUM(C14:AL14) -> 0 | AN14: =AM14*25 -> 0
B15: 6 mm Progress | AM15: =SUM(C15:AL15) -> 0 | AN15: =AM15*25 -> 0
B16: 6 mm Sturgeon Rep. | AM16: =SUM(C16:AL16) -> 0 | AN16: =AM16*25 -> 0
B17: 8 mm Sturgeon Rep. | AM17: =SUM(C17:AL17) -> 0 | AN17: =AM17*25 -> 0
AM18: =SUM(C18:AL18) -> 0 | AN18: =AM18*25 -> 0
AM19: =SUM(C19:AL19) -> 0 | AN19: =AM19*25 -> 0
A20: Miércoles | B20: 3 mm progress ex | AM20: =SUM(C20:AL20) -> 0 | AN20: =AM20*25 -> 0
B21: 4,5 mm metabólica | AM21: =SUM(C21:AL21) -> 0 | AN21: =AM21*25 -> 0
B22: 6 mm metabólica | AM22: =SUM(C22:AL22) -> 0 | AN22: =AM22*25 -> 0
B23: 6 mm Progress | AM23: =SUM(C23:AL23) -> 0 | AN23: =AM23*25 -> 0
B24: 6 mm Sturgeon Rep. | AM24: =SUM(C24:AL24) -> 0 | AN24: =AM24*25 -> 0
B25: 8 mm Sturgeon Rep. | AM25: =SUM(C25:AL25) -> 0 | AN25: =AM25*25 -> 0
AM26: =SUM(C26:AL26) -> 0 | AN26: =AM26*25 -> 0
AM27: =SUM(C27:AL27) -> 0 | AN27: =AM27*25 -> 0
A28: Jueves | B28: 3 mm progress ex | AM28: =SUM(C28:AL28) -> 0 | AN28: =AM28*25 -> 0
B29: 4,5 mm metabólica | AM29: =SUM(C29:AL29) -> 0 | AN29: =AM29*25 -> 0
B30: 6 mm metabólica | AM30: =SUM(C30:AL30) -> 0 | AN30: =AM30*25 -> 0
B31: 6 mm Progress | AM31: =SUM(C31:AL31) -> 0 | AN31: =AM31*25 -> 0
B32: 6 mm Sturgeon Rep. | AM32: =SUM(C32:AL32) -> 0 | AN32: =AM32*25 -> 0
B33: 8 mm Sturgeon Rep. | AM33: =SUM(C33:AL33) -> 0 | AN33: =AM33*25 -> 0
AM34: =SUM(C34:AL34) -> 0 | AN34: =AM34*25 -> 0
A35: Viernes | B35: 3 mm progress ex | AM35: =SUM(C35:AL35) -> 0 | AN35: =AM35*25 -> 0
B36: 4,5 mm metabólica | AM36: =SUM(C36:AL36) -> 0 | AN36: =AM36*25 -> 0
B37: 6 mm metabólica | AM37: =SUM(C37:AL37) -> 0 | AN37: =AM37*25 -> 0
B38: 6 mm Progress | AM38: =SUM(C38:AL38) -> 0 | AN38: =AM38*25 -> 0
B39: 6 mm Sturgeon Rep. | AM39: =SUM(C39:AL39) -> 0 | AN39: =AM39*25 -> 0
B40: 8 mm Sturgeon Rep. | AM40: =SUM(C40:AL40) -> 0 | AN40: =AM40*25 -> 0
AM41: =SUM(C41:AL41) -> 0 | AN41: =AM41*25 -> 0
...

Sheet Total
A1: Alimento | B1: SO1 | C1: SO2 | D1: SO3 | E1: SO4 | F1: SO5 | G1: SO6 | H1: SP1 | I1: SP2 | J1: SP3 | K1: SP4 | L1: SP5 | M1: SP6 | N1: NO1 | O1: NO2 | P1: NO3 | Q1: NO4 | R1: NO5 | S1: NO6 | T1: NC1 | U1: NC2 | V1: NC3 | W1: NC4 | X1: NC5 | Y1: NC6 | Z1: NP1 | AA1: NP2 | AB1: NP3 | AC1: NP4 | AD1: NP5 | AE1: NP6 | AF1: C1 | AG1: C2 | AH1: C3 | AI1: C4 | AJ1: J | AK1: H
A2: 3 mm progress ex | B2: ='1'!C74+'2'!C74+'3'!C74+'4'!C74+'5'!C74+'6'!C74+'7'!C66+'8'!C66+'9'!C66+'10'!C66 -> 0 | C2: ='1'!D74+'2'!D74+'3'!D74+'4'!D74+'5'!D74+'6'!D74+'7'!D66+'8'!D66+'9'!D66+'10'!D66 -> 0 | D2: ='1'!E74+'2'!E74+'3'!E74+'4'!E74+'5'!E74+'6'!E74+'7'!E66+'8'!E66+'9'!E66+'10'!E66 -> 0 | E2: ='1'!F74+'2'!F74+'3'!F74+'4'!F74+'5'!F74+'6'!F74+'7'!F66+'8'!F66+'9'!F66+'10'!F66 -> 0 | F2: ='1'!G74+'2'!G74+'3'!G74+'4'!G74+'5'!G74+'6'!G74+'7'!G66+'8'!G66+'9'!G66+'10'!G66 -> 0 | G2: ='1'!H74+'2'!H74+'3'!H74+'4'!H74+'5'!H74+'6'!H74+'7'!H66+'8'!H66+'9'!H66+'10'!H66 -> 0 | H2: ='1'!I74+'2'!I74+'3'!I74+'4'!I74+'5'!I74+'6'!I74+'7'!I66+'8'!I66+'9'!I66+'10'!I66 -> 0 | I2: ='1'!J74+'2'!J74+'3'!J74+'4'!J74+'5'!J74+'6'!J74+'7'!J66+'8'!J66+'9'!J66+'10'!J66 -> 0 | ... AK2: ='1'!AL74+'2'!AL74+'3'!AL74+'4'!AL74+'5'!AL74+'6'!AL74+'7'!AL66+'8'!AL66+'9'!AL66+'10'!AL66 -> 0 | AL2: =SUM(B2:AK2) -> 21 | AM2: =AL2*215 -> 4515
A3: 4,5 mm metabólica | B3: ='1'!C75+'2'!C75+'3'!C75+'4'!C75+'5'!C75+'6'!C75+'7'!C67+'8'!C67+'9'!C67+'10'!C67 -> 0 | C3: ='1'!D75+'2'!D75+'3'!D75+'4'!D75+'5'!D75+'6'!D75+'7'!D67+'8'!D67+'9'!D67+'10'!D67 -> 0 | D3: ='1'!E75+'2'!E75+'3'!E75+'4'!E75+'5'!E75+'6'!E75+'7'!E67+'8'!E67+'9'!E67+'10'!E67 -> 0 | E3: ='1'!F75+'2'!F75+'3'!F75+'4'!F75+'5'!F75+'6'!F75+'7'!F67+'8'!F67+'9'!F67+'10'!F67 -> 0 | F3: ='1'!G75+'2'!G75+'3'!G75+'4'!G75+'5'!G75+'6'!G75+'7'!G67+'8'!G67+'9'!G67+'10'!G67 -> 0 | G3: ='1'!H75+'2'!H75+'3'!H75+'4'!H75+'5'!H75+'6'!H75+'7'!H67+'8'!H67+'9'!H67+'10'!H67 -> 0 | H3: ='1'!I75+'2'!I75+'3'!I75+'4'!I75+'5'!I75+'6'!I75+'7'!I67+'8'!I67+'9'!I67+'10'!I67 -> 0 | I3: ='1'!J75+'2'!J75+'3'!J75+'4'!J75+'5'!J75+'6'!J75+'7'!J67+'8'!J67+'9'!J67+'10'!J67 -> 0 | ... AK3: ='1'!AL75+'2'!AL75+'3'!AL75+'4'!AL75+'5'!AL75+'6'!AL75+'7'!AL67+'8'!AL67+'9'!AL67+'10'!AL67 -> 0 | AL3: =SUM(B3:AK3) -> 25 | AM3: =AL3*215 -> 5375
A4: 6 mm metabólica | B4: ='1'!C76+'2'!C76+'3'!C76+'4'!C76+'5'!C76+'6'!C76+'7'!C68+'8'!C68+'9'!C68+'10'!C68 -> 0 | C4: ='1'!D76+'2'!D76+'3'!D76+'4'!D76+'5'!D76+'6'!D76+'7'!D68+'8'!D68+'9'!D68+'10'!D68 -> 0 | D4: ='1'!E76+'2'!E76+'3'!E76+'4'!E76+'5'!E76+'6'!E76+'7'!E68+'8'!E68+'9'!E68+'10'!E68 -> 0 | E4: ='1'!F76+'2'!F76+'3'!F76+'4'!F76+'5'!F76+'6'!F76+'7'!F68+'8'!F68+'9'!F68+'10'!F68 -> 0 | F4: ='1'!G76+'2'!G76+'3'!G76+'4'!G76+'5'!G76+'6'!G76+'7'!G68+'8'!G68+'9'!G68+'10'!G68 -> 0 | G4: ='1'!H76+'2'!H76+'3'!H76+'4'!H76+'5'!H76+'6'!H76+'7'!H68+'8'!H68+'9'!H68+'10'!H68 -> 0 | H4: ='1'!I76+'2'!I76+'3'!I76+'4'!I76+'5'!I76+'6'!I76+'7'!I68+'8'!I68+'9'!I68+'10'!I68 -> 0 | I4: ='1'!J76+'2'!J76+'3'!J76+'4'!J76+'5'!J76+'6'!J76+'7'!J68+'8'!J68+'9'!J68+'10'!J68 -> 0 | ... AK4: ='1'!AL76+'2'!AL76+'3'!AL76+'4'!AL76+'5'!AL76+'6'!AL76+'7'!AL68+'8'!AL68+'9'!AL68+'10'!AL68 -> 0 | AL4: =SUM(B4:AK4) -> 36 | AM4: =AL4*215 -> 7740
A5: 6 mm Progress | B5: ='1'!C77+'2'!C77+'3'!C77+'4'!C77+'5'!C77+'6'!C77+'7'!C69+'8'!C69+'9'!C69+'10'!C69 -> 0 | C5: ='1'!D77+'2'!D77+'3'!D77+'4'!D77+'5'!D77+'6'!D77+'7'!D69+'8'!D69+'9'!D69+'10'!D69 -> 0 | D5: ='1'!E77+'2'!E77+'3'!E77+'4'!E77+'5'!E77+'6'!E77+'7'!E69+'8'!E69+'9'!E69+'10'!E69 -> 0 | E5: ='1'!F77+'2'!F77+'3'!F77+'4'!F77+'5'!F77+'6'!F77+'7'!F69+'8'!F69+'9'!F69+'10'!F69 -> 0 | F5: ='1'!G77+'2'!G77+'3'!G77+'4'!G77+'5'!G77+'6'!G77+'7'!G69+'8'!G69+'9'!G69+'10'!G69 -> 0 | G5: ='1'!H77+'2'!H77+'3'!H77+'4'!H77+'5'!H77+'6'!H77+'7'!H69+'8'!H69+'9'!H69+'10'!H69 -> 0 | H5: ='1'!I77+'2'!I77+'3'!I77+'4'!I77+'5'!I77+'6'!I77+'7'!I69+'8'!I69+'9'!I69+'10'!I69 -> 0 | I5: ='1'!J77+'2'!J77+'3'!J77+'4'!J77+'5'!J77+'6'!J77+'7'!J69+'8'!J69+'9'!J69+'10'!J69 -> 0 | ... AK5: ='1'!AL77+'2'!AL77+'3'!AL77+'4'!AL77+'5'!AL77+'6'!AL77+'7'!AL69+'8'!AL69+'9'!AL69+'10'!AL69 -> 0 | AL5: =SUM(B5:AK5) -> 0 | AM5: =AL5*215 -> 0
A6: 6 mm Sturgeon Rep. | B6: ='1'!C78+'2'!C78+'3'!C78+'4'!C78+'5'!C78+'6'!C78+'7'!C70+'8'!C70+'9'!C70+'10'!C70 -> 0 | C6: ='1'!D78+'2'!D78+'3'!D78+'4'!D78+'5'!D78+'6'!D78+'7'!D70+'8'!D70+'9'!D70+'10'!D70 -> 0 | D6: ='1'!E78+'2'!E78+'3'!E78+'4'!E78+'5'!E78+'6'!E78+'7'!E70+'8'!E70+'9'!E70+'10'!E70 -> 0 | E6: ='1'!F78+'2'!F78+'3'!F78+'4'!F78+'5'!F78+'6'!F78+'7'!F70+'8'!F70+'9'!F70+'10'!F70 -> 0 | F6: ='1'!G78+'2'!G78+'3'!G78+'4'!G78+'5'!G78+'6'!G78+'7'!G70+'8'!G70+'9'!G70+'10'!G70 -> 0 | G6: ='1'!H78+'2'!H78+'3'!H78+'4'!H78+'5'!H78+'6'!H78+'7'!H70+'8'!H70+'9'!H70+'10'!H70 -> 0 | H6: ='1'!I78+'2'!I78+'3'!I78+'4'!I78+'5'!I78+'6'!I78+'7'!I70+'8'!I70+'9'!I70+'10'!I70 -> 0 | I6: ='1'!J78+'2'!J78+'3'!J78+'4'!J78+'5'!J78+'6'!J78+'7'!J70+'8'!J70+'9'!J70+'10'!J70 -> 0 | ... AK6: ='1'!AL78+'2'!AL78+'3'!AL78+'4'!AL78+'5'!AL78+'6'!AL78+'7'!AL70+'8'!AL70+'9'!AL70+'10'!AL70 -> 0 | AL6: =SUM(B6:AK6) -> 175 | AM6: =AL6*215 -> 37625
A7: 8 mm Sturgeon Rep. | B7: ='1'!C79+'2'!C79+'3'!C79+'4'!C79+'5'!C79+'6'!C79+'7'!C71+'8'!C71+'9'!C71+'10'!C71 -> 0 | C7: ='1'!D79+'2'!D79+'3'!D79+'4'!D79+'5'!D79+'6'!D79+'7'!D71+'8'!D71+'9'!D71+'10'!D71 -> 0 | D7: ='1'!E79+'2'!E79+'3'!E79+'4'!E79+'5'!E79+'6'!E79+'7'!E71+'8'!E71+'9'!E71+'10'!E71 -> 0 | E7: ='1'!F79+'2'!F79+'3'!F79+'4'!F79+'5'!F79+'6'!F79+'7'!F71+'8'!F71+'9'!F71+'10'!F71 -> 0 | F7: ='1'!G79+'2'!G79+'3'!G79+'4'!G79+'5'!G79+'6'!G79+'7'!G71+'8'!G71+'9'!G71+'10'!G71 -> 0 | G7: ='1'!H79+'2'!H79+'3'!H79+'4'!H79+'5'!H79+'6'!H79+'7'!H71+'8'!H71+'9'!H71+'10'!H71 -> 0 | H7: ='1'!I79+'2'!I79+'3'!I79+'4'!I79+'5'!I79+'6'!I79+'7'!I71+'8'!I71+'9'!I71+'10'!I71 -> 0 | I7: ='1'!J79+'2'!J79+'3'!J79+'4'!J79+'5'!J79+'6'!J79+'7'!J71+'8'!J71+'9'!J71+'10'!J71 -> 0 | ... AK7: ='1'!AL79+'2'!AL79+'3'!AL79+'4'!AL79+'5'!AL79+'6'!AL79+'7'!AL71+'8'!AL71+'9'!AL71+'10'!AL71 -> 0 | AL7: =SUM(B7:AK7) -> 100 | AM7: =AL7*215 -> 21500
B8: ='1'!C80+'2'!C80+'3'!C80+'4'!C80+'5'!C80+'6'!C80+'7'!C72+'8'!C72+'9'!C72+'10'!C72 -> 0 | C8: ='1'!D80+'2'!D80+'3'!D80+'4'!D80+'5'!D80+'6'!D80+'7'!D72+'8'!D72+'9'!D72+'10'!D72 -> 0 | D8: ='1'!E80+'2'!E80+'3'!E80+'4'!E80+'5'!E80+'6'!E80+'7'!E72+'8'!E72+'9'!E72+'10'!E72 -> 0 | E8: ='1'!F80+'2'!F80+'3'!F80+'4'!F80+'5'!F80+'6'!F80+'7'!F72+'8'!F72+'9'!F72+'10'!F72 -> 0 | F8: ='1'!G80+'2'!G80+'3'!G80+'4'!G80+'5'!G80+'6'!G80+'7'!G72+'8'!G72+'9'!G72+'10'!G72 -> 0 | G8: ='1'!H80+'2'!H80+'3'!H80+'4'!H80+'5'!H80+'6'!H80+'7'!H72+'8'!H72+'9'!H72+'10'!H72 -> 0 | H8: ='1'!I80+'2'!I80+'3'!I80+'4'!I80+'5'!I80+'6'!I80+'7'!I72+'8'!I72+'9'!I72+'10'!I72 -> 0 | I8: ='1'!J80+'2'!J80+'3'!J80+'4'!J80+'5'!J80+'6'!J80+'7'!J72+'8'!J72+'9'!J72+'10'!J72 -> 0 | ... AK8: ='1'!AL80+'2'!AL80+'3'!AL80+'4'!AL80+'5'!AL80+'6'!AL80+'7'!AL72+'8'!AL72+'9'!AL72+'10'!AL72 -> 0 | AL8: =SUM(B8:AK8) -> 0 | AM8: =AL8*215 -> 0
A11: Alimentacion Consumida Mensual
A13: Ubicación | C13: Origen | D13: 0,2 mm infa | E13: 0,4 mm infa ex | F13: 0,5 mm thalassa ex | G13: 1,3 mm thalassa ex gr | H13: 3 mm progress ex | I13: 4,5 mm metabólica | J13: 6 mm metabólica | K13: 6 mm Progress | L13: 6 mm Sturgeon Rep. | M13: 8 mm Sturgeon Rep.
A15: Lag. Sur Oriente | B15: SO1 | C15: Iberia | H15: =B2 -> 0 | I15: =B3 -> 0 | J15: =B4 -> 0 | K15: =B5 -> 0 | L15: =B6 -> 0 | M15: =B7 -> 0 | N15: =+B15 -> SO1
B16: SO2 | C16: Iberia | H16: =C2 -> 0 | I16: =C3 -> 0 | J16: =C4 -> 0 | K16: =C5 -> 0 | L16: =C6 -> 0 | M16: =C7 -> 0 | N16: =+B16 -> SO2
B17: SO3 | C17: Fátima | H17: =D2 -> 0 | I17: =D3 -> 0 | J17: =D4 -> 0 | K17: =D5 -> 0 | L17: =D6 -> 0 | M17: =D7 -> 0 | N17: =+B17 -> SO3
B18: SO4 | C18: Oscetra | H18: =E2 -> 0 | I18: =E3 -> 0 | J18: =E4 -> 0 | K18: =E5 -> 0 | L18: =E6 -> 0 | M18: =E7 -> 0 | N18: =+B18 -> SO4
B19: SO5 | C19: Oscetra | H19: =F2 -> 0 | I19: =F3 -> 0 | J19: =F4 -> 0 | K19: =F5 -> 0 | L19: =F6 -> 0 | M19: =F7 -> 0 | N19: =+B19 -> SO5
B20: SO6 | C20: Fátima | H20: =G2 -> 0 | I20: =G3 -> 0 | J20: =G4 -> 0 | K20: =G5 -> 0 | L20: =G6 -> 0 | M20: =G7 -> 0 | N20: =+B20 -> SO6
A21: Lag. Sur Poniente | B21: SP1 | C21: Rosario | H21: =H2 -> 0 | I21: =H3 -> 0 | J21: =H4 -> 0 | K21: =H5 -> 0 | L21: =H6 -> 0 | M21: =H7 -> 0
B22: SP2 | C22: Guadalupe | H22: =I2 -> 0 | I22: =I3 -> 0 | J22: =I4 -> 0 | K22: =I5 -> 0 | L22: =I6 -> 0 | M22: =I7 -> 0
B23: SP3 | C23: Fátima | H23: =J2 -> 9 | I23: =J3 -> 0 | J23: =J4 -> 0 | K23: =J5 -> 0 | L23: =J6 -> 0 | M23: =J7 -> 0
B24: SP4 | C24: Fátima | H24: =K2 -> 9 | I24: =K3 -> 0 | J24: =K4 -> 0 | K24: =K5 -> 0 | L24: =K6 -> 0 | M24: =K7 -> 0
B25: SP5 | C25: Fátima | H25: =L2 -> 0 | I25: =L3 -> 0 | J25: =L4 -> 0 | K25: =L5 -> 0 | L25: =L6 -> 0 | M25: =L7 -> 0
B26: SP6 | C26: Del Carmen | H26: =M2 -> 0 | I26: =M3 -> 0 | J26: =M4 -> 0 | K26: =M5 -> 0 | L26: =M6 -> 0 | M26: =M7 -> 0
A27: Lag Nor Oriente | B27: NO1 | C27: Rosario | H27: =N2 -> 0 | I27: =N3 -> 15 | J27: =N4 -> 0 | K27: =N5 -> 0 | L27: =N6 -> 0 | M27: =N7 -> 0
B28: NO2 | H28: =O2 -> 0 | I28: =O3 -> 0 | J28: =O4 -> 21 | K28: =O5 -> 0 | L28: =O6 -> 0 | M28: =O7 -> 0
B29: NO3 | H29: =P2 -> 0 | I29: =P3 -> 10 | J29: =P4 -> 0 | K29: =P5 -> 0 | L29: =P6 -> 0 | M29: =P7 -> 0
B30: NO4 | H30: =Q2 -> 0 | I30: =Q3 -> 0 | J30: =Q4 -> 0 | K30: =Q5 -> 0 | L30: =Q6 -> 21 | M30: =Q7 -> 0
B31: NO5 | H31: =R2 -> 0 | I31: =R3 -> 0 | J31: =R4 -> 0 | K31: =R5 -> 0 | L31: =R6 -> 21 | M31: =R7 -> 0
B32: NO6 | C32: Rosario | H32: =S2 -> 0 | I32: =S3 -> 0 | J32: =S4 -> 14 | K32: =S5 -> 0 | L32: =S6 -> 0 | M32: =S7 -> 0
A33: Laguna Nor Central | B33: NC1 | H33: =T2 -> 0 | I33: =T3 -> 0 | J33: =T4 -> 1 | K33: =T5 -> 0 | L33: =T6 -> 6 | M33: =T7 -> 6
B34: NC2 | H34: =U2 -> 0 | I34: =U3 -> 0 | J34: =U4 -> 0 | K34: =U5 -> 0 | L34: =U6 -> 6 | M34: =U7 -> 6
B35: NC3 | H35: =V2 -> 0 | I35: =V3 -> 0 | J35: =V4 -> 0 | K35: =V5 -> 0 | L35: =V6 -> 0 | M35: =V7 -> 0
B36: NC4 | H36: =W2 -> 0 | I36: =W3 -> 0 | J36: =W4 -> 0 | K36: =W5 -> 0 | L36: =W6 -> 9 | M36: =W7 -> 9
B37: NC5 | H37: =X2 -> 0 | I37: =X3 -> 0 | J37: =X4 -> 0 | K37: =X5 -> 0 | L37: =X6 -> 12 | M37: =X7 -> 12
B38: NC6 | H38: =Y2 -> 0 | I38: =Y3 -> 0 | J38: =Y4 -> 0 | K38: =Y5 -> 0 | L38: =Y6 -> 9 | M38: =Y7 -> 9
A39: Laguna Nor Poniente | B39: NP1 | H39: =Z2 -> 0 | I39: =Z3 -> 0 | J39: =Z4 -> 0 | K39: =Z5 -> 0 | L39: =Z6 -> 12 | M39: =Z7 -> 9
B40: NP2 | H40: =AA2 -> 0 | I40: =AA3 -> 0 | J40: =AA4 -> 0 | K40: =AA5 -> 0 | L40: =AA6 -> 12 | M40: =AA7 -> 6
B41: NP3 | H41: =AB2 -> 0 | I41: =AB3 -> 0 | J41: =AB4 -> 0 | K41: =AB5 -> 0 | L41: =AB6 -> 9 | M41: =AB7 -> 9
B42: NP4 | H42: =AC2 -> 0 | I42: =AC3 -> 0 | J42: =AC4 -> 0 | K42: =AC5 -> 0 | L42: =AC6 -> 9 | M42: =AC7 -> 9
B43: NP5 | H43: =AD2 -> 0 | I43: =AD3 -> 0 | J43: =AD4 -> 0 | K43: =AD5 -> 0 | L43: =AD6 -> 10 | M43: =AD7 -> 9
B44: NP6 | H44: =AE2 -> 0 | I44: =AE3 -> 0 | J44: =AE4 -> 0 | K44: =AE5 -> 0 | L44: =AE6 -> 3 | M44: =AE7 -> 3
...

Sheet Hoja2
E2: Septiembre
A3: Etiquetas de fila | B3: Cuenta de 4.5 progress | C3: Suma de 8 mm Sturgeon Rep. | D3: Suma de 6.0 mm progress | E3: Suma de 3 mm progress ex | F3: Suma de 4,5 mm metabólica | G3: Suma de 6 mm metabólica | H3: Suma de 8 mm Progress
A4: Candelaria | C4: 0 | E4: 225 | F4: 0 | G4: 0 | H4: 0
A5: Del Carmen | C5: 0 | E5: 0 | F5: 0 | G5: 0 | H5: 1050
A6: Dolores | C6: 0 | E6: 0 | F6: 0 | G6: 0 | H6: 350
A7: Lourdes | C7: 0 | D7: 0 | E7: 0 | F7: 0 | G7: 0 | H7: 0
A8: Ocetra | C8: 2500 | E8: 75 | F8: 0 | G8: 25 | H8: 2975
A9: pilar | C9: 0 | E9: 0 | F9: 250 | G9: 525 | H9: 0
A10: Rosa | C10: 0 | E10: 0 | F10: 0 | G10: 0 | H10: 0
A11: Rosario | C11: 0 | E11: 0 | F11: 375 | G11: 350 | H11: 0
A12: Victoria | C12: 0 | E12: 225 | F12: 0 | G12: 0 | H12: 0
A13: (en blanco) | C13: 0 | E13: 0 | F13: 0 | G13: 0 | H13: 0
A14: Total general | C14: 2500 | D14: 0 | E14: 525 | F14: 625 | G14: 900 | H14: 4375

Sheet Total Consumo Mensual
A1: Registro | B1: PC 01.1 | D1: Programa de Crianza
A2: Versión: | B2: 0.24
A3: Fecha: | B3: 44701 | D3: RESUMEN MENSUAL EXISTENCIAS
A4: Elaborado Por: | B4: A - Vial
A5: Modificado por: | B5: R - Gatica | K5: Agosto
A6: Aprobado Por | B6: A - Vial | D6: Acuícola Alas S.A., Ruta 5 sur, Km 338, VII región, Parral
A7: Hojas: | B7: 1 de 3
A9: Alimentacion Consumida Mensual
A11: Ubicación | C11: Origen | D11: 0,2 mm infa | E11: 0,4 mm infa ex | F11: 1.3 Talahass | G11: 4.5 progress | H11: 6.0 mm progress | I11: 3 mm progress ex | J11: 4,5 mm metabólica | K11: 6 mm metabólica | L11: 8 mm Progress | M11: 8 mm Sturgeon Rep.
A12: Lag. Sur Oriente | B12: SO1 | C12: Ocetra | I12: =Total!H15*25 -> 0 | J12: =Total!I15*25 -> 0 | K12: =Total!J15*25 -> 0 | L12: =Total!L15*25 -> 0 | M12: =Total!M15*25 -> 0 | N12: =+B12 -> SO1
B13: SO2 | C13: Ocetra | I13: =Total!H16*25 -> 0 | J13: =Total!I16*25 -> 0 | K13: =Total!J16*25 -> 0 | L13: =Total!L16*25 -> 0 | M13: =Total!M16*25 -> 0 | N13: =+B13 -> SO2
B14: SO3 | C14: Ocetra | I14: =Total!H17*25 -> 0 | J14: =Total!I17*25 -> 0 | K14: =Total!J17*25 -> 0 | L14: =Total!L17*25 -> 0 | M14: =Total!M17*25 -> 0 | N14: =+B14 -> SO3
B15: SO4 | C15: Ocetra | I15: =Total!H18*25 -> 0 | J15: =Total!I18*25 -> 0 | K15: =Total!J18*25 -> 0 | L15: =Total!L18*25 -> 0 | M15: =Total!M18*25 -> 0 | N15: =+B15 -> SO4
B16: SO5 | C16: Ocetra | I16: =Total!H19*25 -> 0 | J16: =Total!I19*25 -> 0 | K16: =Total!J19*25 -> 0 | L16: =Total!L19*25 -> 0 | M16: =Total!M19*25 -> 0 | N16: =+B16 -> SO5
B17: SO6 | C17: Ocetra | I17: =Total!H20*25 -> 0 | J17: =Total!I20*25 -> 0 | K17: =Total!J20*25 -> 0 | L17: =Total!L20*25 -> 0 | M17: =Total!M20*25 -> 0 | N17: =+B17 -> SO6
A18: Lag. Sur Poniente | B18: SP1 | C18: Rosario | I18: =Total!H21*25 -> 0 | J18: =Total!I21*25 -> 0 | K18: =Total!J21*25 -> 0 | L18: =Total!L21*25 -> 0 | M18: =Total!M21*25 -> 0
B19: SP2 | C19: Ocetra | I19: =Total!H22*25 -> 0 | J19: =Total!I22*25 -> 0 | K19: =Total!J22*25 -> 0 | L19: =Total!L22*25 -> 0 | M19: =Total!M22*25 -> 0
B20: SP3 | C20: Candelaria | I20: =Total!H23*25 -> 225 | J20: =Total!I23*25 -> 0 | K20: =Total!J23*25 -> 0 | L20: =Total!L23*25 -> 0 | M20: =Total!M23*25 -> 0
B21: SP4 | C21: Victoria | I21: =Total!H24*25 -> 225 | J21: =Total!I24*25 -> 0 | K21: =Total!J24*25 -> 0 | L21: =Total!L24*25 -> 0 | M21: =Total!M24*25 -> 0
B22: SP5 | C22: Ocetra | I22: =Total!H25*25 -> 0 | J22: =Total!I25*25 -> 0 | K22: =Total!J25*25 -> 0 | L22: =Total!L25*25 -> 0 | M22: =Total!M25*25 -> 0
B23: SP6 | C23: Del Carmen | I23: =Total!H26*25 -> 0 | J23: =Total!I26*25 -> 0 | K23: =Total!J26*25 -> 0 | L23: =Total!L26*25 -> 0 | M23: =Total!M26*25 -> 0
A24: Lag Nor Oriente | B24: NO1 | C24: Rosario | I24: =Total!H27*25 -> 0 | J24: =Total!I27*25 -> 375 | K24: =Total!J27*25 -> 0 | L24: =Total!L27*25 -> 0 | M24: =Total!M27*25 -> 0
B25: NO2 | C25: pilar | I25: =Total!H28*25 -> 0 | J25: =Total!I28*25 -> 0 | K25: =Total!J28*25 -> 525 | L25: =Total!L28*25 -> 0 | M25: =Total!M28*25 -> 0
B26: NO3 | C26: pilar | I26: =Total!H29*25 -> 0 | J26: =Total!I29*25 -> 250 | K26: =Total!J29*25 -> 0 | L26: =Total!L29*25 -> 0 | M26: =Total!M29*25 -> 0
B27: NO4 | C27: Del carmen | I27: =Total!H30*25 -> 0 | J27: =Total!I30*25 -> 0 | K27: =Total!J30*25 -> 0 | L27: =Total!L30*25 -> 525 | M27: =Total!M30*25 -> 0
B28: NO5 | C28: Del carmen | I28: =Total!H31*25 -> 0 | J28: =Total!I31*25 -> 0 | K28: =Total!J31*25 -> 0 | L28: =Total!L31*25 -> 525 | M28: =Total!M31*25 -> 0
B29: NO6 | C29: Rosario | I29: =Total!H32*25 -> 0 | J29: =Total!I32*25 -> 0 | K29: =Total!J32*25 -> 350 | L29: =Total!L32*25 -> 0 | M29: =Total!M32*25 -> 0
A30: Laguna Nor Central | B30: NC1 | C30: Ocetra | I30: =Total!H33*25 -> 0 | J30: =Total!I33*25 -> 0 | K30: =Total!J33*25 -> 25 | L30: =Total!L33*25 -> 150 | M30: =Total!M33*25 -> 150
B31: NC2 | C31: Ocetra | I31: =Total!H34*25 -> 0 | J31: =Total!I34*25 -> 0 | K31: =Total!J34*25 -> 0 | L31: =Total!L34*25 -> 150 | M31: =Total!M34*25 -> 150
B32: NC3 | C32: Ocetra | I32: =Total!H35*25 -> 0 | J32: =Total!I35*25 -> 0 | K32: =Total!J35*25 -> 0 | L32: =Total!L35*25 -> 0 | M32: =Total!M35*25 -> 0
B33: NC4 | C33: Ocetra | I33: =Total!H36*25 -> 0 | J33: =Total!I36*25 -> 0 | K33: =Total!J36*25 -> 0 | L33: =Total!L36*25 -> 225 | M33: =Total!M36*25 -> 225
B34: NC5 | C34: Ocetra | I34: =Total!H37*25 -> 0 | J34: =Total!I37*25 -> 0 | K34: =Total!J37*25 -> 0 | L34: =Total!L37*25 -> 300 | M34: =Total!M37*25 -> 300
B35: NC6 | C35: Ocetra | I35: =Total!H38*25 -> 0 | J35: =Total!I38*25 -> 0 | K35: =Total!J38*25 -> 0 | L35: =Total!L38*25 -> 225 | M35: =Total!M38*25 -> 225
A36: Laguna Nor Poniente | B36: NP1 | C36: Ocetra | I36: =Total!H39*25 -> 0 | J36: =Total!I39*25 -> 0 | K36: =Total!J39*25 -> 0 | L36: =Total!L39*25 -> 300 | M36: =Total!M39*25 -> 225
B37: NP2 | C37: Ocetra | I37: =Total!H40*25 -> 0 | J37: =Total!I40*25 -> 0 | K37: =Total!J40*25 -> 0 | L37: =Total!L40*25 -> 300 | M37: =Total!M40*25 -> 150
B38: NP3 | C38: Ocetra | I38: =Total!H41*25 -> 0 | J38: =Total!I41*25 -> 0 | K38: =Total!J41*25 -> 0 | L38: =Total!L41*25 -> 225 | M38: =Total!M41*25 -> 225
B39: NP4 | C39: Ocetra | I39: =Total!H42*25 -> 0 | J39: =Total!I42*25 -> 0 | K39: =Total!J42*25 -> 0 | L39: =Total!L42*25 -> 225 | M39: =Total!M42*25 -> 225
B40: NP5 | C40: Ocetra | I40: =Total!H43*25 -> 0 | J40: =Total!I43*25 -> 0 | K40: =Total!J43*25 -> 0 | L40: =Total!L43*25 -> 250 | M40: =Total!M43*25 -> 225
B41: NP6 | C41: Ocetra | I41: =Total!H44*25 -> 0 | J41: =Total!I44*25 -> 0 | K41: =Total!J44*25 -> 0 | L41: =Total!L44*25 -> 75 | M41: =Total!M44*25 -> 75
A42: Laguna Central | B42: C1 | C42: Dolores | I42: =Total!H45*25 -> 0 | J42: =Total!I45*25 -> 0 | K42: =Total!J45*25 -> 0 | L42: =Total!L45*25 -> 350 | M42: =Total!M45*25 -> 0 | N42: =+B42 -> C1
...

Sheet Hoja1
